Workbook

Sheet Campionato
A1: PARAMETRI | B1: Campionato | D1: Campionato Baskin Demo - ESEMPIO COMPILATO 64 Squadre | G1: Posizione | H1: Squadra | I1: Coefficiente | J1: Punti Classifica | K1: Partite Giocate | L1: Partite Vinte | M1: Partite Perse | N1: Partite Forfait | O1: Punti Fatti | P1: Punti Subiti | Q1: Differenza Punti | R1: Media Punti Fatti | S1: Media Punti Subiti | T1: Media Differenza Punti | U1: Record Scontri Diretti | V1: Quoziente Canestri Scontri Diretti | W1: Quoziente Canestri Totale | X1: Squadra | Y1: Vittorie Scontri Diretti | AG1: Squadra | AH1: Sconfitte & Forfait Scontri Diretti | AP1: Squadra | AQ1: Punti Fatti Scontri Diretti | AY1: Squadra | AZ1: Punti Subiti Scontri Diretti
B2: Link Logo 1
B3: Link Logo 2
B4: Gironi | D4: A-H
B5: Stagione | D5: 2026/2027
B6: Punti vittoria | D6: 3
B7: Punti sconfitta | D7: 1
B8: Punti forfait | D8: 0
B9: Punteggio forfait (vincente-perdente, separati da "-") | D9: 40-0
A11: SQUADRE | B11: # | C11: Squadra | D11: Eventuali Punti di Penalizzazione | E11: Girone | X11: Squadra | Y11: 1^ | Z11: 2^ | AA11: 3^ | AB11: 4^ | AC11: 5^ | AD11: 6^ | AE11: 7^ | AF11: 8^ | AG11: Squadra | AH11: 1^ | AI11: 2^ | AJ11: 3^ | AK11: 4^ | AL11: 5^ | AM11: 6^ | AN11: 7^ | AO11: 8^ | AP11: Squadra | AQ11: 1^ | AR11: 2^ | AS11: 3^ | AT11: 4^ | AU11: 5^ | AV11: 6^ | AW11: 7^ | AX11: 8^ | AY11: Squadra | AZ11: 1^ | BA11: 2^ | BB11: 3^ | BC11: 4^ | BD11: 5^ | BE11: 6^ | BF11: 7^ | BG11: 8^
B12: A01 | C12: Anaconde Arrabbiate-Anacondeopoli AE | E12: A | G12: =IF($C12="","",$E12&(COUNTIFS(I$12:I$75,">"&I12,E$12:E$75,"="&E12,C$12:C$75,"<>")+COUNTIFS(I$12:I$75,"="&I12,H$12:H$75,"<="&H12,E$12:E$75,"="&E12,C$12:C$75,"<>"))) -> A1 | H12: =IF($C12="","",IFERROR(LEFT($C12,FIND("-",$C12)-1),$C12)) -> Anaconde Arrabbiate | I12: =TEXT(1000000000+J12,"|0000000000|")&TEXT(SUM(Y12:AF12),"0000000000|")&IF(SUM(AZ12:BG12)=0,"0000000000|",TEXT(ROUND(SUM(AQ12:AX12)/SUM(AZ12:BG12),4)*100000,"0000000000|"))&IF(P12=0,"0000000000|",TEXT(ROUND(O12/P12,4)*100000,"0000000000|")) -> |1000000021|0000000000|0000000000|0000135660| | J12: =L12*constPuntiVittoria+M12*constPuntiSconfitta+N12*constPuntiForfait+IF(D12="",0,D12) -> 21 | K12: =SUM(L12:N12) -> 7 | L12: =IF($H12="",0,SUMIF('Calendario A'!$M$8:$M$110,$H12,'Calendario A'!$N$8:$N$110)+SUMIF('Calendario A'!$T$8:$T$110,$H12,'Calendario A'!$U$8:$U$110)) -> 7 | M12: =IF($H12="",0,SUMIF('Calendario A'!$M$8:$M$110,$H12,'Calendario A'!$P$8:$P$110)+SUMIF('Calendario A'!$T$8:$T$110,$H12,'Calendario A'!$W$8:$W$110)) -> 0 | N12: =IF($H12="",0,SUMIF('Calendario A'!$M$8:$M$110,$H12,'Calendario A'!$O$8:$O$110)+SUMIF('Calendario A'!$T$8:$T$110,$H12,'Calendario A'!$V$8:$V$110)) -> 0 | O12: =IF($H12="",0,SUMIF('Calendario A'!$M$8:$M$110,$H12,'Calendario A'!$Q$8:$Q$110)+SUMIF('Calendario A'!$T$8:$T$110,$H12,'Calendario A'!$X$8:$X$110)) -> 506 | P12: =IF($H12="",0,SUMIF('Calendario A'!$M$8:$M$110,$H12,'Calendario A'!$R$8:$R$110)+SUMIF('Calendario A'!$T$8:$T$110,$H12,'Calendario A'!$Y$8:$Y$110)) -> 373 | Q12: =IF($H12="",0,SUMIF('Calendario A'!$M$8:$M$110,$H12,'Calendario A'!$S$8:$S$110)+SUMIF('Calendario A'!$T$8:$T$110,$H12,'Calendario A'!$Z$8:$Z$110)) -> 133 | R12: =IF(K12=0,0,ROUND(O12/K12,2)) -> 72.29 | S12: =IF(K12=0,0,ROUND(P12/K12,2)) -> 53.29 | T12: =IF(K12=0,0,ROUND(Q12/K12,2)) -> 19 | U12: =IF(COUNT(Y12:AF12)=0,"-",SUM(Y12:AF12)&"-"&SUM(AH12:AO12)) -> - | V12: =IF(COUNT(Y12:AF12)=0,"-",IF(SUM(AZ12:BG12)=0,TEXT(0,"0.0000"),TEXT(ROUND(SUM(AQ12:AX12)/SUM(AZ12:BG12),4),"0.0000"))) -> - | W12: =IF(H12="","-",IF(P12=0,TEXT(0,"0.0000"),TEXT(ROUND(O12/P12,4),"0.0000"))) -> 1.3566 | X12: =$C12 -> Anaconde Arrabbiate-Anacondeopoli AE | Y12: =IF(AND($H12<>"",$H$12<>"",$H12<>$H$12,IFERROR(VLOOKUP($H12,areaCercaPuntiClassificaSquadra,3,FALSE()),-1)=IFERROR(VLOOKUP($H$12,areaCercaPuntiClassificaSquadra,3,FALSE()),-2)),SUMIFS('Calendario A'!$N$8:$N$110,'Calendario A'!$M$8:$M$110,$H12,'Calendario A'!$T$8:$T$110,$H$12)+SUMIFS('Calendario A'!$U$8:$U$110,'Calendario A'!$T$8:$T$110,$H12,'Calendario A'!$M$8:$M$110,$H$12),"-") -> - | Z12: =IF(AND($H12<>"",$H$13<>"",$H12<>$H$13,IFERROR(VLOOKUP($H12,areaCercaPuntiClassificaSquadra,3,FALSE()),-1)=IFERROR(VLOOKUP($H$13,areaCercaPuntiClassificaSquadra,3,FALSE()),-2)),SUMIFS('Calendario A'!$N$8:$N$110,'Calendario A'!$M$8:$M$110,$H12,'Calendario A'!$T$8:$T$110,$H$13)+SUMIFS('Calendario A'!$U$8:$U$110,'Calendario A'!$T$8:$T$110,$H12,'Calendario A'!$M$8:$M$110,$H$13),"-") -> - | AA12: =IF(AND($H12<>"",$H$14<>"",$H12<>$H$14,IFERROR(VLOOKUP($H12,areaCercaPuntiClassificaSquadra,3,FALSE()),-1)=IFERROR(VLOOKUP($H$14,areaCercaPuntiClassificaSquadra,3,FALSE()),-2)),SUMIFS('Calendario A'!$N$8:$N$110,'Calendario A'!$M$8:$M$110,$H12,'Calendario A'!$T$8:$T$110,$H$14)+SUMIFS('Calendario A'!$U$8:$U$110,'Calendario A'!$T$8:$T$110,$H12,'Calendario A'!$M$8:$M$110,$H$14),"-") -> - | AB12: =IF(AND($H12<>"",$H$15<>"",$H12<>$H$15,IFERROR(VLOOKUP($H12,areaCercaPuntiClassificaSquadra,3,FALSE()),-1)=IFERROR(VLOOKUP($H$15,areaCercaPuntiClassificaSquadra,3,FALSE()),-2)),SUMIFS('Calendario A'!$N$8:$N$110,'Calendario A'!$M$8:$M$110,$H12,'Calendario A'!$T$8:$T$110,$H$15)+SUMIFS('Calendario A'!$U$8:$U$110,'Calendario A'!$T$8:$T$110,$H12,'Calendario A'!$M$8:$M$110,$H$15),"-") -> - | AC12: =IF(AND($H12<>"",$H$16<>"",$H12<>$H$16,IFERROR(VLOOKUP($H12,areaCercaPuntiClassificaSquadra,3,FALSE()),-1)=IFERROR(VLOOKUP($H$16,areaCercaPuntiClassificaSquadra,3,FALSE()),-2)),SUMIFS('Calendario A'!$N$8:$N$110,'Calendario A'!$M$8:$M$110,$H12,'Calendario A'!$T$8:$T$110,$H$16)+SUMIFS('Calendario A'!$U$8:$U$110,'Calendario A'!$T$8:$T$110,$H12,'Calendario A'!$M$8:$M$110,$H$16),"-") -> - | AD12: =IF(AND($H12<>"",$H$17<>"",$H12<>$H$17,IFERROR(VLOOKUP($H12,areaCercaPuntiClassificaSquadra,3,FALSE()),-1)=IFERROR(VLOOKUP($H$17,areaCercaPuntiClassificaSquadra,3,FALSE()),-2)),SUMIFS('Calendario A'!$N$8:$N$110,'Calendario A'!$M$8:$M$110,$H12,'Calendario A'!$T$8:$T$110,$H$17)+SUMIFS('Calendario A'!$U$8:$U$110,'Calendario A'!$T$8:$T$110,$H12,'Calendario A'!$M$8:$M$110,$H$17),"-") -> - | AE12: =IF(AND($H12<>"",$H$18<>"",$H12<>$H$18,IFERROR(VLOOKUP($H12,areaCercaPuntiClassificaSquadra,3,FALSE()),-1)=IFERROR(VLOOKUP($H$18,areaCercaPuntiClassificaSquadra,3,FALSE()),-2)),SUMIFS('Calendario A'!$N$8:$N$110,'Calendario A'!$M$8:$M$110,$H12,'Calendario A'!$T$8:$T$110,$H$18)+SUMIFS('Calendario A'!$U$8:$U$110,'Calendario A'!$T$8:$T$110,$H12,'Calendario A'!$M$8:$M$110,$H$18),"-") -> - | AF12: =IF(AND($H12<>"",$H$19<>"",$H12<>$H$19,IFERROR(VLOOKUP($H12,areaCercaPuntiClassificaSquadra,3,FALSE()),-1)=IFERROR(VLOOKUP($H$19,areaCercaPuntiClassificaSquadra,3,FALSE()),-2)),SUMIFS('Calendario A'!$N$8:$N$110,'Calendario A'!$M$8:$M$110,$H12,'Calendario A'!$T$8:$T$110,$H$19)+SUMIFS('Calendario A'!$U$8:$U$110,'Calendario A'!$T$8:$T$110,$H12,'Calendario A'!$M$8:$M$110,$H$19),"-") -> - | AG12: =$C12 -> Anaconde Arrabbiate-Anacondeopoli AE | AH12: =IF(AND($H12<>"",$H$12<>"",$H12<>$H$12,IFERROR(VLOOKUP($H12,areaCercaPuntiClassificaSquadra,3,FALSE()),-1)=IFERROR(VLOOKUP($H$12,areaCercaPuntiClassificaSquadra,3,FALSE()),-2)),SUMIFS('Calendario A'!$P$8:$P$110,'Calendario A'!$M$8:$M$110,$H12,'Calendario A'!$T$8:$T$110,$H$12)+SUMIFS('Calendario A'!$W$8:$W$110,'Calendario A'!$T$8:$T$110,$H12,'Calendario A'!$M$8:$M$110,$H$12)+SUMIFS('Calendario A'!$O$8:$O$110,'Calendario A'!$M$8:$M$110,$H12,'Calendario A'!$T$8:$T$110,$H$12)+SUMIFS('Calendario A'!$V$8:$V$110,'Calendario A'!$T$8:$T$110,$H12,'Calendario A'!$M$8:$M$110,$H$12),"-") -> - | AI12: =IF(AND($H12<>"",$H$13<>"",$H12<>$H$13,IFERROR(VLOOKUP($H12,areaCercaPuntiClassificaSquadra,3,FALSE()),-1)=IFERROR(VLOOKUP($H$13,areaCercaPuntiClassificaSquadra,3,FALSE()),-2)),SUMIFS('Calendario A'!$P$8:$P$110,'Calendario A'!$M$8:$M$110,$H12,'Calendario A'!$T$8:$T$110,$H$13)+SUMIFS('Calendario A'!$W$8:$W$110,'Calendario A'!$T$8:$T$110,$H12,'Calendario A'!$M$8:$M$110,$H$13)+SUMIFS('Calendario A'!$O$8:$O$110,'Calendario A'!$M$8:$M$110,$H12,'Calendario A'!$T$8:$T$110,$H$13)+SUMIFS('Calendario A'!$V$8:$V$110,'Calendario A'!$T$8:$T$110,$H12,'Calendario A'!$M$8:$M$110,$H$13),"-") -> - | AJ12: =IF(AND($H12<>"",$H$14<>"",$H12<>$H$14,IFERROR(VLOOKUP($H12,areaCercaPuntiClassificaSquadra,3,FALSE()),-1)=IFERROR(VLOOKUP($H$14,areaCercaPuntiClassificaSquadra,3,FALSE()),-2)),SUMIFS('Calendario A'!$P$8:$P$110,'Calendario A'!$M$8:$M$110,$H12,'Calendario A'!$T$8:$T$110,$H$14)+SUMIFS('Calendario A'!$W$8:$W$110,'Calendario A'!$T$8:$T$110,$H12,'Calendario A'!$M$8:$M$110,$H$14)+SUMIFS('Calendario A'!$O$8:$O$110,'Calendario A'!$M$8:$M$110,$H12,'Calendario A'!$T$8:$T$110,$H$14)+SUMIFS('Calendario A'!$V$8:$V$110,'Calendario A'!$T$8:$T$110,$H12,'Calendario A'!$M$8:$M$110,$H$14),"-") -> - | AK12: =IF(AND($H12<>"",$H$15<>"",$H12<>$H$15,IFERROR(VLOOKUP($H12,areaCercaPuntiClassificaSquadra,3,FALSE()),-1)=IFERROR(VLOOKUP($H$15,areaCercaPuntiClassificaSquadra,3,FALSE()),-2)),SUMIFS('Calendario A'!$P$8:$P$110,'Calendario A'!$M$8:$M$110,$H12,'Calendario A'!$T$8:$T$110,$H$15)+SUMIFS('Calendario A'!$W$8:$W$110,'Calendario A'!$T$8:$T$110,$H12,'Calendario A'!$M$8:$M$110,$H$15)+SUMIFS('Calendario A'!$O$8:$O$110,'Calendario A'!$M$8:$M$110,$H12,'Calendario A'!$T$8:$T$110,$H$15)+SUMIFS('Calendario A'!$V$8:$V$110,'Calendario A'!$T$8:$T$110,$H12,'Calendario A'!$M$8:$M$110,$H$15),"-") -> - | AL12: =IF(AND($H12<>"",$H$16<>"",$H12<>$H$16,IFERROR(VLOOKUP($H12,areaCercaPuntiClassificaSquadra,3,FALSE()),-1)=IFERROR(VLOOKUP($H$16,areaCercaPuntiClassificaSquadra,3,FALSE()),-2)),SUMIFS('Calendario A'!$P$8:$P$110,'Calendario A'!$M$8:$M$110,$H12,'Calendario A'!$T$8:$T$110,$H$16)+SUMIFS('Calendario A'!$W$8:$W$110,'Calendario A'!$T$8:$T$110,$H12,'Calendario A'!$M$8:$M$110,$H$16)+SUMIFS('Calendario A'!$O$8:$O$110,'Calendario A'!$M$8:$M$110,$H12,'Calendario A'!$T$8:$T$110,$H$16)+SUMIFS('Calendario A'!$V$8:$V$110,'Calendario A'!$T$8:$T$110,$H12,'Calendario A'!$M$8:$M$110,$H$16),"-") -> - | AM12: =IF(AND($H12<>"",$H$17<>"",$H12<>$H$17,IFERROR(VLOOKUP($H12,areaCercaPuntiClassificaSquadra,3,FALSE()),-1)=IFERROR(VLOOKUP($H$17,areaCercaPuntiClassificaSquadra,3,FALSE()),-2)),SUMIFS('Calendario A'!$P$8:$P$110,'Calendario A'!$M$8:$M$110,$H12,'Calendario A'!$T$8:$T$110,$H$17)+SUMIFS('Calendario A'!$W$8:$W$110,'Calendario A'!$T$8:$T$110,$H12,'Calendario A'!$M$8:$M$110,$H$17)+SUMIFS('Calendario A'!$O$8:$O$110,'Calendario A'!$M$8:$M$110,$H12,'Calendario A'!$T$8:$T$110,$H$17)+SUMIFS('Calendario A'!$V$8:$V$110,'Calendario A'!$T$8:$T$110,$H12,'Calendario A'!$M$8:$M$110,$H$17),"-") -> - | AN12: =IF(AND($H12<>"",$H$18<>"",$H12<>$H$18,IFERROR(VLOOKUP($H12,areaCercaPuntiClassificaSquadra,3,FALSE()),-1)=IFERROR(VLOOKUP($H$18,areaCercaPuntiClassificaSquadra,3,FALSE()),-2)),SUMIFS('Calendario A'!$P$8:$P$110,'Calendario A'!$M$8:$M$110,$H12,'Calendario A'!$T$8:$T$110,$H$18)+SUMIFS('Calendario A'!$W$8:$W$110,'Calendario A'!$T$8:$T$110,$H12,'Calendario A'!$M$8:$M$110,$H$18)+SUMIFS('Calendario A'!$O$8:$O$110,'Calendario A'!$M$8:$M$110,$H12,'Calendario A'!$T$8:$T$110,$H$18)+SUMIFS('Calendario A'!$V$8:$V$110,'Calendario A'!$T$8:$T$110,$H12,'Calendario A'!$M$8:$M$110,$H$18),"-") -> - | AO12: =IF(AND($H12<>"",$H$19<>"",$H12<>$H$19,IFERROR(VLOOKUP($H12,areaCercaPuntiClassificaSquadra,3,FALSE()),-1)=IFERROR(VLOOKUP($H$19,areaCercaPuntiClassificaSquadra,3,FALSE()),-2)),SUMIFS('Calendario A'!$P$8:$P$110,'Calendario A'!$M$8:$M$110,$H12,'Calendario A'!$T$8:$T$110,$H$19)+SUMIFS('Calendario A'!$W$8:$W$110,'Calendario A'!$T$8:$T$110,$H12,'Calendario A'!$M$8:$M$110,$H$19)+SUMIFS('Calendario A'!$O$8:$O$110,'Calendario A'!$M$8:$M$110,$H12,'Calendario A'!$T$8:$T$110,$H$19)+SUMIFS('Calendario A'!$V$8:$V$110,'Calendario A'!$T$8:$T$110,$H12,'Calendario A'!$M$8:$M$110,$H$19),"-") -> - | AP12: =$C12 -> Anaconde Arrabbiate-Anacondeopoli AE | AQ12: =IF(AND($H12<>"",$H$12<>"",$H12<>$H$12,IFERROR(VLOOKUP($H12,areaCercaPuntiClassificaSquadra,3,FALSE()),-1)=IFERROR(VLOOKUP($H$12,areaCercaPuntiClassificaSquadra,3,FALSE()),-2)),SUMIFS('Calendario A'!$Q$8:$Q$110,'Calendario A'!$M$8:$M$110,$H12,'Calendario A'!$T$8:$T$110,$H$12)+SUMIFS('Calendario A'!$X$8:$X$110,'Calendario A'!$T$8:$T$110,$H12,'Calendario A'!$M$8:$M$110,$H$12),"-") -> - | AR12: =IF(AND($H12<>"",$H$13<>"",$H12<>$H$13,IFERROR(VLOOKUP($H12,areaCercaPuntiClassificaSquadra,3,FALSE()),-1)=IFERROR(VLOOKUP($H$13,areaCercaPuntiClassificaSquadra,3,FALSE()),-2)),SUMIFS('Calendario A'!$Q$8:$Q$110,'Calendario A'!$M$8:$M$110,$H12,'Calendario A'!$T$8:$T$110,$H$13)+SUMIFS('Calendario A'!$X$8:$X$110,'Calendario A'!$T$8:$T$110,$H12,'Calendario A'!$M$8:$M$110,$H$13),"-") -> - | AS12: =IF(AND($H12<>"",$H$14<>"",$H12<>$H$14,IFERROR(VLOOKUP($H12,areaCercaPuntiClassificaSquadra,3,FALSE()),-1)=IFERROR(VLOOKUP($H$14,areaCercaPuntiClassificaSquadra,3,FALSE()),-2)),SUMIFS('Calendario A'!$Q$8:$Q$110,'Calendario A'!$M$8:$M$110,$H12,'Calendario A'!$T$8:$T$110,$H$14)+SUMIFS('Calendario A'!$X$8:$X$110,'Calendario A'!$T$8:$T$110,$H12,'Calendario A'!$M$8:$M$110,$H$14),"-") -> - | AT12: =IF(AND($H12<>"",$H$15<>"",$H12<>$H$15,IFERROR(VLOOKUP($H12,areaCercaPuntiClassificaSquadra,3,FALSE()),-1)=IFERROR(VLOOKUP($H$15,areaCercaPuntiClassificaSquadra,3,FALSE()),-2)),SUMIFS('Calendario A'!$Q$8:$Q$110,'Calendario A'!$M$8:$M$110,$H12,'Calendario A'!$T$8:$T$110,$H$15)+SUMIFS('Calendario A'!$X$8:$X$110,'Calendario A'!$T$8:$T$110,$H12,'Calendario A'!$M$8:$M$110,$H$15),"-") -> - | AU12: =IF(AND($H12<>"",$H$16<>"",$H12<>$H$16,IFERROR(VLOOKUP($H12,areaCercaPuntiClassificaSquadra,3,FALSE()),-1)=IFERROR(VLOOKUP($H$16,areaCercaPuntiClassificaSquadra,3,FALSE()),-2)),SUMIFS('Calendario A'!$Q$8:$Q$110,'Calendario A'!$M$8:$M$110,$H12,'Calendario A'!$T$8:$T$110,$H$16)+SUMIFS('Calendario A'!$X$8:$X$110,'Calendario A'!$T$8:$T$110,$H12,'Calendario A'!$M$8:$M$110,$H$16),"-") -> - | AV12: =IF(AND($H12<>"",$H$17<>"",$H12<>$H$17,IFERROR(VLOOKUP($H12,areaCercaPuntiClassificaSquadra,3,FALSE()),-1)=IFERROR(VLOOKUP($H$17,areaCercaPuntiClassificaSquadra,3,FALSE()),-2)),SUMIFS('Calendario A'!$Q$8:$Q$110,'Calendario A'!$M$8:$M$110,$H12,'Calendario A'!$T$8:$T$110,$H$17)+SUMIFS('Calendario A'!$X$8:$X$110,'Calendario A'!$T$8:$T$110,$H12,'Calendario A'!$M$8:$M$110,$H$17),"-") -> - | AW12: =IF(AND($H12<>"",$H$18<>"",$H12<>$H$18,IFERROR(VLOOKUP($H12,areaCercaPuntiClassificaSquadra,3,FALSE()),-1)=IFERROR(VLOOKUP($H$18,areaCercaPuntiClassificaSquadra,3,FALSE()),-2)),SUMIFS('Calendario A'!$Q$8:$Q$110,'Calendario A'!$M$8:$M$110,$H12,'Calendario A'!$T$8:$T$110,$H$18)+SUMIFS('Calendario A'!$X$8:$X$110,'Calendario A'!$T$8:$T$110,$H12,'Calendario A'!$M$8:$M$110,$H$18),"-") -> - | AX12: =IF(AND($H12<>"",$H$19<>"",$H12<>$H$19,IFERROR(VLOOKUP($H12,areaCercaPuntiClassificaSquadra,3,FALSE()),-1)=IFERROR(VLOOKUP($H$19,areaCercaPuntiClassificaSquadra,3,FALSE()),-2)),SUMIFS('Calendario A'!$Q$8:$Q$110,'Calendario A'!$M$8:$M$110,$H12,'Calendario A'!$T$8:$T$110,$H$19)+SUMIFS('Calendario A'!$X$8:$X$110,'Calendario A'!$T$8:$T$110,$H12,'Calendario A'!$M$8:$M$110,$H$19),"-") -> - | AY12: =$C12 -> Anaconde Arrabbiate-Anacondeopoli AE | AZ12: =IF(AND($H12<>"",$H$12<>"",$H12<>$H$12,IFERROR(VLOOKUP($H12,areaCercaPuntiClassificaSquadra,3,FALSE()),-1)=IFERROR(VLOOKUP($H$12,areaCercaPuntiClassificaSquadra,3,FALSE()),-2)),SUMIFS('Calendario A'!$R$8:$R$110,'Calendario A'!$M$8:$M$110,$H12,'Calendario A'!$T$8:$T$110,$H$12)+SUMIFS('Calendario A'!$Y$8:$Y$110,'Calendario A'!$T$8:$T$110,$H12,'Calendario A'!$M$8:$M$110,$H$12),"-") -> - | BA12: =IF(AND($H12<>"",$H$13<>"",$H12<>$H$13,IFERROR(VLOOKUP($H12,areaCercaPuntiClassificaSquadra,3,FALSE()),-1)=IFERROR(VLOOKUP($H$13,areaCercaPuntiClassificaSquadra,3,FALSE()),-2)),SUMIFS('Calendario A'!$R$8:$R$110,'Calendario A'!$M$8:$M$110,$H12,'Calendario A'!$T$8:$T$110,$H$13)+SUMIFS('Calendario A'!$Y$8:$Y$110,'Calendario A'!$T$8:$T$110,$H12,'Calendario A'!$M$8:$M$110,$H$13),"-") -> - | BB12: =IF(AND($H12<>"",$H$14<>"",$H12<>$H$14,IFERROR(VLOOKUP($H12,areaCercaPuntiClassificaSquadra,3,FALSE()),-1)=IFERROR(VLOOKUP($H$14,areaCercaPuntiClassificaSquadra,3,FALSE()),-2)),SUMIFS('Calendario A'!$R$8:$R$110,'Calendario A'!$M$8:$M$110,$H12,'Calendario A'!$T$8:$T$110,$H$14)+SUMIFS('Calendario A'!$Y$8:$Y$110,'Calendario A'!$T$8:$T$110,$H12,'Calendario A'!$M$8:$M$110,$H$14),"-") -> - | BC12: =IF(AND($H12<>"",$H$15<>"",$H12<>$H$15,IFERROR(VLOOKUP($H12,areaCercaPuntiClassificaSquadra,3,FALSE()),-1)=IFERROR(VLOOKUP($H$15,areaCercaPuntiClassificaSquadra,3,FALSE()),-2)),SUMIFS('Calendario A'!$R$8:$R$110,'Calendario A'!$M$8:$M$110,$H12,'Calendario A'!$T$8:$T$110,$H$15)+SUMIFS('Calendario A'!$Y$8:$Y$110,'Calendario A'!$T$8:$T$110,$H12,'Calendario A'!$M$8:$M$110,$H$15),"-") -> - | BD12: =IF(AND($H12<>"",$H$16<>"",$H12<>$H$16,IFERROR(VLOOKUP($H12,areaCercaPuntiClassificaSquadra,3,FALSE()),-1)=IFERROR(VLOOKUP($H$16,areaCercaPuntiClassificaSquadra,3,FALSE()),-2)),SUMIFS('Calendario A'!$R$8:$R$110,'Calendario A'!$M$8:$M$110,$H12,'Calendario A'!$T$8:$T$110,$H$16)+SUMIFS('Calendario A'!$Y$8:$Y$110,'Calendario A'!$T$8:$T$110,$H12,'Calendario A'!$M$8:$M$110,$H$16),"-") -> - | BE12: =IF(AND($H12<>"",$H$17<>"",$H12<>$H$17,IFERROR(VLOOKUP($H12,areaCercaPuntiClassificaSquadra,3,FALSE()),-1)=IFERROR(VLOOKUP($H$17,areaCercaPuntiClassificaSquadra,3,FALSE()),-2)),SUMIFS('Calendario A'!$R$8:$R$110,'Calendario A'!$M$8:$M$110,$H12,'Calendario A'!$T$8:$T$110,$H$17)+SUMIFS('Calendario A'!$Y$8:$Y$110,'Calendario A'!$T$8:$T$110,$H12,'Calendario A'!$M$8:$M$110,$H$17),"-") -> - | BF12: =IF(AND($H12<>"",$H$18<>"",$H12<>$H$18,IFERROR(VLOOKUP($H12,areaCercaPuntiClassificaSquadra,3,FALSE()),-1)=IFERROR(VLOOKUP($H$18,areaCercaPuntiClassificaSquadra,3,FALSE()),-2)),SUMIFS('Calendario A'!$R$8:$R$110,'Calendario A'!$M$8:$M$110,$H12,'Calendario A'!$T$8:$T$110,$H$18)+SUMIFS('Calendario A'!$Y$8:$Y$110,'Calendario A'!$T$8:$T$110,$H12,'Calendario A'!$M$8:$M$110,$H$18),"-") -> - | BG12: =IF(AND($H12<>"",$H$19<>"",$H12<>$H$19,IFERROR(VLOOKUP($H12,areaCercaPuntiClassificaSquadra,3,FALSE()),-1)=IFERROR(VLOOKUP($H$19,areaCercaPuntiClassificaSquadra,3,FALSE()),-2)),SUMIFS('Calendario A'!$R$8:$R$110,'Calendario A'!$M$8:$M$110,$H12,'Calendario A'!$T$8:$T$110,$H$19)+SUMIFS('Calendario A'!$Y$8:$Y$110,'Calendario A'!$T$8:$T$110,$H12,'Calendario A'!$M$8:$M$110,$H$19),"-") -> -
B13: A02 | C13: Bufali Belligeranti-Bufaliopoli BI | E13: A | G13: =IF($C13="","",$E13&(COUNTIFS(I$12:I$75,">"&I13,E$12:E$75,"="&E13,C$12:C$75,"<>")+COUNTIFS(I$12:I$75,"="&I13,H$12:H$75,"<="&H13,E$12:E$75,"="&E13,C$12:C$75,"<>"))) -> A7 | H13: =IF($C13="","",IFERROR(LEFT($C13,FIND("-",$C13)-1),$C13)) -> Bufali Belligeranti | I13: =TEXT(1000000000+J13,"|0000000000|")&TEXT(SUM(Y13:AF13),"0000000000|")&IF(SUM(AZ13:BG13)=0,"0000000000|",TEXT(ROUND(SUM(AQ13:AX13)/SUM(AZ13:BG13),4)*100000,"0000000000|"))&IF(P13=0,"0000000000|",TEXT(ROUND(O13/P13,4)*100000,"0000000000|")) -> |1000000009|0000000001|0000154170|0000091310| | J13: =L13*constPuntiVittoria+M13*constPuntiSconfitta+N13*constPuntiForfait+IF(D13="",0,D13) -> 9 | K13: =SUM(L13:N13) -> 7 | L13: =IF($H13="",0,SUMIF('Calendario A'!$M$8:$M$110,$H13,'Calendario A'!$N$8:$N$110)+SUMIF('Calendario A'!$T$8:$T$110,$H13,'Calendario A'!$U$8:$U$110)) -> 1 | M13: =IF($H13="",0,SUMIF('Calendario A'!$M$8:$M$110,$H13,'Calendario A'!$P$8:$P$110)+SUMIF('Calendario A'!$T$8:$T$110,$H13,'Calendario A'!$W$8:$W$110)) -> 6 | N13: =IF($H13="",0,SUMIF('Calendario A'!$M$8:$M$110,$H13,'Calendario A'!$O$8:$O$110)+SUMIF('Calendario A'!$T$8:$T$110,$H13,'Calendario A'!$V$8:$V$110)) -> 0 | O13: =IF($H13="",0,SUMIF('Calendario A'!$M$8:$M$110,$H13,'Calendario A'!$Q$8:$Q$110)+SUMIF('Calendario A'!$T$8:$T$110,$H13,'Calendario A'!$X$8:$X$110)) -> 431 | P13: =IF($H13="",0,SUMIF('Calendario A'!$M$8:$M$110,$H13,'Calendario A'!$R$8:$R$110)+SUMIF('Calendario A'!$T$8:$T$110,$H13,'Calendario A'!$Y$8:$Y$110)) -> 472 | Q13: =IF($H13="",0,SUMIF('Calendario A'!$M$8:$M$110,$H13,'Calendario A'!$S$8:$S$110)+SUMIF('Calendario A'!$T$8:$T$110,$H13,'Calendario A'!$Z$8:$Z$110)) -> -41 | R13: =IF(K13=0,0,ROUND(O13/K13,2)) -> 61.57 | S13: =IF(K13=0,0,ROUND(P13/K13,2)) -> 67.43 | T13: =IF(K13=0,0,ROUND(Q13/K13,2)) -> -5.86 | U13: =IF(COUNT(Y13:AF13)=0,"-",SUM(Y13:AF13)&"-"&SUM(AH13:AO13)) -> 1-0 | V13: =IF(COUNT(Y13:AF13)=0,"-",IF(SUM(AZ13:BG13)=0,TEXT(0,"0.0000"),TEXT(ROUND(SUM(AQ13:AX13)/SUM(AZ13:BG13),4),"0.0000"))) -> 1.5417 | W13: =IF(H13="","-",IF(P13=0,TEXT(0,"0.0000"),TEXT(ROUND(O13/P13,4),"0.0000"))) -> 0.9131 | X13: =$C13 -> Bufali Belligeranti-Bufaliopoli BI | Y13: =IF(AND($H13<>"",$H$12<>"",$H13<>$H$12,IFERROR(VLOOKUP($H13,areaCercaPuntiClassificaSquadra,3,FALSE()),-1)=IFERROR(VLOOKUP($H$12,areaCercaPuntiClassificaSquadra,3,FALSE()),-2)),SUMIFS('Calendario A'!$N$8:$N$110,'Calendario A'!$M$8:$M$110,$H13,'Calendario A'!$T$8:$T$110,$H$12)+SUMIFS('Calendario A'!$U$8:$U$110,'Calendario A'!$T$8:$T$110,$H13,'Calendario A'!$M$8:$M$110,$H$12),"-") -> - | Z13: =IF(AND($H13<>"",$H$13<>"",$H13<>$H$13,IFERROR(VLOOKUP($H13,areaCercaPuntiClassificaSquadra,3,FALSE()),-1)=IFERROR(VLOOKUP($H$13,areaCercaPuntiClassificaSquadra,3,FALSE()),-2)),SUMIFS('Calendario A'!$N$8:$N$110,'Calendario A'!$M$8:$M$110,$H13,'Calendario A'!$T$8:$T$110,$H$13)+SUMIFS('Calendario A'!$U$8:$U$110,'Calendario A'!$T$8:$T$110,$H13,'Calendario A'!$M$8:$M$110,$H$13),"-") -> - | AA13: =IF(AND($H13<>"",$H$14<>"",$H13<>$H$14,IFERROR(VLOOKUP($H13,areaCercaPuntiClassificaSquadra,3,FALSE()),-1)=IFERROR(VLOOKUP($H$14,areaCercaPuntiClassificaSquadra,3,FALSE()),-2)),SUMIFS('Calendario A'!$N$8:$N$110,'Calendario A'!$M$8:$M$110,$H13,'Calendario A'!$T$8:$T$110,$H$14)+SUMIFS('Calendario A'!$U$8:$U$110,'Calendario A'!$T$8:$T$110,$H13,'Calendario A'!$M$8:$M$110,$H$14),"-") -> - | AB13: =IF(AND($H13<>"",$H$15<>"",$H13<>$H$15,IFERROR(VLOOKUP($H13,areaCercaPuntiClassificaSquadra,3,FALSE()),-1)=IFERROR(VLOOKUP($H$15,areaCercaPuntiClassificaSquadra,3,FALSE()),-2)),SUMIFS('Calendario A'!$N$8:$N$110,'Calendario A'!$M$8:$M$110,$H13,'Calendario A'!$T$8:$T$110,$H$15)+SUMIFS('Calendario A'!$U$8:$U$110,'Calendario A'!$T$8:$T$110,$H13,'Calendario A'!$M$8:$M$110,$H$15),"-") -> 1 | AC13: =IF(AND($H13<>"",$H$16<>"",$H13<>$H$16,IFERROR(VLOOKUP($H13,areaCercaPuntiClassificaSquadra,3,FALSE()),-1)=IFERROR(VLOOKUP($H$16,areaCercaPuntiClassificaSquadra,3,FALSE()),-2)),SUMIFS('Calendario A'!$N$8:$N$110,'Calendario A'!$M$8:$M$110,$H13,'Calendario A'!$T$8:$T$110,$H$16)+SUMIFS('Calendario A'!$U$8:$U$110,'Calendario A'!$T$8:$T$110,$H13,'Calendario A'!$M$8:$M$110,$H$16),"-") -> - | AD13: =IF(AND($H13<>"",$H$17<>"",$H13<>$H$17,IFERROR(VLOOKUP($H13,areaCercaPuntiClassificaSquadra,3,FALSE()),-1)=IFERROR(VLOOKUP($H$17,areaCercaPuntiClassificaSquadra,3,FALSE()),-2)),SUMIFS('Calendario A'!$N$8:$N$110,'Calendario A'!$M$8:$M$110,$H13,'Calendario A'!$T$8:$T$110,$H$17)+SUMIFS('Calendario A'!$U$8:$U$110,'Calendario A'!$T$8:$T$110,$H13,'Calendario A'!$M$8:$M$110,$H$17),"-") -> - | AE13: =IF(AND($H13<>"",$H$18<>"",$H13<>$H$18,IFERROR(VLOOKUP($H13,areaCercaPuntiClassificaSquadra,3,FALSE()),-1)=IFERROR(VLOOKUP($H$18,areaCercaPuntiClassificaSquadra,3,FALSE()),-2)),SUMIFS('Calendario A'!$N$8:$N$110,'Calendario A'!$M$8:$M$110,$H13,'Calendario A'!$T$8:$T$110,$H$18)+SUMIFS('Calendario A'!$U$8:$U$110,'Calendario A'!$T$8:$T$110,$H13,'Calendario A'!$M$8:$M$110,$H$18),"-") -> - | AF13: =IF(AND($H13<>"",$H$19<>"",$H13<>$H$19,IFERROR(VLOOKUP($H13,areaCercaPuntiClassificaSquadra,3,FALSE()),-1)=IFERROR(VLOOKUP($H$19,areaCercaPuntiClassificaSquadra,3,FALSE()),-2)),SUMIFS('Calendario A'!$N$8:$N$110,'Calendario A'!$M$8:$M$110,$H13,'Calendario A'!$T$8:$T$110,$H$19)+SUMIFS('Calendario A'!$U$8:$U$110,'Calendario A'!$T$8:$T$110,$H13,'Calendario A'!$M$8:$M$110,$H$19),"-") -> - | AG13: =$C13 -> Bufali Belligeranti-Bufaliopoli BI | AH13: =IF(AND($H13<>"",$H$12<>"",$H13<>$H$12,IFERROR(VLOOKUP($H13,areaCercaPuntiClassificaSquadra,3,FALSE()),-1)=IFERROR(VLOOKUP($H$12,areaCercaPuntiClassificaSquadra,3,FALSE()),-2)),SUMIFS('Calendario A'!$P$8:$P$110,'Calendario A'!$M$8:$M$110,$H13,'Calendario A'!$T$8:$T$110,$H$12)+SUMIFS('Calendario A'!$W$8:$W$110,'Calendario A'!$T$8:$T$110,$H13,'Calendario A'!$M$8:$M$110,$H$12)+SUMIFS('Calendario A'!$O$8:$O$110,'Calendario A'!$M$8:$M$110,$H13,'Calendario A'!$T$8:$T$110,$H$12)+SUMIFS('Calendario A'!$V$8:$V$110,'Calendario A'!$T$8:$T$110,$H13,'Calendario A'!$M$8:$M$110,$H$12),"-") -> - | AI13: =IF(AND($H13<>"",$H$13<>"",$H13<>$H$13,IFERROR(VLOOKUP($H13,areaCercaPuntiClassificaSquadra,3,FALSE()),-1)=IFERROR(VLOOKUP($H$13,areaCercaPuntiClassificaSquadra,3,FALSE()),-2)),SUMIFS('Calendario A'!$P$8:$P$110,'Calendario A'!$M$8:$M$110,$H13,'Calendario A'!$T$8:$T$110,$H$13)+SUMIFS('Calendario A'!$W$8:$W$110,'Calendario A'!$T$8:$T$110,$H13,'Calendario A'!$M$8:$M$110,$H$13)+SUMIFS('Calendario A'!$O$8:$O$110,'Calendario A'!$M$8:$M$110,$H13,'Calendario A'!$T$8:$T$110,$H$13)+SUMIFS('Calendario A'!$V$8:$V$110,'Calendario A'!$T$8:$T$110,$H13,'Calendario A'!$M$8:$M$110,$H$13),"-") -> - | AJ13: =IF(AND($H13<>"",$H$14<>"",$H13<>$H$14,IFERROR(VLOOKUP($H13,areaCercaPuntiClassificaSquadra,3,FALSE()),-1)=IFERROR(VLOOKUP($H$14,areaCercaPuntiClassificaSquadra,3,FALSE()),-2)),SUMIFS('Calendario A'!$P$8:$P$110,'Calendario A'!$M$8:$M$110,$H13,'Calendario A'!$T$8:$T$110,$H$14)+SUMIFS('Calendario A'!$W$8:$W$110,'Calendario A'!$T$8:$T$110,$H13,'Calendario A'!$M$8:$M$110,$H$14)+SUMIFS('Calendario A'!$O$8:$O$110,'Calendario A'!$M$8:$M$110,$H13,'Calendario A'!$T$8:$T$110,$H$14)+SUMIFS('Calendario A'!$V$8:$V$110,'Calendario A'!$T$8:$T$110,$H13,'Calendario A'!$M$8:$M$110,$H$14),"-") -> - | AK13: =IF(AND($H13<>"",$H$15<>"",$H13<>$H$15,IFERROR(VLOOKUP($H13,areaCercaPuntiClassificaSquadra,3,FALSE()),-1)=IFERROR(VLOOKUP($H$15,areaCercaPuntiClassificaSquadra,3,FALSE()),-2)),SUMIFS('Calendario A'!$P$8:$P$110,'Calendario A'!$M$8:$M$110,$H13,'Calendario A'!$T$8:$T$110,$H$15)+SUMIFS('Calendario A'!$W$8:$W$110,'Calendario A'!$T$8:$T$110,$H13,'Calendario A'!$M$8:$M$110,$H$15)+SUMIFS('Calendario A'!$O$8:$O$110,'Calendario A'!$M$8:$M$110,$H13,'Calendario A'!$T$8:$T$110,$H$15)+SUMIFS('Calendario A'!$V$8:$V$110,'Calendario A'!$T$8:$T$110,$H13,'Calendario A'!$M$8:$M$110,$H$15),"-") -> 0 | AL13: =IF(AND($H13<>"",$H$16<>"",$H13<>$H$16,IFERROR(VLOOKUP($H13,areaCercaPuntiClassificaSquadra,3,FALSE()),-1)=IFERROR(VLOOKUP($H$16,areaCercaPuntiClassificaSquadra,3,FALSE()),-2)),SUMIFS('Calendario A'!$P$8:$P$110,'Calendario A'!$M$8:$M$110,$H13,'Calendario A'!$T$8:$T$110,$H$16)+SUMIFS('Calendario A'!$W$8:$W$110,'Calendario A'!$T$8:$T$110,$H13,'Calendario A'!$M$8:$M$110,$H$16)+SUMIFS('Calendario A'!$O$8:$O$110,'Calendario A'!$M$8:$M$110,$H13,'Calendario A'!$T$8:$T$110,$H$16)+SUMIFS('Calendario A'!$V$8:$V$110,'Calendario A'!$T$8:$T$110,$H13,'Calendario A'!$M$8:$M$110,$H$16),"-") -> - | AM13: =IF(AND($H13<>"",$H$17<>"",$H13<>$H$17,IFERROR(VLOOKUP($H13,areaCercaPuntiClassificaSquadra,3,FALSE()),-1)=IFERROR(VLOOKUP($H$17,areaCercaPuntiClassificaSquadra,3,FALSE()),-2)),SUMIFS('Calendario A'!$P$8:$P$110,'Calendario A'!$M$8:$M$110,$H13,'Calendario A'!$T$8:$T$110,$H$17)+SUMIFS('Calendario A'!$W$8:$W$110,'Calendario A'!$T$8:$T$110,$H13,'Calendario A'!$M$8:$M$110,$H$17)+SUMIFS('Calendario A'!$O$8:$O$110,'Calendario A'!$M$8:$M$110,$H13,'Calendario A'!$T$8:$T$110,$H$17)+SUMIFS('Calendario A'!$V$8:$V$110,'Calendario A'!$T$8:$T$110,$H13,'Calendario A'!$M$8:$M$110,$H$17),"-") -> - | AN13: =IF(AND($H13<>"",$H$18<>"",$H13<>$H$18,IFERROR(VLOOKUP($H13,areaCercaPuntiClassificaSquadra,3,FALSE()),-1)=IFERROR(VLOOKUP($H$18,areaCercaPuntiClassificaSquadra,3,FALSE()),-2)),SUMIFS('Calendario A'!$P$8:$P$110,'Calendario A'!$M$8:$M$110,$H13,'Calendario A'!$T$8:$T$110,$H$18)+SUMIFS('Calendario A'!$W$8:$W$110,'Calendario A'!$T$8:$T$110,$H13,'Calendario A'!$M$8:$M$110,$H$18)+SUMIFS('Calendario A'!$O$8:$O$110,'Calendario A'!$M$8:$M$110,$H13,'Calendario A'!$T$8:$T$110,$H$18)+SUMIFS('Calendario A'!$V$8:$V$110,'Calendario A'!$T$8:$T$110,$H13,'Calendario A'!$M$8:$M$110,$H$18),"-") -> - | AO13: =IF(AND($H13<>"",$H$19<>"",$H13<>$H$19,IFERROR(VLOOKUP($H13,areaCercaPuntiClassificaSquadra,3,FALSE()),-1)=IFERROR(VLOOKUP($H$19,areaCercaPuntiClassificaSquadra,3,FALSE()),-2)),SUMIFS('Calendario A'!$P$8:$P$110,'Calendario A'!$M$8:$M$110,$H13,'Calendario A'!$T$8:$T$110,$H$19)+SUMIFS('Calendario A'!$W$8:$W$110,'Calendario A'!$T$8:$T$110,$H13,'Calendario A'!$M$8:$M$110,$H$19)+SUMIFS('Calendario A'!$O$8:$O$110,'Calendario A'!$M$8:$M$110,$H13,'Calendario A'!$T$8:$T$110,$H$19)+SUMIFS('Calendario A'!$V$8:$V$110,'Calendario A'!$T$8:$T$110,$H13,'Calendario A'!$M$8:$M$110,$H$19),"-") -> - | AP13: =$C13 -> Bufali Belligeranti-Bufaliopoli BI | AQ13: =IF(AND($H13<>"",$H$12<>"",$H13<>$H$12,IFERROR(VLOOKUP($H13,areaCercaPuntiClassificaSquadra,3,FALSE()),-1)=IFERROR(VLOOKUP($H$12,areaCercaPuntiClassificaSquadra,3,FALSE()),-2)),SUMIFS('Calendario A'!$Q$8:$Q$110,'Calendario A'!$M$8:$M$110,$H13,'Calendario A'!$T$8:$T$110,$H$12)+SUMIFS('Calendario A'!$X$8:$X$110,'Calendario A'!$T$8:$T$110,$H13,'Calendario A'!$M$8:$M$110,$H$12),"-") -> - | AR13: =IF(AND($H13<>"",$H$13<>"",$H13<>$H$13,IFERROR(VLOOKUP($H13,areaCercaPuntiClassificaSquadra,3,FALSE()),-1)=IFERROR(VLOOKUP($H$13,areaCercaPuntiClassificaSquadra,3,FALSE()),-2)),SUMIFS('Calendario A'!$Q$8:$Q$110,'Calendario A'!$M$8:$M$110,$H13,'Calendario A'!$T$8:$T$110,$H$13)+SUMIFS('Calendario A'!$X$8:$X$110,'Calendario A'!$T$8:$T$110,$H13,'Calendario A'!$M$8:$M$110,$H$13),"-") -> - | AS13: =IF(AND($H13<>"",$H$14<>"",$H13<>$H$14,IFERROR(VLOOKUP($H13,areaCercaPuntiClassificaSquadra,3,FALSE()),-1)=IFERROR(VLOOKUP($H$14,areaCercaPuntiClassificaSquadra,3,FALSE()),-2)),SUMIFS('Calendario A'!$Q$8:$Q$110,'Calendario A'!$M$8:$M$110,$H13,'Calendario A'!$T$8:$T$110,$H$14)+SUMIFS('Calendario A'!$X$8:$X$110,'Calendario A'!$T$8:$T$110,$H13,'Calendario A'!$M$8:$M$110,$H$14),"-") -> - | AT13: =IF(AND($H13<>"",$H$15<>"",$H13<>$H$15,IFERROR(VLOOKUP($H13,areaCercaPuntiClassificaSquadra,3,FALSE()),-1)=IFERROR(VLOOKUP($H$15,areaCercaPuntiClassificaSquadra,3,FALSE()),-2)),SUMIFS('Calendario A'!$Q$8:$Q$110,'Calendario A'!$M$8:$M$110,$H13,'Calendario A'!$T$8:$T$110,$H$15)+SUMIFS('Calendario A'!$X$8:$X$110,'Calendario A'!$T$8:$T$110,$H13,'Calendario A'!$M$8:$M$110,$H$15),"-") -> 74 | AU13: =IF(AND($H13<>"",$H$16<>"",$H13<>$H$16,IFERROR(VLOOKUP($H13,areaCercaPuntiClassificaSquadra,3,FALSE()),-1)=IFERROR(VLOOKUP($H$16,areaCercaPuntiClassificaSquadra,3,FALSE()),-2)),SUMIFS('Calendario A'!$Q$8:$Q$110,'Calendario A'!$M$8:$M$110,$H13,'Calendario A'!$T$8:$T$110,$H$16)+SUMIFS('Calendario A'!$X$8:$X$110,'Calendario A'!$T$8:$T$110,$H13,'Calendario A'!$M$8:$M$110,$H$16),"-") -> - | AV13: =IF(AND($H13<>"",$H$17<>"",$H13<>$H$17,IFERROR(VLOOKUP($H13,areaCercaPuntiClassificaSquadra,3,FALSE()),-1)=IFERROR(VLOOKUP($H$17,areaCercaPuntiClassificaSquadra,3,FALSE()),-2)),SUMIFS('Calendario A'!$Q$8:$Q$110,'Calendario A'!$M$8:$M$110,$H13,'Calendario A'!$T$8:$T$110,$H$17)+SUMIFS('Calendario A'!$X$8:$X$110,'Calendario A'!$T$8:$T$110,$H13,'Calendario A'!$M$8:$M$110,$H$17),"-") -> - | AW13: =IF(AND($H13<>"",$H$18<>"",$H13<>$H$18,IFERROR(VLOOKUP($H13,areaCercaPuntiClassificaSquadra,3,FALSE()),-1)=IFERROR(VLOOKUP($H$18,areaCercaPuntiClassificaSquadra,3,FALSE()),-2)),SUMIFS('Calendario A'!$Q$8:$Q$110,'Calendario A'!$M$8:$M$110,$H13,'Calendario A'!$T$8:$T$110,$H$18)+SUMIFS('Calendario A'!$X$8:$X$110,'Calendario A'!$T$8:$T$110,$H13,'Calendario A'!$M$8:$M$110,$H$18),"-") -> - | AX13: =IF(AND($H13<>"",$H$19<>"",$H13<>$H$19,IFERROR(VLOOKUP($H13,areaCercaPuntiClassificaSquadra,3,FALSE()),-1)=IFERROR(VLOOKUP($H$19,areaCercaPuntiClassificaSquadra,3,FALSE()),-2)),SUMIFS('Calendario A'!$Q$8:$Q$110,'Calendario A'!$M$8:$M$110,$H13,'Calendario A'!$T$8:$T$110,$H$19)+SUMIFS('Calendario A'!$X$8:$X$110,'Calendario A'!$T$8:$T$110,$H13,'Calendario A'!$M$8:$M$110,$H$19),"-") -> - | AY13: =$C13 -> Bufali Belligeranti-Bufaliopoli BI | AZ13: =IF(AND($H13<>"",$H$12<>"",$H13<>$H$12,IFERROR(VLOOKUP($H13,areaCercaPuntiClassificaSquadra,3,FALSE()),-1)=IFERROR(VLOOKUP($H$12,areaCercaPuntiClassificaSquadra,3,FALSE()),-2)),SUMIFS('Calendario A'!$R$8:$R$110,'Calendario A'!$M$8:$M$110,$H13,'Calendario A'!$T$8:$T$110,$H$12)+SUMIFS('Calendario A'!$Y$8:$Y$110,'Calendario A'!$T$8:$T$110,$H13,'Calendario A'!$M$8:$M$110,$H$12),"-") -> - | BA13: =IF(AND($H13<>"",$H$13<>"",$H13<>$H$13,IFERROR(VLOOKUP($H13,areaCercaPuntiClassificaSquadra,3,FALSE()),-1)=IFERROR(VLOOKUP($H$13,areaCercaPuntiClassificaSquadra,3,FALSE()),-2)),SUMIFS('Calendario A'!$R$8:$R$110,'Calendario A'!$M$8:$M$110,$H13,'Calendario A'!$T$8:$T$110,$H$13)+SUMIFS('Calendario A'!$Y$8:$Y$110,'Calendario A'!$T$8:$T$110,$H13,'Calendario A'!$M$8:$M$110,$H$13),"-") -> - | BB13: =IF(AND($H13<>"",$H$14<>"",$H13<>$H$14,IFERROR(VLOOKUP($H13,areaCercaPuntiClassificaSquadra,3,FALSE()),-1)=IFERROR(VLOOKUP($H$14,areaCercaPuntiClassificaSquadra,3,FALSE()),-2)),SUMIFS('Calendario A'!$R$8:$R$110,'Calendario A'!$M$8:$M$110,$H13,'Calendario A'!$T$8:$T$110,$H$14)+SUMIFS('Calendario A'!$Y$8:$Y$110,'Calendario A'!$T$8:$T$110,$H13,'Calendario A'!$M$8:$M$110,$H$14),"-") -> - | BC13: =IF(AND($H13<>"",$H$15<>"",$H13<>$H$15,IFERROR(VLOOKUP($H13,areaCercaPuntiClassificaSquadra,3,FALSE()),-1)=IFERROR(VLOOKUP($H$15,areaCercaPuntiClassificaSquadra,3,FALSE()),-2)),SUMIFS('Calendario A'!$R$8:$R$110,'Calendario A'!$M$8:$M$110,$H13,'Calendario A'!$T$8:$T$110,$H$15)+SUMIFS('Calendario A'!$Y$8:$Y$110,'Calendario A'!$T$8:$T$110,$H13,'Calendario A'!$M$8:$M$110,$H$15),"-") -> 48 | BD13: =IF(AND($H13<>"",$H$16<>"",$H13<>$H$16,IFERROR(VLOOKUP($H13,areaCercaPuntiClassificaSquadra,3,FALSE()),-1)=IFERROR(VLOOKUP($H$16,areaCercaPuntiClassificaSquadra,3,FALSE()),-2)),SUMIFS('Calendario A'!$R$8:$R$110,'Calendario A'!$M$8:$M$110,$H13,'Calendario A'!$T$8:$T$110,$H$16)+SUMIFS('Calendario A'!$Y$8:$Y$110,'Calendario A'!$T$8:$T$110,$H13,'Calendario A'!$M$8:$M$110,$H$16),"-") -> - | BE13: =IF(AND($H13<>"",$H$17<>"",$H13<>$H$17,IFERROR(VLOOKUP($H13,areaCercaPuntiClassificaSquadra,3,FALSE()),-1)=IFERROR(VLOOKUP($H$17,areaCercaPuntiClassificaSquadra,3,FALSE()),-2)),SUMIFS('Calendario A'!$R$8:$R$110,'Calendario A'!$M$8:$M$110,$H13,'Calendario A'!$T$8:$T$110,$H$17)+SUMIFS('Calendario A'!$Y$8:$Y$110,'Calendario A'!$T$8:$T$110,$H13,'Calendario A'!$M$8:$M$110,$H$17),"-") -> - | BF13: =IF(AND($H13<>"",$H$18<>"",$H13<>$H$18,IFERROR(VLOOKUP($H13,areaCercaPuntiClassificaSquadra,3,FALSE()),-1)=IFERROR(VLOOKUP($H$18,areaCercaPuntiClassificaSquadra,3,FALSE()),-2)),SUMIFS('Calendario A'!$R$8:$R$110,'Calendario A'!$M$8:$M$110,$H13,'Calendario A'!$T$8:$T$110,$H$18)+SUMIFS('Calendario A'!$Y$8:$Y$110,'Calendario A'!$T$8:$T$110,$H13,'Calendario A'!$M$8:$M$110,$H$18),"-") -> - | BG13: =IF(AND($H13<>"",$H$19<>"",$H13<>$H$19,IFERROR(VLOOKUP($H13,areaCercaPuntiClassificaSquadra,3,FALSE()),-1)=IFERROR(VLOOKUP($H$19,areaCercaPuntiClassificaSquadra,3,FALSE()),-2)),SUMIFS('Calendario A'!$R$8:$R$110,'Calendario A'!$M$8:$M$110,$H13,'Calendario A'!$T$8:$T$110,$H$19)+SUMIFS('Calendario A'!$Y$8:$Y$110,'Calendario A'!$T$8:$T$110,$H13,'Calendario A'!$M$8:$M$110,$H$19),"-") -> -
B14: A03 | C14: Cobra Coraggiosi-Cobraopoli CA | E14: A | G14: =IF($C14="","",$E14&(COUNTIFS(I$12:I$75,">"&I14,E$12:E$75,"="&E14,C$12:C$75,"<>")+COUNTIFS(I$12:I$75,"="&I14,H$12:H$75,"<="&H14,E$12:E$75,"="&E14,C$12:C$75,"<>"))) -> A6 | H14: =IF($C14="","",IFERROR(LEFT($C14,FIND("-",$C14)-1),$C14)) -> Cobra Coraggiosi | I14: =TEXT(1000000000+J14,"|0000000000|")&TEXT(SUM(Y14:AF14),"0000000000|")&IF(SUM(AZ14:BG14)=0,"0000000000|",TEXT(ROUND(SUM(AQ14:AX14)/SUM(AZ14:BG14),4)*100000,"0000000000|"))&IF(P14=0,"0000000000|",TEXT(ROUND(O14/P14,4)*100000,"0000000000|")) -> |1000000013|0000000000|0000086210|0000096690| | J14: =L14*constPuntiVittoria+M14*constPuntiSconfitta+N14*constPuntiForfait+IF(D14="",0,D14) -> 13 | K14: =SUM(L14:N14) -> 7 | L14: =IF($H14="",0,SUMIF('Calendario A'!$M$8:$M$110,$H14,'Calendario A'!$N$8:$N$110)+SUMIF('Calendario A'!$T$8:$T$110,$H14,'Calendario A'!$U$8:$U$110)) -> 3 | M14: =IF($H14="",0,SUMIF('Calendario A'!$M$8:$M$110,$H14,'Calendario A'!$P$8:$P$110)+SUMIF('Calendario A'!$T$8:$T$110,$H14,'Calendario A'!$W$8:$W$110)) -> 4 | N14: =IF($H14="",0,SUMIF('Calendario A'!$M$8:$M$110,$H14,'Calendario A'!$O$8:$O$110)+SUMIF('Calendario A'!$T$8:$T$110,$H14,'Calendario A'!$V$8:$V$110)) -> 0 | O14: =IF($H14="",0,SUMIF('Calendario A'!$M$8:$M$110,$H14,'Calendario A'!$Q$8:$Q$110)+SUMIF('Calendario A'!$T$8:$T$110,$H14,'Calendario A'!$X$8:$X$110)) -> 409 | P14: =IF($H14="",0,SUMIF('Calendario A'!$M$8:$M$110,$H14,'Calendario A'!$R$8:$R$110)+SUMIF('Calendario A'!$T$8:$T$110,$H14,'Calendario A'!$Y$8:$Y$110)) -> 423 | Q14: =IF($H14="",0,SUMIF('Calendario A'!$M$8:$M$110,$H14,'Calendario A'!$S$8:$S$110)+SUMIF('Calendario A'!$T$8:$T$110,$H14,'Calendario A'!$Z$8:$Z$110)) -> -14 | R14: =IF(K14=0,0,ROUND(O14/K14,2)) -> 58.43 | S14: =IF(K14=0,0,ROUND(P14/K14,2)) -> 60.43 | T14: =IF(K14=0,0,ROUND(Q14/K14,2)) -> -2 | U14: =IF(COUNT(Y14:AF14)=0,"-",SUM(Y14:AF14)&"-"&SUM(AH14:AO14)) -> 0-1 | V14: =IF(COUNT(Y14:AF14)=0,"-",IF(SUM(AZ14:BG14)=0,TEXT(0,"0.0000"),TEXT(ROUND(SUM(AQ14:AX14)/SUM(AZ14:BG14),4),"0.0000"))) -> 0.8621 | W14: =IF(H14="","-",IF(P14=0,TEXT(0,"0.0000"),TEXT(ROUND(O14/P14,4),"0.0000"))) -> 0.9669 | X14: =$C14 -> Cobra Coraggiosi-Cobraopoli CA | Y14: =IF(AND($H14<>"",$H$12<>"",$H14<>$H$12,IFERROR(VLOOKUP($H14,areaCercaPuntiClassificaSquadra,3,FALSE()),-1)=IFERROR(VLOOKUP($H$12,areaCercaPuntiClassificaSquadra,3,FALSE()),-2)),SUMIFS('Calendario A'!$N$8:$N$110,'Calendario A'!$M$8:$M$110,$H14,'Calendario A'!$T$8:$T$110,$H$12)+SUMIFS('Calendario A'!$U$8:$U$110,'Calendario A'!$T$8:$T$110,$H14,'Calendario A'!$M$8:$M$110,$H$12),"-") -> - | Z14: =IF(AND($H14<>"",$H$13<>"",$H14<>$H$13,IFERROR(VLOOKUP($H14,areaCercaPuntiClassificaSquadra,3,FALSE()),-1)=IFERROR(VLOOKUP($H$13,areaCercaPuntiClassificaSquadra,3,FALSE()),-2)),SUMIFS('Calendario A'!$N$8:$N$110,'Calendario A'!$M$8:$M$110,$H14,'Calendario A'!$T$8:$T$110,$H$13)+SUMIFS('Calendario A'!$U$8:$U$110,'Calendario A'!$T$8:$T$110,$H14,'Calendario A'!$M$8:$M$110,$H$13),"-") -> - | AA14: =IF(AND($H14<>"",$H$14<>"",$H14<>$H$14,IFERROR(VLOOKUP($H14,areaCercaPuntiClassificaSquadra,3,FALSE()),-1)=IFERROR(VLOOKUP($H$14,areaCercaPuntiClassificaSquadra,3,FALSE()),-2)),SUMIFS('Calendario A'!$N$8:$N$110,'Calendario A'!$M$8:$M$110,$H14,'Calendario A'!$T$8:$T$110,$H$14)+SUMIFS('Calendario A'!$U$8:$U$110,'Calendario A'!$T$8:$T$110,$H14,'Calendario A'!$M$8:$M$110,$H$14),"-") -> - | AB14: =IF(AND($H14<>"",$H$15<>"",$H14<>$H$15,IFERROR(VLOOKUP($H14,areaCercaPuntiClassificaSquadra,3,FALSE()),-1)=IFERROR(VLOOKUP($H$15,areaCercaPuntiClassificaSquadra,3,FALSE()),-2)),SUMIFS('Calendario A'!$N$8:$N$110,'Calendario A'!$M$8:$M$110,$H14,'Calendario A'!$T$8:$T$110,$H$15)+SUMIFS('Calendario A'!$U$8:$U$110,'Calendario A'!$T$8:$T$110,$H14,'Calendario A'!$M$8:$M$110,$H$15),"-") -> - | AC14: =IF(AND($H14<>"",$H$16<>"",$H14<>$H$16,IFERROR(VLOOKUP($H14,areaCercaPuntiClassificaSquadra,3,FALSE()),-1)=IFERROR(VLOOKUP($H$16,areaCercaPuntiClassificaSquadra,3,FALSE()),-2)),SUMIFS('Calendario A'!$N$8:$N$110,'Calendario A'!$M$8:$M$110,$H14,'Calendario A'!$T$8:$T$110,$H$16)+SUMIFS('Calendario A'!$U$8:$U$110,'Calendario A'!$T$8:$T$110,$H14,'Calendario A'!$M$8:$M$110,$H$16),"-") -> - | AD14: =IF(AND($H14<>"",$H$17<>"",$H14<>$H$17,IFERROR(VLOOKUP($H14,areaCercaPuntiClassificaSquadra,3,FALSE()),-1)=IFERROR(VLOOKUP($H$17,areaCercaPuntiClassificaSquadra,3,FALSE()),-2)),SUMIFS('Calendario A'!$N$8:$N$110,'Calendario A'!$M$8:$M$110,$H14,'Calendario A'!$T$8:$T$110,$H$17)+SUMIFS('Calendario A'!$U$8:$U$110,'Calendario A'!$T$8:$T$110,$H14,'Calendario A'!$M$8:$M$110,$H$17),"-") -> - | AE14: =IF(AND($H14<>"",$H$18<>"",$H14<>$H$18,IFERROR(VLOOKUP($H14,areaCercaPuntiClassificaSquadra,3,FALSE()),-1)=IFERROR(VLOOKUP($H$18,areaCercaPuntiClassificaSquadra,3,FALSE()),-2)),SUMIFS('Calendario A'!$N$8:$N$110,'Calendario A'!$M$8:$M$110,$H14,'Calendario A'!$T$8:$T$110,$H$18)+SUMIFS('Calendario A'!$U$8:$U$110,'Calendario A'!$T$8:$T$110,$H14,'Calendario A'!$M$8:$M$110,$H$18),"-") -> 0 | AF14: =IF(AND($H14<>"",$H$19<>"",$H14<>$H$19,IFERROR(VLOOKUP($H14,areaCercaPuntiClassificaSquadra,3,FALSE()),-1)=IFERROR(VLOOKUP($H$19,areaCercaPuntiClassificaSquadra,3,FALSE()),-2)),SUMIFS('Calendario A'!$N$8:$N$110,'Calendario A'!$M$8:$M$110,$H14,'Calendario A'!$T$8:$T$110,$H$19)+SUMIFS('Calendario A'!$U$8:$U$110,'Calendario A'!$T$8:$T$110,$H14,'Calendario A'!$M$8:$M$110,$H$19),"-") -> - | AG14: =$C14 -> Cobra Coraggiosi-Cobraopoli CA | AH14: =IF(AND($H14<>"",$H$12<>"",$H14<>$H$12,IFERROR(VLOOKUP($H14,areaCercaPuntiClassificaSquadra,3,FALSE()),-1)=IFERROR(VLOOKUP($H$12,areaCercaPuntiClassificaSquadra,3,FALSE()),-2)),SUMIFS('Calendario A'!$P$8:$P$110,'Calendario A'!$M$8:$M$110,$H14,'Calendario A'!$T$8:$T$110,$H$12)+SUMIFS('Calendario A'!$W$8:$W$110,'Calendario A'!$T$8:$T$110,$H14,'Calendario A'!$M$8:$M$110,$H$12)+SUMIFS('Calendario A'!$O$8:$O$110,'Calendario A'!$M$8:$M$110,$H14,'Calendario A'!$T$8:$T$110,$H$12)+SUMIFS('Calendario A'!$V$8:$V$110,'Calendario A'!$T$8:$T$110,$H14,'Calendario A'!$M$8:$M$110,$H$12),"-") -> - | AI14: =IF(AND($H14<>"",$H$13<>"",$H14<>$H$13,IFERROR(VLOOKUP($H14,areaCercaPuntiClassificaSquadra,3,FALSE()),-1)=IFERROR(VLOOKUP($H$13,areaCercaPuntiClassificaSquadra,3,FALSE()),-2)),SUMIFS('Calendario A'!$P$8:$P$110,'Calendario A'!$M$8:$M$110,$H14,'Calendario A'!$T$8:$T$110,$H$13)+SUMIFS('Calendario A'!$W$8:$W$110,'Calendario A'!$T$8:$T$110,$H14,'Calendario A'!$M$8:$M$110,$H$13)+SUMIFS('Calendario A'!$O$8:$O$110,'Calendario A'!$M$8:$M$110,$H14,'Calendario A'!$T$8:$T$110,$H$13)+SUMIFS('Calendario A'!$V$8:$V$110,'Calendario A'!$T$8:$T$110,$H14,'Calendario A'!$M$8:$M$110,$H$13),"-") -> - | AJ14: =IF(AND($H14<>"",$H$14<>"",$H14<>$H$14,IFERROR(VLOOKUP($H14,areaCercaPuntiClassificaSquadra,3,FALSE()),-1)=IFERROR(VLOOKUP($H$14,areaCercaPuntiClassificaSquadra,3,FALSE()),-2)),SUMIFS('Calendario A'!$P$8:$P$110,'Calendario A'!$M$8:$M$110,$H14,'Calendario A'!$T$8:$T$110,$H$14)+SUMIFS('Calendario A'!$W$8:$W$110,'Calendario A'!$T$8:$T$110,$H14,'Calendario A'!$M$8:$M$110,$H$14)+SUMIFS('Calendario A'!$O$8:$O$110,'Calendario A'!$M$8:$M$110,$H14,'Calendario A'!$T$8:$T$110,$H$14)+SUMIFS('Calendario A'!$V$8:$V$110,'Calendario A'!$T$8:$T$110,$H14,'Calendario A'!$M$8:$M$110,$H$14),"-") -> - | AK14: =IF(AND($H14<>"",$H$15<>"",$H14<>$H$15,IFERROR(VLOOKUP($H14,areaCercaPuntiClassificaSquadra,3,FALSE()),-1)=IFERROR(VLOOKUP($H$15,areaCercaPuntiClassificaSquadra,3,FALSE()),-2)),SUMIFS('Calendario A'!$P$8:$P$110,'Calendario A'!$M$8:$M$110,$H14,'Calendario A'!$T$8:$T$110,$H$15)+SUMIFS('Calendario A'!$W$8:$W$110,'Calendario A'!$T$8:$T$110,$H14,'Calendario A'!$M$8:$M$110,$H$15)+SUMIFS('Calendario A'!$O$8:$O$110,'Calendario A'!$M$8:$M$110,$H14,'Calendario A'!$T$8:$T$110,$H$15)+SUMIFS('Calendario A'!$V$8:$V$110,'Calendario A'!$T$8:$T$110,$H14,'Calendario A'!$M$8:$M$110,$H$15),"-") -> - | AL14: =IF(AND($H14<>"",$H$16<>"",$H14<>$H$16,IFERROR(VLOOKUP($H14,areaCercaPuntiClassificaSquadra,3,FALSE()),-1)=IFERROR(VLOOKUP($H$16,areaCercaPuntiClassificaSquadra,3,FALSE()),-2)),SUMIFS('Calendario A'!$P$8:$P$110,'Calendario A'!$M$8:$M$110,$H14,'Calendario A'!$T$8:$T$110,$H$16)+SUMIFS('Calendario A'!$W$8:$W$110,'Calendario A'!$T$8:$T$110,$H14,'Calendario A'!$M$8:$M$110,$H$16)+SUMIFS('Calendario A'!$O$8:$O$110,'Calendario A'!$M$8:$M$110,$H14,'Calendario A'!$T$8:$T$110,$H$16)+SUMIFS('Calendario A'!$V$8:$V$110,'Calendario A'!$T$8:$T$110,$H14,'Calendario A'!$M$8:$M$110,$H$16),"-") -> - | AM14: =IF(AND($H14<>"",$H$17<>"",$H14<>$H$17,IFERROR(VLOOKUP($H14,areaCercaPuntiClassificaSquadra,3,FALSE()),-1)=IFERROR(VLOOKUP($H$17,areaCercaPuntiClassificaSquadra,3,FALSE()),-2)),SUMIFS('Calendario A'!$P$8:$P$110,'Calendario A'!$M$8:$M$110,$H14,'Calendario A'!$T$8:$T$110,$H$17)+SUMIFS('Calendario A'!$W$8:$W$110,'Calendario A'!$T$8:$T$110,$H14,'Calendario A'!$M$8:$M$110,$H$17)+SUMIFS('Calendario A'!$O$8:$O$110,'Calendario A'!$M$8:$M$110,$H14,'Calendario A'!$T$8:$T$110,$H$17)+SUMIFS('Calendario A'!$V$8:$V$110,'Calendario A'!$T$8:$T$110,$H14,'Calendario A'!$M$8:$M$110,$H$17),"-") -> - | AN14: =IF(AND($H14<>"",$H$18<>"",$H14<>$H$18,IFERROR(VLOOKUP($H14,areaCercaPuntiClassificaSquadra,3,FALSE()),-1)=IFERROR(VLOOKUP($H$18,areaCercaPuntiClassificaSquadra,3,FALSE()),-2)),SUMIFS('Calendario A'!$P$8:$P$110,'Calendario A'!$M$8:$M$110,$H14,'Calendario A'!$T$8:$T$110,$H$18)+SUMIFS('Calendario A'!$W$8:$W$110,'Calendario A'!$T$8:$T$110,$H14,'Calendario A'!$M$8:$M$110,$H$18)+SUMIFS('Calendario A'!$O$8:$O$110,'Calendario A'!$M$8:$M$110,$H14,'Calendario A'!$T$8:$T$110,$H$18)+SUMIFS('Calendario A'!$V$8:$V$110,'Calendario A'!$T$8:$T$110,$H14,'Calendario A'!$M$8:$M$110,$H$18),"-") -> 1 | AO14: =IF(AND($H14<>"",$H$19<>"",$H14<>$H$19,IFERROR(VLOOKUP($H14,areaCercaPuntiClassificaSquadra,3,FALSE()),-1)=IFERROR(VLOOKUP($H$19,areaCercaPuntiClassificaSquadra,3,FALSE()),-2)),SUMIFS('Calendario A'!$P$8:$P$110,'Calendario A'!$M$8:$M$110,$H14,'Calendario A'!$T$8:$T$110,$H$19)+SUMIFS('Calendario A'!$W$8:$W$110,'Calendario A'!$T$8:$T$110,$H14,'Calendario A'!$M$8:$M$110,$H$19)+SUMIFS('Calendario A'!$O$8:$O$110,'Calendario A'!$M$8:$M$110,$H14,'Calendario A'!$T$8:$T$110,$H$19)+SUMIFS('Calendario A'!$V$8:$V$110,'Calendario A'!$T$8:$T$110,$H14,'Calendario A'!$M$8:$M$110,$H$19),"-") -> - | AP14: =$C14 -> Cobra Coraggiosi-Cobraopoli CA | AQ14: =IF(AND($H14<>"",$H$12<>"",$H14<>$H$12,IFERROR(VLOOKUP($H14,areaCercaPuntiClassificaSquadra,3,FALSE()),-1)=IFERROR(VLOOKUP($H$12,areaCercaPuntiClassificaSquadra,3,FALSE()),-2)),SUMIFS('Calendario A'!$Q$8:$Q$110,'Calendario A'!$M$8:$M$110,$H14,'Calendario A'!$T$8:$T$110,$H$12)+SUMIFS('Calendario A'!$X$8:$X$110,'Calendario A'!$T$8:$T$110,$H14,'Calendario A'!$M$8:$M$110,$H$12),"-") -> - | AR14: =IF(AND($H14<>"",$H$13<>"",$H14<>$H$13,IFERROR(VLOOKUP($H14,areaCercaPuntiClassificaSquadra,3,FALSE()),-1)=IFERROR(VLOOKUP($H$13,areaCercaPuntiClassificaSquadra,3,FALSE()),-2)),SUMIFS('Calendario A'!$Q$8:$Q$110,'Calendario A'!$M$8:$M$110,$H14,'Calendario A'!$T$8:$T$110,$H$13)+SUMIFS('Calendario A'!$X$8:$X$110,'Calendario A'!$T$8:$T$110,$H14,'Calendario A'!$M$8:$M$110,$H$13),"-") -> - | AS14: =IF(AND($H14<>"",$H$14<>"",$H14<>$H$14,IFERROR(VLOOKUP($H14,areaCercaPuntiClassificaSquadra,3,FALSE()),-1)=IFERROR(VLOOKUP($H$14,areaCercaPuntiClassificaSquadra,3,FALSE()),-2)),SUMIFS('Calendario A'!$Q$8:$Q$110,'Calendario A'!$M$8:$M$110,$H14,'Calendario A'!$T$8:$T$110,$H$14)+SUMIFS('Calendario A'!$X$8:$X$110,'Calendario A'!$T$8:$T$110,$H14,'Calendario A'!$M$8:$M$110,$H$14),"-") -> - | AT14: =IF(AND($H14<>"",$H$15<>"",$H14<>$H$15,IFERROR(VLOOKUP($H14,areaCercaPuntiClassificaSquadra,3,FALSE()),-1)=IFERROR(VLOOKUP($H$15,areaCercaPuntiClassificaSquadra,3,FALSE()),-2)),SUMIFS('Calendario A'!$Q$8:$Q$110,'Calendario A'!$M$8:$M$110,$H14,'Calendario A'!$T$8:$T$110,$H$15)+SUMIFS('Calendario A'!$X$8:$X$110,'Calendario A'!$T$8:$T$110,$H14,'Calendario A'!$M$8:$M$110,$H$15),"-") -> - | AU14: =IF(AND($H14<>"",$H$16<>"",$H14<>$H$16,IFERROR(VLOOKUP($H14,areaCercaPuntiClassificaSquadra,3,FALSE()),-1)=IFERROR(VLOOKUP($H$16,areaCercaPuntiClassificaSquadra,3,FALSE()),-2)),SUMIFS('Calendario A'!$Q$8:$Q$110,'Calendario A'!$M$8:$M$110,$H14,'Calendario A'!$T$8:$T$110,$H$16)+SUMIFS('Calendario A'!$X$8:$X$110,'Calendario A'!$T$8:$T$110,$H14,'Calendario A'!$M$8:$M$110,$H$16),"-") -> - | AV14: =IF(AND($H14<>"",$H$17<>"",$H14<>$H$17,IFERROR(VLOOKUP($H14,areaCercaPuntiClassificaSquadra,3,FALSE()),-1)=IFERROR(VLOOKUP($H$17,areaCercaPuntiClassificaSquadra,3,FALSE()),-2)),SUMIFS('Calendario A'!$Q$8:$Q$110,'Calendario A'!$M$8:$M$110,$H14,'Calendario A'!$T$8:$T$110,$H$17)+SUMIFS('Calendario A'!$X$8:$X$110,'Calendario A'!$T$8:$T$110,$H14,'Calendario A'!$M$8:$M$110,$H$17),"-") -> - | AW14: =IF(AND($H14<>"",$H$18<>"",$H14<>$H$18,IFERROR(VLOOKUP($H14,areaCercaPuntiClassificaSquadra,3,FALSE()),-1)=IFERROR(VLOOKUP($H$18,areaCercaPuntiClassificaSquadra,3,FALSE()),-2)),SUMIFS('Calendario A'!$Q$8:$Q$110,'Calendario A'!$M$8:$M$110,$H14,'Calendario A'!$T$8:$T$110,$H$18)+SUMIFS('Calendario A'!$X$8:$X$110,'Calendario A'!$T$8:$T$110,$H14,'Calendario A'!$M$8:$M$110,$H$18),"-") -> 50 | AX14: =IF(AND($H14<>"",$H$19<>"",$H14<>$H$19,IFERROR(VLOOKUP($H14,areaCercaPuntiClassificaSquadra,3,FALSE()),-1)=IFERROR(VLOOKUP($H$19,areaCercaPuntiClassificaSquadra,3,FALSE()),-2)),SUMIFS('Calendario A'!$Q$8:$Q$110,'Calendario A'!$M$8:$M$110,$H14,'Calendario A'!$T$8:$T$110,$H$19)+SUMIFS('Calendario A'!$X$8:$X$110,'Calendario A'!$T$8:$T$110,$H14,'Calendario A'!$M$8:$M$110,$H$19),"-") -> - | AY14: =$C14 -> Cobra Coraggiosi-Cobraopoli CA | AZ14: =IF(AND($H14<>"",$H$12<>"",$H14<>$H$12,IFERROR(VLOOKUP($H14,areaCercaPuntiClassificaSquadra,3,FALSE()),-1)=IFERROR(VLOOKUP($H$12,areaCercaPuntiClassificaSquadra,3,FALSE()),-2)),SUMIFS('Calendario A'!$R$8:$R$110,'Calendario A'!$M$8:$M$110,$H14,'Calendario A'!$T$8:$T$110,$H$12)+SUMIFS('Calendario A'!$Y$8:$Y$110,'Calendario A'!$T$8:$T$110,$H14,'Calendario A'!$M$8:$M$110,$H$12),"-") -> - | BA14: =IF(AND($H14<>"",$H$13<>"",$H14<>$H$13,IFERROR(VLOOKUP($H14,areaCercaPuntiClassificaSquadra,3,FALSE()),-1)=IFERROR(VLOOKUP($H$13,areaCercaPuntiClassificaSquadra,3,FALSE()),-2)),SUMIFS('Calendario A'!$R$8:$R$110,'Calendario A'!$M$8:$M$110,$H14,'Calendario A'!$T$8:$T$110,$H$13)+SUMIFS('Calendario A'!$Y$8:$Y$110,'Calendario A'!$T$8:$T$110,$H14,'Calendario A'!$M$8:$M$110,$H$13),"-") -> - | BB14: =IF(AND($H14<>"",$H$14<>"",$H14<>$H$14,IFERROR(VLOOKUP($H14,areaCercaPuntiClassificaSquadra,3,FALSE()),-1)=IFERROR(VLOOKUP($H$14,areaCercaPuntiClassificaSquadra,3,FALSE()),-2)),SUMIFS('Calendario A'!$R$8:$R$110,'Calendario A'!$M$8:$M$110,$H14,'Calendario A'!$T$8:$T$110,$H$14)+SUMIFS('Calendario A'!$Y$8:$Y$110,'Calendario A'!$T$8:$T$110,$H14,'Calendario A'!$M$8:$M$110,$H$14),"-") -> - | BC14: =IF(AND($H14<>"",$H$15<>"",$H14<>$H$15,IFERROR(VLOOKUP($H14,areaCercaPuntiClassificaSquadra,3,FALSE()),-1)=IFERROR(VLOOKUP($H$15,areaCercaPuntiClassificaSquadra,3,FALSE()),-2)),SUMIFS('Calendario A'!$R$8:$R$110,'Calendario A'!$M$8:$M$110,$H14,'Calendario A'!$T$8:$T$110,$H$15)+SUMIFS('Calendario A'!$Y$8:$Y$110,'Calendario A'!$T$8:$T$110,$H14,'Calendario A'!$M$8:$M$110,$H$15),"-") -> - | BD14: =IF(AND($H14<>"",$H$16<>"",$H14<>$H$16,IFERROR(VLOOKUP($H14,areaCercaPuntiClassificaSquadra,3,FALSE()),-1)=IFERROR(VLOOKUP($H$16,areaCercaPuntiClassificaSquadra,3,FALSE()),-2)),SUMIFS('Calendario A'!$R$8:$R$110,'Calendario A'!$M$8:$M$110,$H14,'Calendario A'!$T$8:$T$110,$H$16)+SUMIFS('Calendario A'!$Y$8:$Y$110,'Calendario A'!$T$8:$T$110,$H14,'Calendario A'!$M$8:$M$110,$H$16),"-") -> - | BE14: =IF(AND($H14<>"",$H$17<>"",$H14<>$H$17,IFERROR(VLOOKUP($H14,areaCercaPuntiClassificaSquadra,3,FALSE()),-1)=IFERROR(VLOOKUP($H$17,areaCercaPuntiClassificaSquadra,3,FALSE()),-2)),SUMIFS('Calendario A'!$R$8:$R$110,'Calendario A'!$M$8:$M$110,$H14,'Calendario A'!$T$8:$T$110,$H$17)+SUMIFS('Calendario A'!$Y$8:$Y$110,'Calendario A'!$T$8:$T$110,$H14,'Calendario A'!$M$8:$M$110,$H$17),"-") -> - | BF14: =IF(AND($H14<>"",$H$18<>"",$H14<>$H$18,IFERROR(VLOOKUP($H14,areaCercaPuntiClassificaSquadra,3,FALSE()),-1)=IFERROR(VLOOKUP($H$18,areaCercaPuntiClassificaSquadra,3,FALSE()),-2)),SUMIFS('Calendario A'!$R$8:$R$110,'Calendario A'!$M$8:$M$110,$H14,'Calendario A'!$T$8:$T$110,$H$18)+SUMIFS('Calendario A'!$Y$8:$Y$110,'Calendario A'!$T$8:$T$110,$H14,'Calendario A'!$M$8:$M$110,$H$18),"-") -> 58 | BG14: =IF(AND($H14<>"",$H$19<>"",$H14<>$H$19,IFERROR(VLOOKUP($H14,areaCercaPuntiClassificaSquadra,3,FALSE()),-1)=IFERROR(VLOOKUP($H$19,areaCercaPuntiClassificaSquadra,3,FALSE()),-2)),SUMIFS('Calendario A'!$R$8:$R$110,'Calendario A'!$M$8:$M$110,$H14,'Calendario A'!$T$8:$T$110,$H$19)+SUMIFS('Calendario A'!$Y$8:$Y$110,'Calendario A'!$T$8:$T$110,$H14,'Calendario A'!$M$8:$M$110,$H$19),"-") -> -
