Workbook
Name constNomeCampionato: Campionato!$D$2
Name constGironi: Campionato!$D$5
Name constNomiGironi: Campionato!$D$11
Name constLogo1: Campionato!$D$3
Name constLogo2: Campionato!$D$4
Name constSezioneCampionato: Campionato!$D$5
Name constStagionaCampionato: Campionato!$D$6
Name constPuntiVittoria: Campionato!$D$7
Name constPuntiSconfitta: Campionato!$D$8
Name constPuntiForfait: Campionato!$D$9
Name constPunteggioForfait: Campionato!$D$10
Name areaNomiSquadre: Campionato!$B$14:$C$113
Name areaNomiBreviSquadre: Campionato!$B$14:$H$113
Name areaCoefficienteSquadre: Campionato!$I$14:$I$113
Name areaCercaPuntiClassificaSquadra: Campionato!$H$14:$J$113
Name areaCercaDatiPerPosizioneSquadre: Campionato!$G$14:$W$113
Name areaCampiSquadre: Campionato!$B$117:$D$225
Name ARBITRI: Arbitri!$D$5:$D$104
Name UDC: UdC!$D$5:$D$104
Name areaSquadraACalendario: 'Calendario A'!$M$8:$M$165
Name areaVintaACalendario: 'Calendario A'!$N$8:$N$165
Name areaForfaitACalendario: 'Calendario A'!$O$8:$O$165
Name areaPersaACalendario: 'Calendario A'!$P$8:$P$165
Name areaPuntiFattiACalendario: 'Calendario A'!$Q$8:$Q$165
Name areaPuntiSubitiACalendario: 'Calendario A'!$R$8:$R$165
Name areaDifferenzaPuntiACalendario: 'Calendario A'!$S$8:$S$165
Name areaSquadraBCalendario: 'Calendario A'!$T$8:$T$165
Name areaVintaBCalendario: 'Calendario A'!$U$8:$U$165
Name areaForfaitBCalendario: 'Calendario A'!$V$8:$V$165
Name areaPersaBCalendario: 'Calendario A'!$W$8:$W$165
Name areaPuntiFattiBCalendario: 'Calendario A'!$X$8:$X$165
Name areaPuntiSubitiBCalendario: 'Calendario A'!$Y$8:$Y$165
Name areaDifferenzaPuntiBCalendario: 'Calendario A'!$Z$8:$Z$165
Name areaSquadraACalendario: 'Calendario B'!$M$8:$M$165
Name areaVintaACalendario: 'Calendario B'!$N$8:$N$165
Name areaForfaitACalendario: 'Calendario B'!$O$8:$O$165
Name areaPersaACalendario: 'Calendario B'!$P$8:$P$165
Name areaPuntiFattiACalendario: 'Calendario B'!$Q$8:$Q$165
Name areaPuntiSubitiACalendario: 'Calendario B'!$R$8:$R$165
Name areaDifferenzaPuntiACalendario: 'Calendario B'!$S$8:$S$165
Name areaSquadraBCalendario: 'Calendario B'!$T$8:$T$165
Name areaVintaBCalendario: 'Calendario B'!$U$8:$U$165
Name areaForfaitBCalendario: 'Calendario B'!$V$8:$V$165
Name areaPersaBCalendario: 'Calendario B'!$W$8:$W$165
Name areaPuntiFattiBCalendario: 'Calendario B'!$X$8:$X$165
Name areaPuntiSubitiBCalendario: 'Calendario B'!$Y$8:$Y$165
Name areaDifferenzaPuntiBCalendario: 'Calendario B'!$Z$8:$Z$165
Name areaSquadraACalendario: 'Calendario C'!$M$8:$M$165
Name areaVintaACalendario: 'Calendario C'!$N$8:$N$165
Name areaForfaitACalendario: 'Calendario C'!$O$8:$O$165
Name areaPersaACalendario: 'Calendario C'!$P$8:$P$165
Name areaPuntiFattiACalendario: 'Calendario C'!$Q$8:$Q$165
Name areaPuntiSubitiACalendario: 'Calendario C'!$R$8:$R$165
Name areaDifferenzaPuntiACalendario: 'Calendario C'!$S$8:$S$165
Name areaSquadraBCalendario: 'Calendario C'!$T$8:$T$165
Name areaVintaBCalendario: 'Calendario C'!$U$8:$U$165
Name areaForfaitBCalendario: 'Calendario C'!$V$8:$V$165
Name areaPersaBCalendario: 'Calendario C'!$W$8:$W$165
Name areaPuntiFattiBCalendario: 'Calendario C'!$X$8:$X$165
Name areaPuntiSubitiBCalendario: 'Calendario C'!$Y$8:$Y$165

Sheet Campionato
B1: PARAMETRI
B2: Campionato
B3: Link Logo 1
B4: Link Logo 2
B5: Gironi (separati da virgola) | D5: A,B,C,D,E,F,G,H,I,J
B6: Stagione
B7: Punti vittoria | D7: 3
B8: Punti sconfitta | D8: 1
B9: Punti forfait | D9: 0
B10: Punteggio forfait (vincente-perdente, separati da "-") | D10: 40-0
B11: Nomi gironi per la stampa (stesso ordine, separati da virgola)
B12: SQUADRE | Y12: Squadre del girone (in ordine di inserimento) | AJ12: Squadra | AK12: Vittorie Scontri Diretti | AV12: Squadra | AW12: Sconfitte & Forfait Scontri Diretti | BH12: Squadra | BI12: Punti Fatti Scontri Diretti | BT12: Squadra | BU12: Punti Subiti Scontri Diretti
B13: # | C13: Squadra | D13: Eventuali Punti di Penalizzazione | E13: Girone | G13: Posizione | H13: Squadra | I13: Coefficiente | J13: Punti Classifica | K13: Partite Giocate | L13: Partite Vinte | M13: Partite Perse | N13: Partite Forfait | O13: Punti Fatti | P13: Punti Subiti | Q13: Differenza Punti | R13: Media Punti Fatti | S13: Media Punti Subiti | T13: Media Differenza Punti | U13: Record Scontri Diretti | V13: Quoziente Canestri Scontri Diretti | W13: Quoziente Canestri Totale | X13: Chiave girone | Y13: 1^ | Z13: 2^ | AA13: 3^ | AB13: 4^ | AC13: 5^ | AD13: 6^ | AE13: 7^ | AF13: 8^ | AG13: 9^ | AH13: 10^ | AJ13: Squadra | AK13: 1^ | AL13: 2^ | AM13: 3^ | AN13: 4^ | AO13: 5^ | AP13: 6^ | AQ13: 7^ | AR13: 8^ | AS13: 9^ | AT13: 10^ | AV13: Squadra | AW13: 1^ | AX13: 2^ | AY13: 3^ | AZ13: 4^ | BA13: 5^ | BB13: 6^ | BC13: 7^ | BD13: 8^ | BE13: 9^ | BF13: 10^ | BH13: Squadra | BI13: 1^ | BJ13: 2^ | BK13: 3^ | BL13: 4^ | BM13: 5^ | BN13: 6^ | BO13: 7^ | BP13: 8^ | BQ13: 9^ | BR13: 10^ | BT13: Squadra | BU13: 1^ | BV13: 2^ | BW13: 3^ | BX13: 4^ | BY13: 5^ | BZ13: 6^ | CA13: 7^ | CB13: 8^ | CC13: 9^ | CD13: 10^ | CF13: Vittorie SD
B14: A01 | E14: A | G14: =IF($C14="","",$E14&(COUNTIFS(I$14:I$113,">"&I14,E$14:E$113,"="&E14,C$14:C$113,"<>")+COUNTIFS(I$14:I$113,"="&I14,H$14:H$113,"<="&H14,E$14:E$113,"="&E14,C$14:C$113,"<>"))) | H14: =IF($C14="","",IFERROR(LEFT($C14,FIND("-",$C14)-1),$C14)) | I14: =TEXT(1000000000+J14,"|0000000000|")&TEXT(SUM(AK14:AT14),"0000000000|")&IF(SUM(BU14:CD14)=0,"0000000000|",TEXT(ROUND(SUM(BI14:BR14)/SUM(BU14:CD14),4)*100000,"0000000000|"))&IF(P14=0,"0000000000|",TEXT(ROUND(O14/P14,4)*100000,"0000000000|")) | J14: =L14*constPuntiVittoria+M14*constPuntiSconfitta+N14*constPuntiForfait+IF(D14="",0,D14) | K14: =SUM(L14:N14) | L14: =IF($H14="",0,SUMIF(Dati!$A$2:$A$451,$H14,Dati!$B$2:$B$451)+SUMIF(Dati!$H$2:$H$451,$H14,Dati!$I$2:$I$451)) | M14: =IF($H14="",0,SUMIF(Dati!$A$2:$A$451,$H14,Dati!$D$2:$D$451)+SUMIF(Dati!$H$2:$H$451,$H14,Dati!$K$2:$K$451)) | N14: =IF($H14="",0,SUMIF(Dati!$A$2:$A$451,$H14,Dati!$C$2:$C$451)+SUMIF(Dati!$H$2:$H$451,$H14,Dati!$J$2:$J$451)) | O14: =IF($H14="",0,SUMIF(Dati!$A$2:$A$451,$H14,Dati!$E$2:$E$451)+SUMIF(Dati!$H$2:$H$451,$H14,Dati!$L$2:$L$451)) | P14: =IF($H14="",0,SUMIF(Dati!$A$2:$A$451,$H14,Dati!$F$2:$F$451)+SUMIF(Dati!$H$2:$H$451,$H14,Dati!$M$2:$M$451)) | Q14: =IF($H14="",0,SUMIF(Dati!$A$2:$A$451,$H14,Dati!$G$2:$G$451)+SUMIF(Dati!$H$2:$H$451,$H14,Dati!$N$2:$N$451)) | R14: =IF(K14=0,0,ROUND(O14/K14,2)) | S14: =IF(K14=0,0,ROUND(P14/K14,2)) | T14: =IF(K14=0,0,ROUND(Q14/K14,2)) | U14: =IF(COUNTIFS($E$14:$E$113,$E14,$J$14:$J$113,$J14,$C$14:$C$113,"<>")<=1,"-",SUM(AK14:AT14)&"-"&SUM(AW14:BF14)) | V14: =IF(COUNTIFS($E$14:$E$113,$E14,$J$14:$J$113,$J14,$C$14:$C$113,"<>",$CF$14:$CF$113,$CF14)<=1,"-",IF(SUM(BU14:CD14)=0,0,ROUND(SUM(BI14:BR14)/SUM(BU14:CD14),3))) | W14: =IF(COUNTIFS($E$14:$E$113,$E14,$J$14:$J$113,$J14,$C$14:$C$113,"<>",$CF$14:$CF$113,$CF14,$V$14:$V$113,$V14)<=1,"-",IF(P14=0,0,ROUND(O14/P14,3))) | X14: =IF($C14="","",$E14&"#"&COUNTIFS($E$14:$E14,$E14,$C$14:$C14,"<>")) | Y14: =IFERROR(INDEX($H$14:$H$113,MATCH($E14&"#1",$X$14:$X$113,0)),"") | Z14: =IFERROR(INDEX($H$14:$H$113,MATCH($E14&"#2",$X$14:$X$113,0)),"") | AA14: =IFERROR(INDEX($H$14:$H$113,MATCH($E14&"#3",$X$14:$X$113,0)),"") | AB14: =IFERROR(INDEX($H$14:$H$113,MATCH($E14&"#4",$X$14:$X$113,0)),"") | AC14: =IFERROR(INDEX($H$14:$H$113,MATCH($E14&"#5",$X$14:$X$113,0)),"") | AD14: =IFERROR(INDEX($H$14:$H$113,MATCH($E14&"#6",$X$14:$X$113,0)),"") | AE14: =IFERROR(INDEX($H$14:$H$113,MATCH($E14&"#7",$X$14:$X$113,0)),"") | AF14: =IFERROR(INDEX($H$14:$H$113,MATCH($E14&"#8",$X$14:$X$113,0)),"") | AG14: =IFERROR(INDEX($H$14:$H$113,MATCH($E14&"#9",$X$14:$X$113,0)),"") | AH14: =IFERROR(INDEX($H$14:$H$113,MATCH($E14&"#10",$X$14:$X$113,0)),"") | AJ14: =$C14 | AK14: =IF(AND($H14<>"",$Y14<>"",$H14<>$Y14,IFERROR(VLOOKUP($H14,areaCercaPuntiClassificaSquadra,3,FALSE),-1)=IFERROR(VLOOKUP($Y14,areaCercaPuntiClassificaSquadra,3,FALSE),-2)),SUMIFS(Dati!$B$2:$B$451,Dati!$A$2:$A$451,$H14,Dati!$H$2:$H$451,$Y14)+SUMIFS(Dati!$I$2:$I$451,Dati!$H$2:$H$451,$H14,Dati!$A$2:$A$451,$Y14),"-") | AL14: =IF(AND($H14<>"",$Z14<>"",$H14<>$Z14,IFERROR(VLOOKUP($H14,areaCercaPuntiClassificaSquadra,3,FALSE),-1)=IFERROR(VLOOKUP($Z14,areaCercaPuntiClassificaSquadra,3,FALSE),-2)),SUMIFS(Dati!$B$2:$B$451,Dati!$A$2:$A$451,$H14,Dati!$H$2:$H$451,$Z14)+SUMIFS(Dati!$I$2:$I$451,Dati!$H$2:$H$451,$H14,Dati!$A$2:$A$451,$Z14),"-") | AM14: =IF(AND($H14<>"",$AA14<>"",$H14<>$AA14,IFERROR(VLOOKUP($H14,areaCercaPuntiClassificaSquadra,3,FALSE),-1)=IFERROR(VLOOKUP($AA14,areaCercaPuntiClassificaSquadra,3,FALSE),-2)),SUMIFS(Dati!$B$2:$B$451,Dati!$A$2:$A$451,$H14,Dati!$H$2:$H$451,$AA14)+SUMIFS(Dati!$I$2:$I$451,Dati!$H$2:$H$451,$H14,Dati!$A$2:$A$451,$AA14),"-") | AN14: =IF(AND($H14<>"",$AB14<>"",$H14<>$AB14,IFERROR(VLOOKUP($H14,areaCercaPuntiClassificaSquadra,3,FALSE),-1)=IFERROR(VLOOKUP($AB14,areaCercaPuntiClassificaSquadra,3,FALSE),-2)),SUMIFS(Dati!$B$2:$B$451,Dati!$A$2:$A$451,$H14,Dati!$H$2:$H$451,$AB14)+SUMIFS(Dati!$I$2:$I$451,Dati!$H$2:$H$451,$H14,Dati!$A$2:$A$451,$AB14),"-") | AO14: =IF(AND($H14<>"",$AC14<>"",$H14<>$AC14,IFERROR(VLOOKUP($H14,areaCercaPuntiClassificaSquadra,3,FALSE),-1)=IFERROR(VLOOKUP($AC14,areaCercaPuntiClassificaSquadra,3,FALSE),-2)),SUMIFS(Dati!$B$2:$B$451,Dati!$A$2:$A$451,$H14,Dati!$H$2:$H$451,$AC14)+SUMIFS(Dati!$I$2:$I$451,Dati!$H$2:$H$451,$H14,Dati!$A$2:$A$451,$AC14),"-") | AP14: =IF(AND($H14<>"",$AD14<>"",$H14<>$AD14,IFERROR(VLOOKUP($H14,areaCercaPuntiClassificaSquadra,3,FALSE),-1)=IFERROR(VLOOKUP($AD14,areaCercaPuntiClassificaSquadra,3,FALSE),-2)),SUMIFS(Dati!$B$2:$B$451,Dati!$A$2:$A$451,$H14,Dati!$H$2:$H$451,$AD14)+SUMIFS(Dati!$I$2:$I$451,Dati!$H$2:$H$451,$H14,Dati!$A$2:$A$451,$AD14),"-") | AQ14: =IF(AND($H14<>"",$AE14<>"",$H14<>$AE14,IFERROR(VLOOKUP($H14,areaCercaPuntiClassificaSquadra,3,FALSE),-1)=IFERROR(VLOOKUP($AE14,areaCercaPuntiClassificaSquadra,3,FALSE),-2)),SUMIFS(Dati!$B$2:$B$451,Dati!$A$2:$A$451,$H14,Dati!$H$2:$H$451,$AE14)+SUMIFS(Dati!$I$2:$I$451,Dati!$H$2:$H$451,$H14,Dati!$A$2:$A$451,$AE14),"-") | AR14: =IF(AND($H14<>"",$AF14<>"",$H14<>$AF14,IFERROR(VLOOKUP($H14,areaCercaPuntiClassificaSquadra,3,FALSE),-1)=IFERROR(VLOOKUP($AF14,areaCercaPuntiClassificaSquadra,3,FALSE),-2)),SUMIFS(Dati!$B$2:$B$451,Dati!$A$2:$A$451,$H14,Dati!$H$2:$H$451,$AF14)+SUMIFS(Dati!$I$2:$I$451,Dati!$H$2:$H$451,$H14,Dati!$A$2:$A$451,$AF14),"-") | AS14: =IF(AND($H14<>"",$AG14<>"",$H14<>$AG14,IFERROR(VLOOKUP($H14,areaCercaPuntiClassificaSquadra,3,FALSE),-1)=IFERROR(VLOOKUP($AG14,areaCercaPuntiClassificaSquadra,3,FALSE),-2)),SUMIFS(Dati!$B$2:$B$451,Dati!$A$2:$A$451,$H14,Dati!$H$2:$H$451,$AG14)+SUMIFS(Dati!$I$2:$I$451,Dati!$H$2:$H$451,$H14,Dati!$A$2:$A$451,$AG14),"-") | AT14: =IF(AND($H14<>"",$AH14<>"",$H14<>$AH14,IFERROR(VLOOKUP($H14,areaCercaPuntiClassificaSquadra,3,FALSE),-1)=IFERROR(VLOOKUP($AH14,areaCercaPuntiClassificaSquadra,3,FALSE),-2)),SUMIFS(Dati!$B$2:$B$451,Dati!$A$2:$A$451,$H14,Dati!$H$2:$H$451,$AH14)+SUMIFS(Dati!$I$2:$I$451,Dati!$H$2:$H$451,$H14,Dati!$A$2:$A$451,$AH14),"-") | AV14: =$C14 | AW14: =IF(AND($H14<>"",$Y14<>"",$H14<>$Y14,IFERROR(VLOOKUP($H14,areaCercaPuntiClassificaSquadra,3,FALSE),-1)=IFERROR(VLOOKUP($Y14,areaCercaPuntiClassificaSquadra,3,FALSE),-2)),SUMIFS(Dati!$D$2:$D$451,Dati!$A$2:$A$451,$H14,Dati!$H$2:$H$451,$Y14)+SUMIFS(Dati!$K$2:$K$451,Dati!$H$2:$H$451,$H14,Dati!$A$2:$A$451,$Y14)+SUMIFS(Dati!$C$2:$C$451,Dati!$A$2:$A$451,$H14,Dati!$H$2:$H$451,$Y14)+SUMIFS(Dati!$J$2:$J$451,Dati!$H$2:$H$451,$H14,Dati!$A$2:$A$451,$Y14),"-") | AX14: =IF(AND($H14<>"",$Z14<>"",$H14<>$Z14,IFERROR(VLOOKUP($H14,areaCercaPuntiClassificaSquadra,3,FALSE),-1)=IFERROR(VLOOKUP($Z14,areaCercaPuntiClassificaSquadra,3,FALSE),-2)),SUMIFS(Dati!$D$2:$D$451,Dati!$A$2:$A$451,$H14,Dati!$H$2:$H$451,$Z14)+SUMIFS(Dati!$K$2:$K$451,Dati!$H$2:$H$451,$H14,Dati!$A$2:$A$451,$Z14)+SUMIFS(Dati!$C$2:$C$451,Dati!$A$2:$A$451,$H14,Dati!$H$2:$H$451,$Z14)+SUMIFS(Dati!$J$2:$J$451,Dati!$H$2:$H$451,$H14,Dati!$A$2:$A$451,$Z14),"-") | AY14: =IF(AND($H14<>"",$AA14<>"",$H14<>$AA14,IFERROR(VLOOKUP($H14,areaCercaPuntiClassificaSquadra,3,FALSE),-1)=IFERROR(VLOOKUP($AA14,areaCercaPuntiClassificaSquadra,3,FALSE),-2)),SUMIFS(Dati!$D$2:$D$451,Dati!$A$2:$A$451,$H14,Dati!$H$2:$H$451,$AA14)+SUMIFS(Dati!$K$2:$K$451,Dati!$H$2:$H$451,$H14,Dati!$A$2:$A$451,$AA14)+SUMIFS(Dati!$C$2:$C$451,Dati!$A$2:$A$451,$H14,Dati!$H$2:$H$451,$AA14)+SUMIFS(Dati!$J$2:$J$451,Dati!$H$2:$H$451,$H14,Dati!$A$2:$A$451,$AA14),"-") | AZ14: =IF(AND($H14<>"",$AB14<>"",$H14<>$AB14,IFERROR(VLOOKUP($H14,areaCercaPuntiClassificaSquadra,3,FALSE),-1)=IFERROR(VLOOKUP($AB14,areaCercaPuntiClassificaSquadra,3,FALSE),-2)),SUMIFS(Dati!$D$2:$D$451,Dati!$A$2:$A$451,$H14,Dati!$H$2:$H$451,$AB14)+SUMIFS(Dati!$K$2:$K$451,Dati!$H$2:$H$451,$H14,Dati!$A$2:$A$451,$AB14)+SUMIFS(Dati!$C$2:$C$451,Dati!$A$2:$A$451,$H14,Dati!$H$2:$H$451,$AB14)+SUMIFS(Dati!$J$2:$J$451,Dati!$H$2:$H$451,$H14,Dati!$A$2:$A$451,$AB14),"-") | BA14: =IF(AND($H14<>"",$AC14<>"",$H14<>$AC14,IFERROR(VLOOKUP($H14,areaCercaPuntiClassificaSquadra,3,FALSE),-1)=IFERROR(VLOOKUP($AC14,areaCercaPuntiClassificaSquadra,3,FALSE),-2)),SUMIFS(Dati!$D$2:$D$451,Dati!$A$2:$A$451,$H14,Dati!$H$2:$H$451,$AC14)+SUMIFS(Dati!$K$2:$K$451,Dati!$H$2:$H$451,$H14,Dati!$A$2:$A$451,$AC14)+SUMIFS(Dati!$C$2:$C$451,Dati!$A$2:$A$451,$H14,Dati!$H$2:$H$451,$AC14)+SUMIFS(Dati!$J$2:$J$451,Dati!$H$2:$H$451,$H14,Dati!$A$2:$A$451,$AC14),"-") | BB14: =IF(AND($H14<>"",$AD14<>"",$H14<>$AD14,IFERROR(VLOOKUP($H14,areaCercaPuntiClassificaSquadra,3,FALSE),-1)=IFERROR(VLOOKUP($AD14,areaCercaPuntiClassificaSquadra,3,FALSE),-2)),SUMIFS(Dati!$D$2:$D$451,Dati!$A$2:$A$451,$H14,Dati!$H$2:$H$451,$AD14)+SUMIFS(Dati!$K$2:$K$451,Dati!$H$2:$H$451,$H14,Dati!$A$2:$A$451,$AD14)+SUMIFS(Dati!$C$2:$C$451,Dati!$A$2:$A$451,$H14,Dati!$H$2:$H$451,$AD14)+SUMIFS(Dati!$J$2:$J$451,Dati!$H$2:$H$451,$H14,Dati!$A$2:$A$451,$AD14),"-") | BC14: =IF(AND($H14<>"",$AE14<>"",$H14<>$AE14,IFERROR(VLOOKUP($H14,areaCercaPuntiClassificaSquadra,3,FALSE),-1)=IFERROR(VLOOKUP($AE14,areaCercaPuntiClassificaSquadra,3,FALSE),-2)),SUMIFS(Dati!$D$2:$D$451,Dati!$A$2:$A$451,$H14,Dati!$H$2:$H$451,$AE14)+SUMIFS(Dati!$K$2:$K$451,Dati!$H$2:$H$451,$H14,Dati!$A$2:$A$451,$AE14)+SUMIFS(Dati!$C$2:$C$451,Dati!$A$2:$A$451,$H14,Dati!$H$2:$H$451,$AE14)+SUMIFS(Dati!$J$2:$J$451,Dati!$H$2:$H$451,$H14,Dati!$A$2:$A$451,$AE14),"-") | BD14: =IF(AND($H14<>"",$AF14<>"",$H14<>$AF14,IFERROR(VLOOKUP($H14,areaCercaPuntiClassificaSquadra,3,FALSE),-1)=IFERROR(VLOOKUP($AF14,areaCercaPuntiClassificaSquadra,3,FALSE),-2)),SUMIFS(Dati!$D$2:$D$451,Dati!$A$2:$A$451,$H14,Dati!$H$2:$H$451,$AF14)+SUMIFS(Dati!$K$2:$K$451,Dati!$H$2:$H$451,$H14,Dati!$A$2:$A$451,$AF14)+SUMIFS(Dati!$C$2:$C$451,Dati!$A$2:$A$451,$H14,Dati!$H$2:$H$451,$AF14)+SUMIFS(Dati!$J$2:$J$451,Dati!$H$2:$H$451,$H14,Dati!$A$2:$A$451,$AF14),"-") | BE14: =IF(AND($H14<>"",$AG14<>"",$H14<>$AG14,IFERROR(VLOOKUP($H14,areaCercaPuntiClassificaSquadra,3,FALSE),-1)=IFERROR(VLOOKUP($AG14,areaCercaPuntiClassificaSquadra,3,FALSE),-2)),SUMIFS(Dati!$D$2:$D$451,Dati!$A$2:$A$451,$H14,Dati!$H$2:$H$451,$AG14)+SUMIFS(Dati!$K$2:$K$451,Dati!$H$2:$H$451,$H14,Dati!$A$2:$A$451,$AG14)+SUMIFS(Dati!$C$2:$C$451,Dati!$A$2:$A$451,$H14,Dati!$H$2:$H$451,$AG14)+SUMIFS(Dati!$J$2:$J$451,Dati!$H$2:$H$451,$H14,Dati!$A$2:$A$451,$AG14),"-") | BF14: =IF(AND($H14<>"",$AH14<>"",$H14<>$AH14,IFERROR(VLOOKUP($H14,areaCercaPuntiClassificaSquadra,3,FALSE),-1)=IFERROR(VLOOKUP($AH14,areaCercaPuntiClassificaSquadra,3,FALSE),-2)),SUMIFS(Dati!$D$2:$D$451,Dati!$A$2:$A$451,$H14,Dati!$H$2:$H$451,$AH14)+SUMIFS(Dati!$K$2:$K$451,Dati!$H$2:$H$451,$H14,Dati!$A$2:$A$451,$AH14)+SUMIFS(Dati!$C$2:$C$451,Dati!$A$2:$A$451,$H14,Dati!$H$2:$H$451,$AH14)+SUMIFS(Dati!$J$2:$J$451,Dati!$H$2:$H$451,$H14,Dati!$A$2:$A$451,$AH14),"-") | BH14: =$C14 | BI14: =IF(AND($H14<>"",$Y14<>"",$H14<>$Y14,IFERROR(VLOOKUP($H14,areaCercaPuntiClassificaSquadra,3,FALSE),-1)=IFERROR(VLOOKUP($Y14,areaCercaPuntiClassificaSquadra,3,FALSE),-2)),SUMIFS(Dati!$E$2:$E$451,Dati!$A$2:$A$451,$H14,Dati!$H$2:$H$451,$Y14)+SUMIFS(Dati!$L$2:$L$451,Dati!$H$2:$H$451,$H14,Dati!$A$2:$A$451,$Y14),"-") | BJ14: =IF(AND($H14<>"",$Z14<>"",$H14<>$Z14,IFERROR(VLOOKUP($H14,areaCercaPuntiClassificaSquadra,3,FALSE),-1)=IFERROR(VLOOKUP($Z14,areaCercaPuntiClassificaSquadra,3,FALSE),-2)),SUMIFS(Dati!$E$2:$E$451,Dati!$A$2:$A$451,$H14,Dati!$H$2:$H$451,$Z14)+SUMIFS(Dati!$L$2:$L$451,Dati!$H$2:$H$451,$H14,Dati!$A$2:$A$451,$Z14),"-") | BK14: =IF(AND($H14<>"",$AA14<>"",$H14<>$AA14,IFERROR(VLOOKUP($H14,areaCercaPuntiClassificaSquadra,3,FALSE),-1)=IFERROR(VLOOKUP($AA14,areaCercaPuntiClassificaSquadra,3,FALSE),-2)),SUMIFS(Dati!$E$2:$E$451,Dati!$A$2:$A$451,$H14,Dati!$H$2:$H$451,$AA14)+SUMIFS(Dati!$L$2:$L$451,Dati!$H$2:$H$451,$H14,Dati!$A$2:$A$451,$AA14),"-") | BL14: =IF(AND($H14<>"",$AB14<>"",$H14<>$AB14,IFERROR(VLOOKUP($H14,areaCercaPuntiClassificaSquadra,3,FALSE),-1)=IFERROR(VLOOKUP($AB14,areaCercaPuntiClassificaSquadra,3,FALSE),-2)),SUMIFS(Dati!$E$2:$E$451,Dati!$A$2:$A$451,$H14,Dati!$H$2:$H$451,$AB14)+SUMIFS(Dati!$L$2:$L$451,Dati!$H$2:$H$451,$H14,Dati!$A$2:$A$451,$AB14),"-") | BM14: =IF(AND($H14<>"",$AC14<>"",$H14<>$AC14,IFERROR(VLOOKUP($H14,areaCercaPuntiClassificaSquadra,3,FALSE),-1)=IFERROR(VLOOKUP($AC14,areaCercaPuntiClassificaSquadra,3,FALSE),-2)),SUMIFS(Dati!$E$2:$E$451,Dati!$A$2:$A$451,$H14,Dati!$H$2:$H$451,$AC14)+SUMIFS(Dati!$L$2:$L$451,Dati!$H$2:$H$451,$H14,Dati!$A$2:$A$451,$AC14),"-") | BN14: =IF(AND($H14<>"",$AD14<>"",$H14<>$AD14,IFERROR(VLOOKUP($H14,areaCercaPuntiClassificaSquadra,3,FALSE),-1)=IFERROR(VLOOKUP($AD14,areaCercaPuntiClassificaSquadra,3,FALSE),-2)),SUMIFS(Dati!$E$2:$E$451,Dati!$A$2:$A$451,$H14,Dati!$H$2:$H$451,$AD14)+SUMIFS(Dati!$L$2:$L$451,Dati!$H$2:$H$451,$H14,Dati!$A$2:$A$451,$AD14),"-") | BO14: =IF(AND($H14<>"",$AE14<>"",$H14<>$AE14,IFERROR(VLOOKUP($H14,areaCercaPuntiClassificaSquadra,3,FALSE),-1)=IFERROR(VLOOKUP($AE14,areaCercaPuntiClassificaSquadra,3,FALSE),-2)),SUMIFS(Dati!$E$2:$E$451,Dati!$A$2:$A$451,$H14,Dati!$H$2:$H$451,$AE14)+SUMIFS(Dati!$L$2:$L$451,Dati!$H$2:$H$451,$H14,Dati!$A$2:$A$451,$AE14),"-") | BP14: =IF(AND($H14<>"",$AF14<>"",$H14<>$AF14,IFERROR(VLOOKUP($H14,areaCercaPuntiClassificaSquadra,3,FALSE),-1)=IFERROR(VLOOKUP($AF14,areaCercaPuntiClassificaSquadra,3,FALSE),-2)),SUMIFS(Dati!$E$2:$E$451,Dati!$A$2:$A$451,$H14,Dati!$H$2:$H$451,$AF14)+SUMIFS(Dati!$L$2:$L$451,Dati!$H$2:$H$451,$H14,Dati!$A$2:$A$451,$AF14),"-") | BQ14: =IF(AND($H14<>"",$AG14<>"",$H14<>$AG14,IFERROR(VLOOKUP($H14,areaCercaPuntiClassificaSquadra,3,FALSE),-1)=IFERROR(VLOOKUP($AG14,areaCercaPuntiClassificaSquadra,3,FALSE),-2)),SUMIFS(Dati!$E$2:$E$451,Dati!$A$2:$A$451,$H14,Dati!$H$2:$H$451,$AG14)+SUMIFS(Dati!$L$2:$L$451,Dati!$H$2:$H$451,$H14,Dati!$A$2:$A$451,$AG14),"-") | BR14: =IF(AND($H14<>"",$AH14<>"",$H14<>$AH14,IFERROR(VLOOKUP($H14,areaCercaPuntiClassificaSquadra,3,FALSE),-1)=IFERROR(VLOOKUP($AH14,areaCercaPuntiClassificaSquadra,3,FALSE),-2)),SUMIFS(Dati!$E$2:$E$451,Dati!$A$2:$A$451,$H14,Dati!$H$2:$H$451,$AH14)+SUMIFS(Dati!$L$2:$L$451,Dati!$H$2:$H$451,$H14,Dati!$A$2:$A$451,$AH14),"-") | BT14: =$C14 | BU14: =IF(AND($H14<>"",$Y14<>"",$H14<>$Y14,IFERROR(VLOOKUP($H14,areaCercaPuntiClassificaSquadra,3,FALSE),-1)=IFERROR(VLOOKUP($Y14,areaCercaPuntiClassificaSquadra,3,FALSE),-2)),SUMIFS(Dati!$F$2:$F$451,Dati!$A$2:$A$451,$H14,Dati!$H$2:$H$451,$Y14)+SUMIFS(Dati!$M$2:$M$451,Dati!$H$2:$H$451,$H14,Dati!$A$2:$A$451,$Y14),"-") | BV14: =IF(AND($H14<>"",$Z14<>"",$H14<>$Z14,IFERROR(VLOOKUP($H14,areaCercaPuntiClassificaSquadra,3,FALSE),-1)=IFERROR(VLOOKUP($Z14,areaCercaPuntiClassificaSquadra,3,FALSE),-2)),SUMIFS(Dati!$F$2:$F$451,Dati!$A$2:$A$451,$H14,Dati!$H$2:$H$451,$Z14)+SUMIFS(Dati!$M$2:$M$451,Dati!$H$2:$H$451,$H14,Dati!$A$2:$A$451,$Z14),"-") | BW14: =IF(AND($H14<>"",$AA14<>"",$H14<>$AA14,IFERROR(VLOOKUP($H14,areaCercaPuntiClassificaSquadra,3,FALSE),-1)=IFERROR(VLOOKUP($AA14,areaCercaPuntiClassificaSquadra,3,FALSE),-2)),SUMIFS(Dati!$F$2:$F$451,Dati!$A$2:$A$451,$H14,Dati!$H$2:$H$451,$AA14)+SUMIFS(Dati!$M$2:$M$451,Dati!$H$2:$H$451,$H14,Dati!$A$2:$A$451,$AA14),"-") | BX14: =IF(AND($H14<>"",$AB14<>"",$H14<>$AB14,IFERROR(VLOOKUP($H14,areaCercaPuntiClassificaSquadra,3,FALSE),-1)=IFERROR(VLOOKUP($AB14,areaCercaPuntiClassificaSquadra,3,FALSE),-2)),SUMIFS(Dati!$F$2:$F$451,Dati!$A$2:$A$451,$H14,Dati!$H$2:$H$451,$AB14)+SUMIFS(Dati!$M$2:$M$451,Dati!$H$2:$H$451,$H14,Dati!$A$2:$A$451,$AB14),"-") | BY14: =IF(AND($H14<>"",$AC14<>"",$H14<>$AC14,IFERROR(VLOOKUP($H14,areaCercaPuntiClassificaSquadra,3,FALSE),-1)=IFERROR(VLOOKUP($AC14,areaCercaPuntiClassificaSquadra,3,FALSE),-2)),SUMIFS(Dati!$F$2:$F$451,Dati!$A$2:$A$451,$H14,Dati!$H$2:$H$451,$AC14)+SUMIFS(Dati!$M$2:$M$451,Dati!$H$2:$H$451,$H14,Dati!$A$2:$A$451,$AC14),"-") | BZ14: =IF(AND($H14<>"",$AD14<>"",$H14<>$AD14,IFERROR(VLOOKUP($H14,areaCercaPuntiClassificaSquadra,3,FALSE),-1)=IFERROR(VLOOKUP($AD14,areaCercaPuntiClassificaSquadra,3,FALSE),-2)),SUMIFS(Dati!$F$2:$F$451,Dati!$A$2:$A$451,$H14,Dati!$H$2:$H$451,$AD14)+SUMIFS(Dati!$M$2:$M$451,Dati!$H$2:$H$451,$H14,Dati!$A$2:$A$451,$AD14),"-") | CA14: =IF(AND($H14<>"",$AE14<>"",$H14<>$AE14,IFERROR(VLOOKUP($H14,areaCercaPuntiClassificaSquadra,3,FALSE),-1)=IFERROR(VLOOKUP($AE14,areaCercaPuntiClassificaSquadra,3,FALSE),-2)),SUMIFS(Dati!$F$2:$F$451,Dati!$A$2:$A$451,$H14,Dati!$H$2:$H$451,$AE14)+SUMIFS(Dati!$M$2:$M$451,Dati!$H$2:$H$451,$H14,Dati!$A$2:$A$451,$AE14),"-") | CB14: =IF(AND($H14<>"",$AF14<>"",$H14<>$AF14,IFERROR(VLOOKUP($H14,areaCercaPuntiClassificaSquadra,3,FALSE),-1)=IFERROR(VLOOKUP($AF14,areaCercaPuntiClassificaSquadra,3,FALSE),-2)),SUMIFS(Dati!$F$2:$F$451,Dati!$A$2:$A$451,$H14,Dati!$H$2:$H$451,$AF14)+SUMIFS(Dati!$M$2:$M$451,Dati!$H$2:$H$451,$H14,Dati!$A$2:$A$451,$AF14),"-") | CC14: =IF(AND($H14<>"",$AG14<>"",$H14<>$AG14,IFERROR(VLOOKUP($H14,areaCercaPuntiClassificaSquadra,3,FALSE),-1)=IFERROR(VLOOKUP($AG14,areaCercaPuntiClassificaSquadra,3,FALSE),-2)),SUMIFS(Dati!$F$2:$F$451,Dati!$A$2:$A$451,$H14,Dati!$H$2:$H$451,$AG14)+SUMIFS(Dati!$M$2:$M$451,Dati!$H$2:$H$451,$H14,Dati!$A$2:$A$451,$AG14),"-") | CD14: =IF(AND($H14<>"",$AH14<>"",$H14<>$AH14,IFERROR(VLOOKUP($H14,areaCercaPuntiClassificaSquadra,3,FALSE),-1)=IFERROR(VLOOKUP($AH14,areaCercaPuntiClassificaSquadra,3,FALSE),-2)),SUMIFS(Dati!$F$2:$F$451,Dati!$A$2:$A$451,$H14,Dati!$H$2:$H$451,$AH14)+SUMIFS(Dati!$M$2:$M$451,Dati!$H$2:$H$451,$H14,Dati!$A$2:$A$451,$AH14),"-") | CF14: =IF($C14="","",SUM(AK14:AT14))
B15: A02 | E15: A | G15: =IF($C15="","",$E15&(COUNTIFS(I$14:I$113,">"&I15,E$14:E$113,"="&E15,C$14:C$113,"<>")+COUNTIFS(I$14:I$113,"="&I15,H$14:H$113,"<="&H15,E$14:E$113,"="&E15,C$14:C$113,"<>"))) | H15: =IF($C15="","",IFERROR(LEFT($C15,FIND("-",$C15)-1),$C15)) | I15: =TEXT(1000000000+J15,"|0000000000|")&TEXT(SUM(AK15:AT15),"0000000000|")&IF(SUM(BU15:CD15)=0,"0000000000|",TEXT(ROUND(SUM(BI15:BR15)/SUM(BU15:CD15),4)*100000,"0000000000|"))&IF(P15=0,"0000000000|",TEXT(ROUND(O15/P15,4)*100000,"0000000000|")) | J15: =L15*constPuntiVittoria+M15*constPuntiSconfitta+N15*constPuntiForfait+IF(D15="",0,D15) | K15: =SUM(L15:N15) | L15: =IF($H15="",0,SUMIF(Dati!$A$2:$A$451,$H15,Dati!$B$2:$B$451)+SUMIF(Dati!$H$2:$H$451,$H15,Dati!$I$2:$I$451)) | M15: =IF($H15="",0,SUMIF(Dati!$A$2:$A$451,$H15,Dati!$D$2:$D$451)+SUMIF(Dati!$H$2:$H$451,$H15,Dati!$K$2:$K$451)) | N15: =IF($H15="",0,SUMIF(Dati!$A$2:$A$451,$H15,Dati!$C$2:$C$451)+SUMIF(Dati!$H$2:$H$451,$H15,Dati!$J$2:$J$451)) | O15: =IF($H15="",0,SUMIF(Dati!$A$2:$A$451,$H15,Dati!$E$2:$E$451)+SUMIF(Dati!$H$2:$H$451,$H15,Dati!$L$2:$L$451)) | P15: =IF($H15="",0,SUMIF(Dati!$A$2:$A$451,$H15,Dati!$F$2:$F$451)+SUMIF(Dati!$H$2:$H$451,$H15,Dati!$M$2:$M$451)) | Q15: =IF($H15="",0,SUMIF(Dati!$A$2:$A$451,$H15,Dati!$G$2:$G$451)+SUMIF(Dati!$H$2:$H$451,$H15,Dati!$N$2:$N$451)) | R15: =IF(K15=0,0,ROUND(O15/K15,2)) | S15: =IF(K15=0,0,ROUND(P15/K15,2)) | T15: =IF(K15=0,0,ROUND(Q15/K15,2)) | U15: =IF(COUNTIFS($E$14:$E$113,$E15,$J$14:$J$113,$J15,$C$14:$C$113,"<>")<=1,"-",SUM(AK15:AT15)&"-"&SUM(AW15:BF15)) | V15: =IF(COUNTIFS($E$14:$E$113,$E15,$J$14:$J$113,$J15,$C$14:$C$113,"<>",$CF$14:$CF$113,$CF15)<=1,"-",IF(SUM(BU15:CD15)=0,0,ROUND(SUM(BI15:BR15)/SUM(BU15:CD15),3))) | W15: =IF(COUNTIFS($E$14:$E$113,$E15,$J$14:$J$113,$J15,$C$14:$C$113,"<>",$CF$14:$CF$113,$CF15,$V$14:$V$113,$V15)<=1,"-",IF(P15=0,0,ROUND(O15/P15,3))) | X15: =IF($C15="","",$E15&"#"&COUNTIFS($E$14:$E15,$E15,$C$14:$C15,"<>")) | Y15: =IFERROR(INDEX($H$14:$H$113,MATCH($E15&"#1",$X$14:$X$113,0)),"") | Z15: =IFERROR(INDEX($H$14:$H$113,MATCH($E15&"#2",$X$14:$X$113,0)),"") | AA15: =IFERROR(INDEX($H$14:$H$113,MATCH($E15&"#3",$X$14:$X$113,0)),"") | AB15: =IFERROR(INDEX($H$14:$H$113,MATCH($E15&"#4",$X$14:$X$113,0)),"") | AC15: =IFERROR(INDEX($H$14:$H$113,MATCH($E15&"#5",$X$14:$X$113,0)),"") | AD15: =IFERROR(INDEX($H$14:$H$113,MATCH($E15&"#6",$X$14:$X$113,0)),"") | AE15: =IFERROR(INDEX($H$14:$H$113,MATCH($E15&"#7",$X$14:$X$113,0)),"") | AF15: =IFERROR(INDEX($H$14:$H$113,MATCH($E15&"#8",$X$14:$X$113,0)),"") | AG15: =IFERROR(INDEX($H$14:$H$113,MATCH($E15&"#9",$X$14:$X$113,0)),"") | AH15: =IFERROR(INDEX($H$14:$H$113,MATCH($E15&"#10",$X$14:$X$113,0)),"") | AJ15: =$C15 | AK15: =IF(AND($H15<>"",$Y15<>"",$H15<>$Y15,IFERROR(VLOOKUP($H15,areaCercaPuntiClassificaSquadra,3,FALSE),-1)=IFERROR(VLOOKUP($Y15,areaCercaPuntiClassificaSquadra,3,FALSE),-2)),SUMIFS(Dati!$B$2:$B$451,Dati!$A$2:$A$451,$H15,Dati!$H$2:$H$451,$Y15)+SUMIFS(Dati!$I$2:$I$451,Dati!$H$2:$H$451,$H15,Dati!$A$2:$A$451,$Y15),"-") | AL15: =IF(AND($H15<>"",$Z15<>"",$H15<>$Z15,IFERROR(VLOOKUP($H15,areaCercaPuntiClassificaSquadra,3,FALSE),-1)=IFERROR(VLOOKUP($Z15,areaCercaPuntiClassificaSquadra,3,FALSE),-2)),SUMIFS(Dati!$B$2:$B$451,Dati!$A$2:$A$451,$H15,Dati!$H$2:$H$451,$Z15)+SUMIFS(Dati!$I$2:$I$451,Dati!$H$2:$H$451,$H15,Dati!$A$2:$A$451,$Z15),"-") | AM15: =IF(AND($H15<>"",$AA15<>"",$H15<>$AA15,IFERROR(VLOOKUP($H15,areaCercaPuntiClassificaSquadra,3,FALSE),-1)=IFERROR(VLOOKUP($AA15,areaCercaPuntiClassificaSquadra,3,FALSE),-2)),SUMIFS(Dati!$B$2:$B$451,Dati!$A$2:$A$451,$H15,Dati!$H$2:$H$451,$AA15)+SUMIFS(Dati!$I$2:$I$451,Dati!$H$2:$H$451,$H15,Dati!$A$2:$A$451,$AA15),"-") | AN15: =IF(AND($H15<>"",$AB15<>"",$H15<>$AB15,IFERROR(VLOOKUP($H15,areaCercaPuntiClassificaSquadra,3,FALSE),-1)=IFERROR(VLOOKUP($AB15,areaCercaPuntiClassificaSquadra,3,FALSE),-2)),SUMIFS(Dati!$B$2:$B$451,Dati!$A$2:$A$451,$H15,Dati!$H$2:$H$451,$AB15)+SUMIFS(Dati!$I$2:$I$451,Dati!$H$2:$H$451,$H15,Dati!$A$2:$A$451,$AB15),"-") | AO15: =IF(AND($H15<>"",$AC15<>"",$H15<>$AC15,IFERROR(VLOOKUP($H15,areaCercaPuntiClassificaSquadra,3,FALSE),-1)=IFERROR(VLOOKUP($AC15,areaCercaPuntiClassificaSquadra,3,FALSE),-2)),SUMIFS(Dati!$B$2:$B$451,Dati!$A$2:$A$451,$H15,Dati!$H$2:$H$451,$AC15)+SUMIFS(Dati!$I$2:$I$451,Dati!$H$2:$H$451,$H15,Dati!$A$2:$A$451,$AC15),"-") | AP15: =IF(AND($H15<>"",$AD15<>"",$H15<>$AD15,IFERROR(VLOOKUP($H15,areaCercaPuntiClassificaSquadra,3,FALSE),-1)=IFERROR(VLOOKUP($AD15,areaCercaPuntiClassificaSquadra,3,FALSE),-2)),SUMIFS(Dati!$B$2:$B$451,Dati!$A$2:$A$451,$H15,Dati!$H$2:$H$451,$AD15)+SUMIFS(Dati!$I$2:$I$451,Dati!$H$2:$H$451,$H15,Dati!$A$2:$A$451,$AD15),"-") | AQ15: =IF(AND($H15<>"",$AE15<>"",$H15<>$AE15,IFERROR(VLOOKUP($H15,areaCercaPuntiClassificaSquadra,3,FALSE),-1)=IFERROR(VLOOKUP($AE15,areaCercaPuntiClassificaSquadra,3,FALSE),-2)),SUMIFS(Dati!$B$2:$B$451,Dati!$A$2:$A$451,$H15,Dati!$H$2:$H$451,$AE15)+SUMIFS(Dati!$I$2:$I$451,Dati!$H$2:$H$451,$H15,Dati!$A$2:$A$451,$AE15),"-") | AR15: =IF(AND($H15<>"",$AF15<>"",$H15<>$AF15,IFERROR(VLOOKUP($H15,areaCercaPuntiClassificaSquadra,3,FALSE),-1)=IFERROR(VLOOKUP($AF15,areaCercaPuntiClassificaSquadra,3,FALSE),-2)),SUMIFS(Dati!$B$2:$B$451,Dati!$A$2:$A$451,$H15,Dati!$H$2:$H$451,$AF15)+SUMIFS(Dati!$I$2:$I$451,Dati!$H$2:$H$451,$H15,Dati!$A$2:$A$451,$AF15),"-") | AS15: =IF(AND($H15<>"",$AG15<>"",$H15<>$AG15,IFERROR(VLOOKUP($H15,areaCercaPuntiClassificaSquadra,3,FALSE),-1)=IFERROR(VLOOKUP($AG15,areaCercaPuntiClassificaSquadra,3,FALSE),-2)),SUMIFS(Dati!$B$2:$B$451,Dati!$A$2:$A$451,$H15,Dati!$H$2:$H$451,$AG15)+SUMIFS(Dati!$I$2:$I$451,Dati!$H$2:$H$451,$H15,Dati!$A$2:$A$451,$AG15),"-") | AT15: =IF(AND($H15<>"",$AH15<>"",$H15<>$AH15,IFERROR(VLOOKUP($H15,areaCercaPuntiClassificaSquadra,3,FALSE),-1)=IFERROR(VLOOKUP($AH15,areaCercaPuntiClassificaSquadra,3,FALSE),-2)),SUMIFS(Dati!$B$2:$B$451,Dati!$A$2:$A$451,$H15,Dati!$H$2:$H$451,$AH15)+SUMIFS(Dati!$I$2:$I$451,Dati!$H$2:$H$451,$H15,Dati!$A$2:$A$451,$AH15),"-") | AV15: =$C15 | AW15: =IF(AND($H15<>"",$Y15<>"",$H15<>$Y15,IFERROR(VLOOKUP($H15,areaCercaPuntiClassificaSquadra,3,FALSE),-1)=IFERROR(VLOOKUP($Y15,areaCercaPuntiClassificaSquadra,3,FALSE),-2)),SUMIFS(Dati!$D$2:$D$451,Dati!$A$2:$A$451,$H15,Dati!$H$2:$H$451,$Y15)+SUMIFS(Dati!$K$2:$K$451,Dati!$H$2:$H$451,$H15,Dati!$A$2:$A$451,$Y15)+SUMIFS(Dati!$C$2:$C$451,Dati!$A$2:$A$451,$H15,Dati!$H$2:$H$451,$Y15)+SUMIFS(Dati!$J$2:$J$451,Dati!$H$2:$H$451,$H15,Dati!$A$2:$A$451,$Y15),"-") | AX15: =IF(AND($H15<>"",$Z15<>"",$H15<>$Z15,IFERROR(VLOOKUP($H15,areaCercaPuntiClassificaSquadra,3,FALSE),-1)=IFERROR(VLOOKUP($Z15,areaCercaPuntiClassificaSquadra,3,FALSE),-2)),SUMIFS(Dati!$D$2:$D$451,Dati!$A$2:$A$451,$H15,Dati!$H$2:$H$451,$Z15)+SUMIFS(Dati!$K$2:$K$451,Dati!$H$2:$H$451,$H15,Dati!$A$2:$A$451,$Z15)+SUMIFS(Dati!$C$2:$C$451,Dati!$A$2:$A$451,$H15,Dati!$H$2:$H$451,$Z15)+SUMIFS(Dati!$J$2:$J$451,Dati!$H$2:$H$451,$H15,Dati!$A$2:$A$451,$Z15),"-") | AY15: =IF(AND($H15<>"",$AA15<>"",$H15<>$AA15,IFERROR(VLOOKUP($H15,areaCercaPuntiClassificaSquadra,3,FALSE),-1)=IFERROR(VLOOKUP($AA15,areaCercaPuntiClassificaSquadra,3,FALSE),-2)),SUMIFS(Dati!$D$2:$D$451,Dati!$A$2:$A$451,$H15,Dati!$H$2:$H$451,$AA15)+SUMIFS(Dati!$K$2:$K$451,Dati!$H$2:$H$451,$H15,Dati!$A$2:$A$451,$AA15)+SUMIFS(Dati!$C$2:$C$451,Dati!$A$2:$A$451,$H15,Dati!$H$2:$H$451,$AA15)+SUMIFS(Dati!$J$2:$J$451,Dati!$H$2:$H$451,$H15,Dati!$A$2:$A$451,$AA15),"-") | AZ15: =IF(AND($H15<>"",$AB15<>"",$H15<>$AB15,IFERROR(VLOOKUP($H15,areaCercaPuntiClassificaSquadra,3,FALSE),-1)=IFERROR(VLOOKUP($AB15,areaCercaPuntiClassificaSquadra,3,FALSE),-2)),SUMIFS(Dati!$D$2:$D$451,Dati!$A$2:$A$451,$H15,Dati!$H$2:$H$451,$AB15)+SUMIFS(Dati!$K$2:$K$451,Dati!$H$2:$H$451,$H15,Dati!$A$2:$A$451,$AB15)+SUMIFS(Dati!$C$2:$C$451,Dati!$A$2:$A$451,$H15,Dati!$H$2:$H$451,$AB15)+SUMIFS(Dati!$J$2:$J$451,Dati!$H$2:$H$451,$H15,Dati!$A$2:$A$451,$AB15),"-") | BA15: =IF(AND($H15<>"",$AC15<>"",$H15<>$AC15,IFERROR(VLOOKUP($H15,areaCercaPuntiClassificaSquadra,3,FALSE),-1)=IFERROR(VLOOKUP($AC15,areaCercaPuntiClassificaSquadra,3,FALSE),-2)),SUMIFS(Dati!$D$2:$D$451,Dati!$A$2:$A$451,$H15,Dati!$H$2:$H$451,$AC15)+SUMIFS(Dati!$K$2:$K$451,Dati!$H$2:$H$451,$H15,Dati!$A$2:$A$451,$AC15)+SUMIFS(Dati!$C$2:$C$451,Dati!$A$2:$A$451,$H15,Dati!$H$2:$H$451,$AC15)+SUMIFS(Dati!$J$2:$J$451,Dati!$H$2:$H$451,$H15,Dati!$A$2:$A$451,$AC15),"-") | BB15: =IF(AND($H15<>"",$AD15<>"",$H15<>$AD15,IFERROR(VLOOKUP($H15,areaCercaPuntiClassificaSquadra,3,FALSE),-1)=IFERROR(VLOOKUP($AD15,areaCercaPuntiClassificaSquadra,3,FALSE),-2)),SUMIFS(Dati!$D$2:$D$451,Dati!$A$2:$A$451,$H15,Dati!$H$2:$H$451,$AD15)+SUMIFS(Dati!$K$2:$K$451,Dati!$H$2:$H$451,$H15,Dati!$A$2:$A$451,$AD15)+SUMIFS(Dati!$C$2:$C$451,Dati!$A$2:$A$451,$H15,Dati!$H$2:$H$451,$AD15)+SUMIFS(Dati!$J$2:$J$451,Dati!$H$2:$H$451,$H15,Dati!$A$2:$A$451,$AD15),"-") | BC15: =IF(AND($H15<>"",$AE15<>"",$H15<>$AE15,IFERROR(VLOOKUP($H15,areaCercaPuntiClassificaSquadra,3,FALSE),-1)=IFERROR(VLOOKUP($AE15,areaCercaPuntiClassificaSquadra,3,FALSE),-2)),SUMIFS(Dati!$D$2:$D$451,Dati!$A$2:$A$451,$H15,Dati!$H$2:$H$451,$AE15)+SUMIFS(Dati!$K$2:$K$451,Dati!$H$2:$H$451,$H15,Dati!$A$2:$A$451,$AE15)+SUMIFS(Dati!$C$2:$C$451,Dati!$A$2:$A$451,$H15,Dati!$H$2:$H$451,$AE15)+SUMIFS(Dati!$J$2:$J$451,Dati!$H$2:$H$451,$H15,Dati!$A$2:$A$451,$AE15),"-") | BD15: =IF(AND($H15<>"",$AF15<>"",$H15<>$AF15,IFERROR(VLOOKUP($H15,areaCercaPuntiClassificaSquadra,3,FALSE),-1)=IFERROR(VLOOKUP($AF15,areaCercaPuntiClassificaSquadra,3,FALSE),-2)),SUMIFS(Dati!$D$2:$D$451,Dati!$A$2:$A$451,$H15,Dati!$H$2:$H$451,$AF15)+SUMIFS(Dati!$K$2:$K$451,Dati!$H$2:$H$451,$H15,Dati!$A$2:$A$451,$AF15)+SUMIFS(Dati!$C$2:$C$451,Dati!$A$2:$A$451,$H15,Dati!$H$2:$H$451,$AF15)+SUMIFS(Dati!$J$2:$J$451,Dati!$H$2:$H$451,$H15,Dati!$A$2:$A$451,$AF15),"-") | BE15: =IF(AND($H15<>"",$AG15<>"",$H15<>$AG15,IFERROR(VLOOKUP($H15,areaCercaPuntiClassificaSquadra,3,FALSE),-1)=IFERROR(VLOOKUP($AG15,areaCercaPuntiClassificaSquadra,3,FALSE),-2)),SUMIFS(Dati!$D$2:$D$451,Dati!$A$2:$A$451,$H15,Dati!$H$2:$H$451,$AG15)+SUMIFS(Dati!$K$2:$K$451,Dati!$H$2:$H$451,$H15,Dati!$A$2:$A$451,$AG15)+SUMIFS(Dati!$C$2:$C$451,Dati!$A$2:$A$451,$H15,Dati!$H$2:$H$451,$AG15)+SUMIFS(Dati!$J$2:$J$451,Dati!$H$2:$H$451,$H15,Dati!$A$2:$A$451,$AG15),"-") | BF15: =IF(AND($H15<>"",$AH15<>"",$H15<>$AH15,IFERROR(VLOOKUP($H15,areaCercaPuntiClassificaSquadra,3,FALSE),-1)=IFERROR(VLOOKUP($AH15,areaCercaPuntiClassificaSquadra,3,FALSE),-2)),SUMIFS(Dati!$D$2:$D$451,Dati!$A$2:$A$451,$H15,Dati!$H$2:$H$451,$AH15)+SUMIFS(Dati!$K$2:$K$451,Dati!$H$2:$H$451,$H15,Dati!$A$2:$A$451,$AH15)+SUMIFS(Dati!$C$2:$C$451,Dati!$A$2:$A$451,$H15,Dati!$H$2:$H$451,$AH15)+SUMIFS(Dati!$J$2:$J$451,Dati!$H$2:$H$451,$H15,Dati!$A$2:$A$451,$AH15),"-") | BH15: =$C15 | BI15: =IF(AND($H15<>"",$Y15<>"",$H15<>$Y15,IFERROR(VLOOKUP($H15,areaCercaPuntiClassificaSquadra,3,FALSE),-1)=IFERROR(VLOOKUP($Y15,areaCercaPuntiClassificaSquadra,3,FALSE),-2)),SUMIFS(Dati!$E$2:$E$451,Dati!$A$2:$A$451,$H15,Dati!$H$2:$H$451,$Y15)+SUMIFS(Dati!$L$2:$L$451,Dati!$H$2:$H$451,$H15,Dati!$A$2:$A$451,$Y15),"-") | BJ15: =IF(AND($H15<>"",$Z15<>"",$H15<>$Z15,IFERROR(VLOOKUP($H15,areaCercaPuntiClassificaSquadra,3,FALSE),-1)=IFERROR(VLOOKUP($Z15,areaCercaPuntiClassificaSquadra,3,FALSE),-2)),SUMIFS(Dati!$E$2:$E$451,Dati!$A$2:$A$451,$H15,Dati!$H$2:$H$451,$Z15)+SUMIFS(Dati!$L$2:$L$451,Dati!$H$2:$H$451,$H15,Dati!$A$2:$A$451,$Z15),"-") | BK15: =IF(AND($H15<>"",$AA15<>"",$H15<>$AA15,IFERROR(VLOOKUP($H15,areaCercaPuntiClassificaSquadra,3,FALSE),-1)=IFERROR(VLOOKUP($AA15,areaCercaPuntiClassificaSquadra,3,FALSE),-2)),SUMIFS(Dati!$E$2:$E$451,Dati!$A$2:$A$451,$H15,Dati!$H$2:$H$451,$AA15)+SUMIFS(Dati!$L$2:$L$451,Dati!$H$2:$H$451,$H15,Dati!$A$2:$A$451,$AA15),"-") | BL15: =IF(AND($H15<>"",$AB15<>"",$H15<>$AB15,IFERROR(VLOOKUP($H15,areaCercaPuntiClassificaSquadra,3,FALSE),-1)=IFERROR(VLOOKUP($AB15,areaCercaPuntiClassificaSquadra,3,FALSE),-2)),SUMIFS(Dati!$E$2:$E$451,Dati!$A$2:$A$451,$H15,Dati!$H$2:$H$451,$AB15)+SUMIFS(Dati!$L$2:$L$451,Dati!$H$2:$H$451,$H15,Dati!$A$2:$A$451,$AB15),"-") | BM15: =IF(AND($H15<>"",$AC15<>"",$H15<>$AC15,IFERROR(VLOOKUP($H15,areaCercaPuntiClassificaSquadra,3,FALSE),-1)=IFERROR(VLOOKUP($AC15,areaCercaPuntiClassificaSquadra,3,FALSE),-2)),SUMIFS(Dati!$E$2:$E$451,Dati!$A$2:$A$451,$H15,Dati!$H$2:$H$451,$AC15)+SUMIFS(Dati!$L$2:$L$451,Dati!$H$2:$H$451,$H15,Dati!$A$2:$A$451,$AC15),"-") | BN15: =IF(AND($H15<>"",$AD15<>"",$H15<>$AD15,IFERROR(VLOOKUP($H15,areaCercaPuntiClassificaSquadra,3,FALSE),-1)=IFERROR(VLOOKUP($AD15,areaCercaPuntiClassificaSquadra,3,FALSE),-2)),SUMIFS(Dati!$E$2:$E$451,Dati!$A$2:$A$451,$H15,Dati!$H$2:$H$451,$AD15)+SUMIFS(Dati!$L$2:$L$451,Dati!$H$2:$H$451,$H15,Dati!$A$2:$A$451,$AD15),"-") | BO15: =IF(AND($H15<>"",$AE15<>"",$H15<>$AE15,IFERROR(VLOOKUP($H15,areaCercaPuntiClassificaSquadra,3,FALSE),-1)=IFERROR(VLOOKUP($AE15,areaCercaPuntiClassificaSquadra,3,FALSE),-2)),SUMIFS(Dati!$E$2:$E$451,Dati!$A$2:$A$451,$H15,Dati!$H$2:$H$451,$AE15)+SUMIFS(Dati!$L$2:$L$451,Dati!$H$2:$H$451,$H15,Dati!$A$2:$A$451,$AE15),"-") | BP15: =IF(AND($H15<>"",$AF15<>"",$H15<>$AF15,IFERROR(VLOOKUP($H15,areaCercaPuntiClassificaSquadra,3,FALSE),-1)=IFERROR(VLOOKUP($AF15,areaCercaPuntiClassificaSquadra,3,FALSE),-2)),SUMIFS(Dati!$E$2:$E$451,Dati!$A$2:$A$451,$H15,Dati!$H$2:$H$451,$AF15)+SUMIFS(Dati!$L$2:$L$451,Dati!$H$2:$H$451,$H15,Dati!$A$2:$A$451,$AF15),"-") | BQ15: =IF(AND($H15<>"",$AG15<>"",$H15<>$AG15,IFERROR(VLOOKUP($H15,areaCercaPuntiClassificaSquadra,3,FALSE),-1)=IFERROR(VLOOKUP($AG15,areaCercaPuntiClassificaSquadra,3,FALSE),-2)),SUMIFS(Dati!$E$2:$E$451,Dati!$A$2:$A$451,$H15,Dati!$H$2:$H$451,$AG15)+SUMIFS(Dati!$L$2:$L$451,Dati!$H$2:$H$451,$H15,Dati!$A$2:$A$451,$AG15),"-") | BR15: =IF(AND($H15<>"",$AH15<>"",$H15<>$AH15,IFERROR(VLOOKUP($H15,areaCercaPuntiClassificaSquadra,3,FALSE),-1)=IFERROR(VLOOKUP($AH15,areaCercaPuntiClassificaSquadra,3,FALSE),-2)),SUMIFS(Dati!$E$2:$E$451,Dati!$A$2:$A$451,$H15,Dati!$H$2:$H$451,$AH15)+SUMIFS(Dati!$L$2:$L$451,Dati!$H$2:$H$451,$H15,Dati!$A$2:$A$451,$AH15),"-") | BT15: =$C15 | BU15: =IF(AND($H15<>"",$Y15<>"",$H15<>$Y15,IFERROR(VLOOKUP($H15,areaCercaPuntiClassificaSquadra,3,FALSE),-1)=IFERROR(VLOOKUP($Y15,areaCercaPuntiClassificaSquadra,3,FALSE),-2)),SUMIFS(Dati!$F$2:$F$451,Dati!$A$2:$A$451,$H15,Dati!$H$2:$H$451,$Y15)+SUMIFS(Dati!$M$2:$M$451,Dati!$H$2:$H$451,$H15,Dati!$A$2:$A$451,$Y15),"-") | BV15: =IF(AND($H15<>"",$Z15<>"",$H15<>$Z15,IFERROR(VLOOKUP($H15,areaCercaPuntiClassificaSquadra,3,FALSE),-1)=IFERROR(VLOOKUP($Z15,areaCercaPuntiClassificaSquadra,3,FALSE),-2)),SUMIFS(Dati!$F$2:$F$451,Dati!$A$2:$A$451,$H15,Dati!$H$2:$H$451,$Z15)+SUMIFS(Dati!$M$2:$M$451,Dati!$H$2:$H$451,$H15,Dati!$A$2:$A$451,$Z15),"-") | BW15: =IF(AND($H15<>"",$AA15<>"",$H15<>$AA15,IFERROR(VLOOKUP($H15,areaCercaPuntiClassificaSquadra,3,FALSE),-1)=IFERROR(VLOOKUP($AA15,areaCercaPuntiClassificaSquadra,3,FALSE),-2)),SUMIFS(Dati!$F$2:$F$451,Dati!$A$2:$A$451,$H15,Dati!$H$2:$H$451,$AA15)+SUMIFS(Dati!$M$2:$M$451,Dati!$H$2:$H$451,$H15,Dati!$A$2:$A$451,$AA15),"-") | BX15: =IF(AND($H15<>"",$AB15<>"",$H15<>$AB15,IFERROR(VLOOKUP($H15,areaCercaPuntiClassificaSquadra,3,FALSE),-1)=IFERROR(VLOOKUP($AB15,areaCercaPuntiClassificaSquadra,3,FALSE),-2)),SUMIFS(Dati!$F$2:$F$451,Dati!$A$2:$A$451,$H15,Dati!$H$2:$H$451,$AB15)+SUMIFS(Dati!$M$2:$M$451,Dati!$H$2:$H$451,$H15,Dati!$A$2:$A$451,$AB15),"-") | BY15: =IF(AND($H15<>"",$AC15<>"",$H15<>$AC15,IFERROR(VLOOKUP($H15,areaCercaPuntiClassificaSquadra,3,FALSE),-1)=IFERROR(VLOOKUP($AC15,areaCercaPuntiClassificaSquadra,3,FALSE),-2)),SUMIFS(Dati!$F$2:$F$451,Dati!$A$2:$A$451,$H15,Dati!$H$2:$H$451,$AC15)+SUMIFS(Dati!$M$2:$M$451,Dati!$H$2:$H$451,$H15,Dati!$A$2:$A$451,$AC15),"-") | BZ15: =IF(AND($H15<>"",$AD15<>"",$H15<>$AD15,IFERROR(VLOOKUP($H15,areaCercaPuntiClassificaSquadra,3,FALSE),-1)=IFERROR(VLOOKUP($AD15,areaCercaPuntiClassificaSquadra,3,FALSE),-2)),SUMIFS(Dati!$F$2:$F$451,Dati!$A$2:$A$451,$H15,Dati!$H$2:$H$451,$AD15)+SUMIFS(Dati!$M$2:$M$451,Dati!$H$2:$H$451,$H15,Dati!$A$2:$A$451,$AD15),"-") | CA15: =IF(AND($H15<>"",$AE15<>"",$H15<>$AE15,IFERROR(VLOOKUP($H15,areaCercaPuntiClassificaSquadra,3,FALSE),-1)=IFERROR(VLOOKUP($AE15,areaCercaPuntiClassificaSquadra,3,FALSE),-2)),SUMIFS(Dati!$F$2:$F$451,Dati!$A$2:$A$451,$H15,Dati!$H$2:$H$451,$AE15)+SUMIFS(Dati!$M$2:$M$451,Dati!$H$2:$H$451,$H15,Dati!$A$2:$A$451,$AE15),"-") | CB15: =IF(AND($H15<>"",$AF15<>"",$H15<>$AF15,IFERROR(VLOOKUP($H15,areaCercaPuntiClassificaSquadra,3,FALSE),-1)=IFERROR(VLOOKUP($AF15,areaCercaPuntiClassificaSquadra,3,FALSE),-2)),SUMIFS(Dati!$F$2:$F$451,Dati!$A$2:$A$451,$H15,Dati!$H$2:$H$451,$AF15)+SUMIFS(Dati!$M$2:$M$451,Dati!$H$2:$H$451,$H15,Dati!$A$2:$A$451,$AF15),"-") | CC15: =IF(AND($H15<>"",$AG15<>"",$H15<>$AG15,IFERROR(VLOOKUP($H15,areaCercaPuntiClassificaSquadra,3,FALSE),-1)=IFERROR(VLOOKUP($AG15,areaCercaPuntiClassificaSquadra,3,FALSE),-2)),SUMIFS(Dati!$F$2:$F$451,Dati!$A$2:$A$451,$H15,Dati!$H$2:$H$451,$AG15)+SUMIFS(Dati!$M$2:$M$451,Dati!$H$2:$H$451,$H15,Dati!$A$2:$A$451,$AG15),"-") | CD15: =IF(AND($H15<>"",$AH15<>"",$H15<>$AH15,IFERROR(VLOOKUP($H15,areaCercaPuntiClassificaSquadra,3,FALSE),-1)=IFERROR(VLOOKUP($AH15,areaCercaPuntiClassificaSquadra,3,FALSE),-2)),SUMIFS(Dati!$F$2:$F$451,Dati!$A$2:$A$451,$H15,Dati!$H$2:$H$451,$AH15)+SUMIFS(Dati!$M$2:$M$451,Dati!$H$2:$H$451,$H15,Dati!$A$2:$A$451,$AH15),"-") | CF15: =IF($C15="","",SUM(AK15:AT15))
B16: A03 | E16: A | G16: =IF($C16="","",$E16&(COUNTIFS(I$14:I$113,">"&I16,E$14:E$113,"="&E16,C$14:C$113,"<>")+COUNTIFS(I$14:I$113,"="&I16,H$14:H$113,"<="&H16,E$14:E$113,"="&E16,C$14:C$113,"<>"))) | H16: =IF($C16="","",IFERROR(LEFT($C16,FIND("-",$C16)-1),$C16)) | I16: =TEXT(1000000000+J16,"|0000000000|")&TEXT(SUM(AK16:AT16),"0000000000|")&IF(SUM(BU16:CD16)=0,"0000000000|",TEXT(ROUND(SUM(BI16:BR16)/SUM(BU16:CD16),4)*100000,"0000000000|"))&IF(P16=0,"0000000000|",TEXT(ROUND(O16/P16,4)*100000,"0000000000|")) | J16: =L16*constPuntiVittoria+M16*constPuntiSconfitta+N16*constPuntiForfait+IF(D16="",0,D16) | K16: =SUM(L16:N16) | L16: =IF($H16="",0,SUMIF(Dati!$A$2:$A$451,$H16,Dati!$B$2:$B$451)+SUMIF(Dati!$H$2:$H$451,$H16,Dati!$I$2:$I$451)) | M16: =IF($H16="",0,SUMIF(Dati!$A$2:$A$451,$H16,Dati!$D$2:$D$451)+SUMIF(Dati!$H$2:$H$451,$H16,Dati!$K$2:$K$451)) | N16: =IF($H16="",0,SUMIF(Dati!$A$2:$A$451,$H16,Dati!$C$2:$C$451)+SUMIF(Dati!$H$2:$H$451,$H16,Dati!$J$2:$J$451)) | O16: =IF($H16="",0,SUMIF(Dati!$A$2:$A$451,$H16,Dati!$E$2:$E$451)+SUMIF(Dati!$H$2:$H$451,$H16,Dati!$L$2:$L$451)) | P16: =IF($H16="",0,SUMIF(Dati!$A$2:$A$451,$H16,Dati!$F$2:$F$451)+SUMIF(Dati!$H$2:$H$451,$H16,Dati!$M$2:$M$451)) | Q16: =IF($H16="",0,SUMIF(Dati!$A$2:$A$451,$H16,Dati!$G$2:$G$451)+SUMIF(Dati!$H$2:$H$451,$H16,Dati!$N$2:$N$451)) | R16: =IF(K16=0,0,ROUND(O16/K16,2)) | S16: =IF(K16=0,0,ROUND(P16/K16,2)) | T16: =IF(K16=0,0,ROUND(Q16/K16,2)) | U16: =IF(COUNTIFS($E$14:$E$113,$E16,$J$14:$J$113,$J16,$C$14:$C$113,"<>")<=1,"-",SUM(AK16:AT16)&"-"&SUM(AW16:BF16)) | V16: =IF(COUNTIFS($E$14:$E$113,$E16,$J$14:$J$113,$J16,$C$14:$C$113,"<>",$CF$14:$CF$113,$CF16)<=1,"-",IF(SUM(BU16:CD16)=0,0,ROUND(SUM(BI16:BR16)/SUM(BU16:CD16),3))) | W16: =IF(COUNTIFS($E$14:$E$113,$E16,$J$14:$J$113,$J16,$C$14:$C$113,"<>",$CF$14:$CF$113,$CF16,$V$14:$V$113,$V16)<=1,"-",IF(P16=0,0,ROUND(O16/P16,3))) | X16: =IF($C16="","",$E16&"#"&COUNTIFS($E$14:$E16,$E16,$C$14:$C16,"<>")) | Y16: =IFERROR(INDEX($H$14:$H$113,MATCH($E16&"#1",$X$14:$X$113,0)),"") | Z16: =IFERROR(INDEX($H$14:$H$113,MATCH($E16&"#2",$X$14:$X$113,0)),"") | AA16: =IFERROR(INDEX($H$14:$H$113,MATCH($E16&"#3",$X$14:$X$113,0)),"") | AB16: =IFERROR(INDEX($H$14:$H$113,MATCH($E16&"#4",$X$14:$X$113,0)),"") | AC16: =IFERROR(INDEX($H$14:$H$113,MATCH($E16&"#5",$X$14:$X$113,0)),"") | AD16: =IFERROR(INDEX($H$14:$H$113,MATCH($E16&"#6",$X$14:$X$113,0)),"") | AE16: =IFERROR(INDEX($H$14:$H$113,MATCH($E16&"#7",$X$14:$X$113,0)),"") | AF16: =IFERROR(INDEX($H$14:$H$113,MATCH($E16&"#8",$X$14:$X$113,0)),"") | AG16: =IFERROR(INDEX($H$14:$H$113,MATCH($E16&"#9",$X$14:$X$113,0)),"") | AH16: =IFERROR(INDEX($H$14:$H$113,MATCH($E16&"#10",$X$14:$X$113,0)),"") | AJ16: =$C16 | AK16: =IF(AND($H16<>"",$Y16<>"",$H16<>$Y16,IFERROR(VLOOKUP($H16,areaCercaPuntiClassificaSquadra,3,FALSE),-1)=IFERROR(VLOOKUP($Y16,areaCercaPuntiClassificaSquadra,3,FALSE),-2)),SUMIFS(Dati!$B$2:$B$451,Dati!$A$2:$A$451,$H16,Dati!$H$2:$H$451,$Y16)+SUMIFS(Dati!$I$2:$I$451,Dati!$H$2:$H$451,$H16,Dati!$A$2:$A$451,$Y16),"-") | AL16: =IF(AND($H16<>"",$Z16<>"",$H16<>$Z16,IFERROR(VLOOKUP($H16,areaCercaPuntiClassificaSquadra,3,FALSE),-1)=IFERROR(VLOOKUP($Z16,areaCercaPuntiClassificaSquadra,3,FALSE),-2)),SUMIFS(Dati!$B$2:$B$451,Dati!$A$2:$A$451,$H16,Dati!$H$2:$H$451,$Z16)+SUMIFS(Dati!$I$2:$I$451,Dati!$H$2:$H$451,$H16,Dati!$A$2:$A$451,$Z16),"-") | AM16: =IF(AND($H16<>"",$AA16<>"",$H16<>$AA16,IFERROR(VLOOKUP($H16,areaCercaPuntiClassificaSquadra,3,FALSE),-1)=IFERROR(VLOOKUP($AA16,areaCercaPuntiClassificaSquadra,3,FALSE),-2)),SUMIFS(Dati!$B$2:$B$451,Dati!$A$2:$A$451,$H16,Dati!$H$2:$H$451,$AA16)+SUMIFS(Dati!$I$2:$I$451,Dati!$H$2:$H$451,$H16,Dati!$A$2:$A$451,$AA16),"-") | AN16: =IF(AND($H16<>"",$AB16<>"",$H16<>$AB16,IFERROR(VLOOKUP($H16,areaCercaPuntiClassificaSquadra,3,FALSE),-1)=IFERROR(VLOOKUP($AB16,areaCercaPuntiClassificaSquadra,3,FALSE),-2)),SUMIFS(Dati!$B$2:$B$451,Dati!$A$2:$A$451,$H16,Dati!$H$2:$H$451,$AB16)+SUMIFS(Dati!$I$2:$I$451,Dati!$H$2:$H$451,$H16,Dati!$A$2:$A$451,$AB16),"-") | AO16: =IF(AND($H16<>"",$AC16<>"",$H16<>$AC16,IFERROR(VLOOKUP($H16,areaCercaPuntiClassificaSquadra,3,FALSE),-1)=IFERROR(VLOOKUP($AC16,areaCercaPuntiClassificaSquadra,3,FALSE),-2)),SUMIFS(Dati!$B$2:$B$451,Dati!$A$2:$A$451,$H16,Dati!$H$2:$H$451,$AC16)+SUMIFS(Dati!$I$2:$I$451,Dati!$H$2:$H$451,$H16,Dati!$A$2:$A$451,$AC16),"-") | AP16: =IF(AND($H16<>"",$AD16<>"",$H16<>$AD16,IFERROR(VLOOKUP($H16,areaCercaPuntiClassificaSquadra,3,FALSE),-1)=IFERROR(VLOOKUP($AD16,areaCercaPuntiClassificaSquadra,3,FALSE),-2)),SUMIFS(Dati!$B$2:$B$451,Dati!$A$2:$A$451,$H16,Dati!$H$2:$H$451,$AD16)+SUMIFS(Dati!$I$2:$I$451,Dati!$H$2:$H$451,$H16,Dati!$A$2:$A$451,$AD16),"-") | AQ16: =IF(AND($H16<>"",$AE16<>"",$H16<>$AE16,IFERROR(VLOOKUP($H16,areaCercaPuntiClassificaSquadra,3,FALSE),-1)=IFERROR(VLOOKUP($AE16,areaCercaPuntiClassificaSquadra,3,FALSE),-2)),SUMIFS(Dati!$B$2:$B$451,Dati!$A$2:$A$451,$H16,Dati!$H$2:$H$451,$AE16)+SUMIFS(Dati!$I$2:$I$451,Dati!$H$2:$H$451,$H16,Dati!$A$2:$A$451,$AE16),"-") | AR16: =IF(AND($H16<>"",$AF16<>"",$H16<>$AF16,IFERROR(VLOOKUP($H16,areaCercaPuntiClassificaSquadra,3,FALSE),-1)=IFERROR(VLOOKUP($AF16,areaCercaPuntiClassificaSquadra,3,FALSE),-2)),SUMIFS(Dati!$B$2:$B$451,Dati!$A$2:$A$451,$H16,Dati!$H$2:$H$451,$AF16)+SUMIFS(Dati!$I$2:$I$451,Dati!$H$2:$H$451,$H16,Dati!$A$2:$A$451,$AF16),"-") | AS16: =IF(AND($H16<>"",$AG16<>"",$H16<>$AG16,IFERROR(VLOOKUP($H16,areaCercaPuntiClassificaSquadra,3,FALSE),-1)=IFERROR(VLOOKUP($AG16,areaCercaPuntiClassificaSquadra,3,FALSE),-2)),SUMIFS(Dati!$B$2:$B$451,Dati!$A$2:$A$451,$H16,Dati!$H$2:$H$451,$AG16)+SUMIFS(Dati!$I$2:$I$451,Dati!$H$2:$H$451,$H16,Dati!$A$2:$A$451,$AG16),"-") | AT16: =IF(AND($H16<>"",$AH16<>"",$H16<>$AH16,IFERROR(VLOOKUP($H16,areaCercaPuntiClassificaSquadra,3,FALSE),-1)=IFERROR(VLOOKUP($AH16,areaCercaPuntiClassificaSquadra,3,FALSE),-2)),SUMIFS(Dati!$B$2:$B$451,Dati!$A$2:$A$451,$H16,Dati!$H$2:$H$451,$AH16)+SUMIFS(Dati!$I$2:$I$451,Dati!$H$2:$H$451,$H16,Dati!$A$2:$A$451,$AH16),"-") | AV16: =$C16 | AW16: =IF(AND($H16<>"",$Y16<>"",$H16<>$Y16,IFERROR(VLOOKUP($H16,areaCercaPuntiClassificaSquadra,3,FALSE),-1)=IFERROR(VLOOKUP($Y16,areaCercaPuntiClassificaSquadra,3,FALSE),-2)),SUMIFS(Dati!$D$2:$D$451,Dati!$A$2:$A$451,$H16,Dati!$H$2:$H$451,$Y16)+SUMIFS(Dati!$K$2:$K$451,Dati!$H$2:$H$451,$H16,Dati!$A$2:$A$451,$Y16)+SUMIFS(Dati!$C$2:$C$451,Dati!$A$2:$A$451,$H16,Dati!$H$2:$H$451,$Y16)+SUMIFS(Dati!$J$2:$J$451,Dati!$H$2:$H$451,$H16,Dati!$A$2:$A$451,$Y16),"-") | AX16: =IF(AND($H16<>"",$Z16<>"",$H16<>$Z16,IFERROR(VLOOKUP($H16,areaCercaPuntiClassificaSquadra,3,FALSE),-1)=IFERROR(VLOOKUP($Z16,areaCercaPuntiClassificaSquadra,3,FALSE),-2)),SUMIFS(Dati!$D$2:$D$451,Dati!$A$2:$A$451,$H16,Dati!$H$2:$H$451,$Z16)+SUMIFS(Dati!$K$2:$K$451,Dati!$H$2:$H$451,$H16,Dati!$A$2:$A$451,$Z16)+SUMIFS(Dati!$C$2:$C$451,Dati!$A$2:$A$451,$H16,Dati!$H$2:$H$451,$Z16)+SUMIFS(Dati!$J$2:$J$451,Dati!$H$2:$H$451,$H16,Dati!$A$2:$A$451,$Z16),"-") | AY16: =IF(AND($H16<>"",$AA16<>"",$H16<>$AA16,IFERROR(VLOOKUP($H16,areaCercaPuntiClassificaSquadra,3,FALSE),-1)=IFERROR(VLOOKUP($AA16,areaCercaPuntiClassificaSquadra,3,FALSE),-2)),SUMIFS(Dati!$D$2:$D$451,Dati!$A$2:$A$451,$H16,Dati!$H$2:$H$451,$AA16)+SUMIFS(Dati!$K$2:$K$451,Dati!$H$2:$H$451,$H16,Dati!$A$2:$A$451,$AA16)+SUMIFS(Dati!$C$2:$C$451,Dati!$A$2:$A$451,$H16,Dati!$H$2:$H$451,$AA16)+SUMIFS(Dati!$J$2:$J$451,Dati!$H$2:$H$451,$H16,Dati!$A$2:$A$451,$AA16),"-") | AZ16: =IF(AND($H16<>"",$AB16<>"",$H16<>$AB16,IFERROR(VLOOKUP($H16,areaCercaPuntiClassificaSquadra,3,FALSE),-1)=IFERROR(VLOOKUP($AB16,areaCercaPuntiClassificaSquadra,3,FALSE),-2)),SUMIFS(Dati!$D$2:$D$451,Dati!$A$2:$A$451,$H16,Dati!$H$2:$H$451,$AB16)+SUMIFS(Dati!$K$2:$K$451,Dati!$H$2:$H$451,$H16,Dati!$A$2:$A$451,$AB16)+SUMIFS(Dati!$C$2:$C$451,Dati!$A$2:$A$451,$H16,Dati!$H$2:$H$451,$AB16)+SUMIFS(Dati!$J$2:$J$451,Dati!$H$2:$H$451,$H16,Dati!$A$2:$A$451,$AB16),"-") | BA16: =IF(AND($H16<>"",$AC16<>"",$H16<>$AC16,IFERROR(VLOOKUP($H16,areaCercaPuntiClassificaSquadra,3,FALSE),-1)=IFERROR(VLOOKUP($AC16,areaCercaPuntiClassificaSquadra,3,FALSE),-2)),SUMIFS(Dati!$D$2:$D$451,Dati!$A$2:$A$451,$H16,Dati!$H$2:$H$451,$AC16)+SUMIFS(Dati!$K$2:$K$451,Dati!$H$2:$H$451,$H16,Dati!$A$2:$A$451,$AC16)+SUMIFS(Dati!$C$2:$C$451,Dati!$A$2:$A$451,$H16,Dati!$H$2:$H$451,$AC16)+SUMIFS(Dati!$J$2:$J$451,Dati!$H$2:$H$451,$H16,Dati!$A$2:$A$451,$AC16),"-") | BB16: =IF(AND($H16<>"",$AD16<>"",$H16<>$AD16,IFERROR(VLOOKUP($H16,areaCercaPuntiClassificaSquadra,3,FALSE),-1)=IFERROR(VLOOKUP($AD16,areaCercaPuntiClassificaSquadra,3,FALSE),-2)),SUMIFS(Dati!$D$2:$D$451,Dati!$A$2:$A$451,$H16,Dati!$H$2:$H$451,$AD16)+SUMIFS(Dati!$K$2:$K$451,Dati!$H$2:$H$451,$H16,Dati!$A$2:$A$451,$AD16)+SUMIFS(Dati!$C$2:$C$451,Dati!$A$2:$A$451,$H16,Dati!$H$2:$H$451,$AD16)+SUMIFS(Dati!$J$2:$J$451,Dati!$H$2:$H$451,$H16,Dati!$A$2:$A$451,$AD16),"-") | BC16: =IF(AND($H16<>"",$AE16<>"",$H16<>$AE16,IFERROR(VLOOKUP($H16,areaCercaPuntiClassificaSquadra,3,FALSE),-1)=IFERROR(VLOOKUP($AE16,areaCercaPuntiClassificaSquadra,3,FALSE),-2)),SUMIFS(Dati!$D$2:$D$451,Dati!$A$2:$A$451,$H16,Dati!$H$2:$H$451,$AE16)+SUMIFS(Dati!$K$2:$K$451,Dati!$H$2:$H$451,$H16,Dati!$A$2:$A$451,$AE16)+SUMIFS(Dati!$C$2:$C$451,Dati!$A$2:$A$451,$H16,Dati!$H$2:$H$451,$AE16)+SUMIFS(Dati!$J$2:$J$451,Dati!$H$2:$H$451,$H16,Dati!$A$2:$A$451,$AE16),"-") | BD16: =IF(AND($H16<>"",$AF16<>"",$H16<>$AF16,IFERROR(VLOOKUP($H16,areaCercaPuntiClassificaSquadra,3,FALSE),-1)=IFERROR(VLOOKUP($AF16,areaCercaPuntiClassificaSquadra,3,FALSE),-2)),SUMIFS(Dati!$D$2:$D$451,Dati!$A$2:$A$451,$H16,Dati!$H$2:$H$451,$AF16)+SUMIFS(Dati!$K$2:$K$451,Dati!$H$2:$H$451,$H16,Dati!$A$2:$A$451,$AF16)+SUMIFS(Dati!$C$2:$C$451,Dati!$A$2:$A$451,$H16,Dati!$H$2:$H$451,$AF16)+SUMIFS(Dati!$J$2:$J$451,Dati!$H$2:$H$451,$H16,Dati!$A$2:$A$451,$AF16),"-") | BE16: =IF(AND($H16<>"",$AG16<>"",$H16<>$AG16,IFERROR(VLOOKUP($H16,areaCercaPuntiClassificaSquadra,3,FALSE),-1)=IFERROR(VLOOKUP($AG16,areaCercaPuntiClassificaSquadra,3,FALSE),-2)),SUMIFS(Dati!$D$2:$D$451,Dati!$A$2:$A$451,$H16,Dati!$H$2:$H$451,$AG16)+SUMIFS(Dati!$K$2:$K$451,Dati!$H$2:$H$451,$H16,Dati!$A$2:$A$451,$AG16)+SUMIFS(Dati!$C$2:$C$451,Dati!$A$2:$A$451,$H16,Dati!$H$2:$H$451,$AG16)+SUMIFS(Dati!$J$2:$J$451,Dati!$H$2:$H$451,$H16,Dati!$A$2:$A$451,$AG16),"-") | BF16: =IF(AND($H16<>"",$AH16<>"",$H16<>$AH16,IFERROR(VLOOKUP($H16,areaCercaPuntiClassificaSquadra,3,FALSE),-1)=IFERROR(VLOOKUP($AH16,areaCercaPuntiClassificaSquadra,3,FALSE),-2)),SUMIFS(Dati!$D$2:$D$451,Dati!$A$2:$A$451,$H16,Dati!$H$2:$H$451,$AH16)+SUMIFS(Dati!$K$2:$K$451,Dati!$H$2:$H$451,$H16,Dati!$A$2:$A$451,$AH16)+SUMIFS(Dati!$C$2:$C$451,Dati!$A$2:$A$451,$H16,Dati!$H$2:$H$451,$AH16)+SUMIFS(Dati!$J$2:$J$451,Dati!$H$2:$H$451,$H16,Dati!$A$2:$A$451,$AH16),"-") | BH16: =$C16 | BI16: =IF(AND($H16<>"",$Y16<>"",$H16<>$Y16,IFERROR(VLOOKUP($H16,areaCercaPuntiClassificaSquadra,3,FALSE),-1)=IFERROR(VLOOKUP($Y16,areaCercaPuntiClassificaSquadra,3,FALSE),-2)),SUMIFS(Dati!$E$2:$E$451,Dati!$A$2:$A$451,$H16,Dati!$H$2:$H$451,$Y16)+SUMIFS(Dati!$L$2:$L$451,Dati!$H$2:$H$451,$H16,Dati!$A$2:$A$451,$Y16),"-") | BJ16: =IF(AND($H16<>"",$Z16<>"",$H16<>$Z16,IFERROR(VLOOKUP($H16,areaCercaPuntiClassificaSquadra,3,FALSE),-1)=IFERROR(VLOOKUP($Z16,areaCercaPuntiClassificaSquadra,3,FALSE),-2)),SUMIFS(Dati!$E$2:$E$451,Dati!$A$2:$A$451,$H16,Dati!$H$2:$H$451,$Z16)+SUMIFS(Dati!$L$2:$L$451,Dati!$H$2:$H$451,$H16,Dati!$A$2:$A$451,$Z16),"-") | BK16: =IF(AND($H16<>"",$AA16<>"",$H16<>$AA16,IFERROR(VLOOKUP($H16,areaCercaPuntiClassificaSquadra,3,FALSE),-1)=IFERROR(VLOOKUP($AA16,areaCercaPuntiClassificaSquadra,3,FALSE),-2)),SUMIFS(Dati!$E$2:$E$451,Dati!$A$2:$A$451,$H16,Dati!$H$2:$H$451,$AA16)+SUMIFS(Dati!$L$2:$L$451,Dati!$H$2:$H$451,$H16,Dati!$A$2:$A$451,$AA16),"-") | BL16: =IF(AND($H16<>"",$AB16<>"",$H16<>$AB16,IFERROR(VLOOKUP($H16,areaCercaPuntiClassificaSquadra,3,FALSE),-1)=IFERROR(VLOOKUP($AB16,areaCercaPuntiClassificaSquadra,3,FALSE),-2)),SUMIFS(Dati!$E$2:$E$451,Dati!$A$2:$A$451,$H16,Dati!$H$2:$H$451,$AB16)+SUMIFS(Dati!$L$2:$L$451,Dati!$H$2:$H$451,$H16,Dati!$A$2:$A$451,$AB16),"-") | BM16: =IF(AND($H16<>"",$AC16<>"",$H16<>$AC16,IFERROR(VLOOKUP($H16,areaCercaPuntiClassificaSquadra,3,FALSE),-1)=IFERROR(VLOOKUP($AC16,areaCercaPuntiClassificaSquadra,3,FALSE),-2)),SUMIFS(Dati!$E$2:$E$451,Dati!$A$2:$A$451,$H16,Dati!$H$2:$H$451,$AC16)+SUMIFS(Dati!$L$2:$L$451,Dati!$H$2:$H$451,$H16,Dati!$A$2:$A$451,$AC16),"-") | BN16: =IF(AND($H16<>"",$AD16<>"",$H16<>$AD16,IFERROR(VLOOKUP($H16,areaCercaPuntiClassificaSquadra,3,FALSE),-1)=IFERROR(VLOOKUP($AD16,areaCercaPuntiClassificaSquadra,3,FALSE),-2)),SUMIFS(Dati!$E$2:$E$451,Dati!$A$2:$A$451,$H16,Dati!$H$2:$H$451,$AD16)+SUMIFS(Dati!$L$2:$L$451,Dati!$H$2:$H$451,$H16,Dati!$A$2:$A$451,$AD16),"-") | BO16: =IF(AND($H16<>"",$AE16<>"",$H16<>$AE16,IFERROR(VLOOKUP($H16,areaCercaPuntiClassificaSquadra,3,FALSE),-1)=IFERROR(VLOOKUP($AE16,areaCercaPuntiClassificaSquadra,3,FALSE),-2)),SUMIFS(Dati!$E$2:$E$451,Dati!$A$2:$A$451,$H16,Dati!$H$2:$H$451,$AE16)+SUMIFS(Dati!$L$2:$L$451,Dati!$H$2:$H$451,$H16,Dati!$A$2:$A$451,$AE16),"-") | BP16: =IF(AND($H16<>"",$AF16<>"",$H16<>$AF16,IFERROR(VLOOKUP($H16,areaCercaPuntiClassificaSquadra,3,FALSE),-1)=IFERROR(VLOOKUP($AF16,areaCercaPuntiClassificaSquadra,3,FALSE),-2)),SUMIFS(Dati!$E$2:$E$451,Dati!$A$2:$A$451,$H16,Dati!$H$2:$H$451,$AF16)+SUMIFS(Dati!$L$2:$L$451,Dati!$H$2:$H$451,$H16,Dati!$A$2:$A$451,$AF16),"-") | BQ16: =IF(AND($H16<>"",$AG16<>"",$H16<>$AG16,IFERROR(VLOOKUP($H16,areaCercaPuntiClassificaSquadra,3,FALSE),-1)=IFERROR(VLOOKUP($AG16,areaCercaPuntiClassificaSquadra,3,FALSE),-2)),SUMIFS(Dati!$E$2:$E$451,Dati!$A$2:$A$451,$H16,Dati!$H$2:$H$451,$AG16)+SUMIFS(Dati!$L$2:$L$451,Dati!$H$2:$H$451,$H16,Dati!$A$2:$A$451,$AG16),"-") | BR16: =IF(AND($H16<>"",$AH16<>"",$H16<>$AH16,IFERROR(VLOOKUP($H16,areaCercaPuntiClassificaSquadra,3,FALSE),-1)=IFERROR(VLOOKUP($AH16,areaCercaPuntiClassificaSquadra,3,FALSE),-2)),SUMIFS(Dati!$E$2:$E$451,Dati!$A$2:$A$451,$H16,Dati!$H$2:$H$451,$AH16)+SUMIFS(Dati!$L$2:$L$451,Dati!$H$2:$H$451,$H16,Dati!$A$2:$A$451,$AH16),"-") | BT16: =$C16 | BU16: =IF(AND($H16<>"",$Y16<>"",$H16<>$Y16,IFERROR(VLOOKUP($H16,areaCercaPuntiClassificaSquadra,3,FALSE),-1)=IFERROR(VLOOKUP($Y16,areaCercaPuntiClassificaSquadra,3,FALSE),-2)),SUMIFS(Dati!$F$2:$F$451,Dati!$A$2:$A$451,$H16,Dati!$H$2:$H$451,$Y16)+SUMIFS(Dati!$M$2:$M$451,Dati!$H$2:$H$451,$H16,Dati!$A$2:$A$451,$Y16),"-") | BV16: =IF(AND($H16<>"",$Z16<>"",$H16<>$Z16,IFERROR(VLOOKUP($H16,areaCercaPuntiClassificaSquadra,3,FALSE),-1)=IFERROR(VLOOKUP($Z16,areaCercaPuntiClassificaSquadra,3,FALSE),-2)),SUMIFS(Dati!$F$2:$F$451,Dati!$A$2:$A$451,$H16,Dati!$H$2:$H$451,$Z16)+SUMIFS(Dati!$M$2:$M$451,Dati!$H$2:$H$451,$H16,Dati!$A$2:$A$451,$Z16),"-") | BW16: =IF(AND($H16<>"",$AA16<>"",$H16<>$AA16,IFERROR(VLOOKUP($H16,areaCercaPuntiClassificaSquadra,3,FALSE),-1)=IFERROR(VLOOKUP($AA16,areaCercaPuntiClassificaSquadra,3,FALSE),-2)),SUMIFS(Dati!$F$2:$F$451,Dati!$A$2:$A$451,$H16,Dati!$H$2:$H$451,$AA16)+SUMIFS(Dati!$M$2:$M$451,Dati!$H$2:$H$451,$H16,Dati!$A$2:$A$451,$AA16),"-") | BX16: =IF(AND($H16<>"",$AB16<>"",$H16<>$AB16,IFERROR(VLOOKUP($H16,areaCercaPuntiClassificaSquadra,3,FALSE),-1)=IFERROR(VLOOKUP($AB16,areaCercaPuntiClassificaSquadra,3,FALSE),-2)),SUMIFS(Dati!$F$2:$F$451,Dati!$A$2:$A$451,$H16,Dati!$H$2:$H$451,$AB16)+SUMIFS(Dati!$M$2:$M$451,Dati!$H$2:$H$451,$H16,Dati!$A$2:$A$451,$AB16),"-") | BY16: =IF(AND($H16<>"",$AC16<>"",$H16<>$AC16,IFERROR(VLOOKUP($H16,areaCercaPuntiClassificaSquadra,3,FALSE),-1)=IFERROR(VLOOKUP($AC16,areaCercaPuntiClassificaSquadra,3,FALSE),-2)),SUMIFS(Dati!$F$2:$F$451,Dati!$A$2:$A$451,$H16,Dati!$H$2:$H$451,$AC16)+SUMIFS(Dati!$M$2:$M$451,Dati!$H$2:$H$451,$H16,Dati!$A$2:$A$451,$AC16),"-") | BZ16: =IF(AND($H16<>"",$AD16<>"",$H16<>$AD16,IFERROR(VLOOKUP($H16,areaCercaPuntiClassificaSquadra,3,FALSE),-1)=IFERROR(VLOOKUP($AD16,areaCercaPuntiClassificaSquadra,3,FALSE),-2)),SUMIFS(Dati!$F$2:$F$451,Dati!$A$2:$A$451,$H16,Dati!$H$2:$H$451,$AD16)+SUMIFS(Dati!$M$2:$M$451,Dati!$H$2:$H$451,$H16,Dati!$A$2:$A$451,$AD16),"-") | CA16: =IF(AND($H16<>"",$AE16<>"",$H16<>$AE16,IFERROR(VLOOKUP($H16,areaCercaPuntiClassificaSquadra,3,FALSE),-1)=IFERROR(VLOOKUP($AE16,areaCercaPuntiClassificaSquadra,3,FALSE),-2)),SUMIFS(Dati!$F$2:$F$451,Dati!$A$2:$A$451,$H16,Dati!$H$2:$H$451,$AE16)+SUMIFS(Dati!$M$2:$M$451,Dati!$H$2:$H$451,$H16,Dati!$A$2:$A$451,$AE16),"-") | CB16: =IF(AND($H16<>"",$AF16<>"",$H16<>$AF16,IFERROR(VLOOKUP($H16,areaCercaPuntiClassificaSquadra,3,FALSE),-1)=IFERROR(VLOOKUP($AF16,areaCercaPuntiClassificaSquadra,3,FALSE),-2)),SUMIFS(Dati!$F$2:$F$451,Dati!$A$2:$A$451,$H16,Dati!$H$2:$H$451,$AF16)+SUMIFS(Dati!$M$2:$M$451,Dati!$H$2:$H$451,$H16,Dati!$A$2:$A$451,$AF16),"-") | CC16: =IF(AND($H16<>"",$AG16<>"",$H16<>$AG16,IFERROR(VLOOKUP($H16,areaCercaPuntiClassificaSquadra,3,FALSE),-1)=IFERROR(VLOOKUP($AG16,areaCercaPuntiClassificaSquadra,3,FALSE),-2)),SUMIFS(Dati!$F$2:$F$451,Dati!$A$2:$A$451,$H16,Dati!$H$2:$H$451,$AG16)+SUMIFS(Dati!$M$2:$M$451,Dati!$H$2:$H$451,$H16,Dati!$A$2:$A$451,$AG16),"-") | CD16: =IF(AND($H16<>"",$AH16<>"",$H16<>$AH16,IFERROR(VLOOKUP($H16,areaCercaPuntiClassificaSquadra,3,FALSE),-1)=IFERROR(VLOOKUP($AH16,areaCercaPuntiClassificaSquadra,3,FALSE),-2)),SUMIFS(Dati!$F$2:$F$451,Dati!$A$2:$A$451,$H16,Dati!$H$2:$H$451,$AH16)+SUMIFS(Dati!$M$2:$M$451,Dati!$H$2:$H$451,$H16,Dati!$A$2:$A$451,$AH16),"-") | CF16: =IF($C16="","",SUM(AK16:AT16))
