Workbook

Sheet Campionato
B1: PARAMETRI
B2: Campionato | D2: Campionato Baskin Demo - ESEMPIO 10 Squadre
B3: Link Logo 1
B4: Link Logo 2
B5: Gironi (separati da virgola) | D5: A
B6: Stagione | D6: 2026/2027
B7: Punti vittoria | D7: 3
B8: Punti sconfitta | D8: 1
B9: Punti forfait | D9: 0
B10: Punteggio forfait (vincente-perdente, separati da "-") | D10: 40-0
B11: Nomi gironi per la stampa (stesso ordine, separati da virgola) | D11: Gold
B12: SQUADRE | Y12: Squadre del girone (in ordine di inserimento) | AJ12: Squadra | AK12: Vittorie Scontri Diretti | AV12: Squadra | AW12: Sconfitte & Forfait Scontri Diretti | BH12: Squadra | BI12: Punti Fatti Scontri Diretti | BT12: Squadra | BU12: Punti Subiti Scontri Diretti
B13: # | C13: Squadra | D13: Eventuali Punti di Penalizzazione | E13: Girone | G13: Posizione | H13: Squadra | I13: Coefficiente | J13: Punti Classifica | K13: Partite Giocate | L13: Partite Vinte | M13: Partite Perse | N13: Partite Forfait | O13: Punti Fatti | P13: Punti Subiti | Q13: Differenza Punti | R13: Media Punti Fatti | S13: Media Punti Subiti | T13: Media Differenza Punti | U13: Record Scontri Diretti | V13: Quoziente Canestri Scontri Diretti | W13: Quoziente Canestri Totale | X13: Chiave girone | Y13: 1^ | Z13: 2^ | AA13: 3^ | AB13: 4^ | AC13: 5^ | AD13: 6^ | AE13: 7^ | AF13: 8^ | AG13: 9^ | AH13: 10^ | AJ13: Squadra | AK13: 1^ | AL13: 2^ | AM13: 3^ | AN13: 4^ | AO13: 5^ | AP13: 6^ | AQ13: 7^ | AR13: 8^ | AS13: 9^ | AT13: 10^ | AV13: Squadra | AW13: 1^ | AX13: 2^ | AY13: 3^ | AZ13: 4^ | BA13: 5^ | BB13: 6^ | BC13: 7^ | BD13: 8^ | BE13: 9^ | BF13: 10^ | BH13: Squadra | BI13: 1^ | BJ13: 2^ | BK13: 3^ | BL13: 4^ | BM13: 5^ | BN13: 6^ | BO13: 7^ | BP13: 8^ | BQ13: 9^ | BR13: 10^ | BT13: Squadra | BU13: 1^ | BV13: 2^ | BW13: 3^ | BX13: 4^ | BY13: 5^ | BZ13: 6^ | CA13: 7^ | CB13: 8^ | CC13: 9^ | CD13: 10^ | CF13: Vittorie SD
B14: A01 | C14: Anaconde Audaci-Anacondeopoli AA | E14: A | G14: =IF($C14="","",$E14&(COUNTIFS(I$14:I$23,">"&I14,E$14:E$23,"="&E14,C$14:C$23,"<>")+COUNTIFS(I$14:I$23,"="&I14,H$14:H$23,"<="&H14,E$14:E$23,"="&E14,C$14:C$23,"<>"))) -> A2 | H14: =IF($C14="","",IFERROR(LEFT($C14,FIND("-",$C14)-1),$C14)) -> Anaconde Audaci | I14: =TEXT(1000000000+J14,"|0000000000|")&TEXT(SUM(AK14:AT14),"0000000000|")&IF(SUM(BU14:CD14)=0,"0000000000|",TEXT(ROUND(SUM(BI14:BR14)/SUM(BU14:CD14),4)*100000,"0000000000|"))&IF(P14=0,"0000000000|",TEXT(ROUND(O14/P14,4)*100000,"0000000000|")) -> |1000000021|0000000001|0000119570|0000111580| | J14: =L14*Campionato!$D$7+M14*Campionato!$D$8+N14*Campionato!$D$9+IF(D14="",0,D14) -> 21 | K14: =SUM(L14:N14) -> 9 | L14: =IF($H14="",0,SUMIF(Dati!$A$2:$A$46,$H14,Dati!$B$2:$B$46)+SUMIF(Dati!$H$2:$H$46,$H14,Dati!$I$2:$I$46)) -> 6 | M14: =IF($H14="",0,SUMIF(Dati!$A$2:$A$46,$H14,Dati!$D$2:$D$46)+SUMIF(Dati!$H$2:$H$46,$H14,Dati!$K$2:$K$46)) -> 3 | N14: =IF($H14="",0,SUMIF(Dati!$A$2:$A$46,$H14,Dati!$C$2:$C$46)+SUMIF(Dati!$H$2:$H$46,$H14,Dati!$J$2:$J$46)) -> 0 | O14: =IF($H14="",0,SUMIF(Dati!$A$2:$A$46,$H14,Dati!$E$2:$E$46)+SUMIF(Dati!$H$2:$H$46,$H14,Dati!$L$2:$L$46)) -> 530 | P14: =IF($H14="",0,SUMIF(Dati!$A$2:$A$46,$H14,Dati!$F$2:$F$46)+SUMIF(Dati!$H$2:$H$46,$H14,Dati!$M$2:$M$46)) -> 475 | Q14: =IF($H14="",0,SUMIF(Dati!$A$2:$A$46,$H14,Dati!$G$2:$G$46)+SUMIF(Dati!$H$2:$H$46,$H14,Dati!$N$2:$N$46)) -> 55 | R14: =IF(K14=0,0,ROUND(O14/K14,2)) -> 58.89 | S14: =IF(K14=0,0,ROUND(P14/K14,2)) -> 52.78 | T14: =IF(K14=0,0,ROUND(Q14/K14,2)) -> 6.11 | U14: =IF(COUNTIFS($E$14:$E$23,$E14,$J$14:$J$23,$J14,$C$14:$C$23,"<>")<=1,"-",SUM(AK14:AT14)&"-"&SUM(AW14:BF14)) -> 1-1 | V14: =IF(COUNTIFS($E$14:$E$23,$E14,$J$14:$J$23,$J14,$C$14:$C$23,"<>",$CF$14:$CF$23,$CF14)<=1,"-",IF(SUM(BU14:CD14)=0,0,ROUND(SUM(BI14:BR14)/SUM(BU14:CD14),3))) -> 1.196 | W14: =IF(COUNTIFS($E$14:$E$23,$E14,$J$14:$J$23,$J14,$C$14:$C$23,"<>",$CF$14:$CF$23,$CF14,$V$14:$V$23,$V14)<=1,"-",IF(P14=0,0,ROUND(O14/P14,3))) -> - | X14: =IF($C14="","",$E14&"#"&COUNTIFS($E$14:$E14,$E14,$C$14:$C14,"<>")) -> A#1 | Y14: =IFERROR(INDEX($H$14:$H$23,MATCH($E14&"#1",$X$14:$X$23,0)),"") -> Anaconde Audaci | Z14: =IFERROR(INDEX($H$14:$H$23,MATCH($E14&"#2",$X$14:$X$23,0)),"") -> Bufali Belligeranti | AA14: =IFERROR(INDEX($H$14:$H$23,MATCH($E14&"#3",$X$14:$X$23,0)),"") -> Cobra Celeri | AB14: =IFERROR(INDEX($H$14:$H$23,MATCH($E14&"#4",$X$14:$X$23,0)),"") -> Dingo Docili | AC14: =IFERROR(INDEX($H$14:$H$23,MATCH($E14&"#5",$X$14:$X$23,0)),"") -> Ermellini Eleganti | AD14: =IFERROR(INDEX($H$14:$H$23,MATCH($E14&"#6",$X$14:$X$23,0)),"") -> Falchi Feroci | AE14: =IFERROR(INDEX($H$14:$H$23,MATCH($E14&"#7",$X$14:$X$23,0)),"") -> Gazzelle Gentili | AF14: =IFERROR(INDEX($H$14:$H$23,MATCH($E14&"#8",$X$14:$X$23,0)),"") -> Ibis Instancabili | AG14: =IFERROR(INDEX($H$14:$H$23,MATCH($E14&"#9",$X$14:$X$23,0)),"") -> Lupi Leali | AH14: =IFERROR(INDEX($H$14:$H$23,MATCH($E14&"#10",$X$14:$X$23,0)),"") -> Marmotte Mobili | AJ14: =$C14 -> Anaconde Audaci-Anacondeopoli AA | AK14: =IF(AND($H14<>"",$Y14<>"",$H14<>$Y14,IFERROR(INDEX($J$14:$J$23,MATCH($H14,$H$14:$H$23,0)),-1)=IFERROR(INDEX($J$14:$J$23,MATCH($Y14,$H$14:$H$23,0)),-2)),SUMIFS(Dati!$B$2:$B$46,Dati!$A$2:$A$46,$H14,Dati!$H$2:$H$46,$Y14)+SUMIFS(Dati!$I$2:$I$46,Dati!$H$2:$H$46,$H14,Dati!$A$2:$A$46,$Y14),"-") -> - | AL14: =IF(AND($H14<>"",$Z14<>"",$H14<>$Z14,IFERROR(INDEX($J$14:$J$23,MATCH($H14,$H$14:$H$23,0)),-1)=IFERROR(INDEX($J$14:$J$23,MATCH($Z14,$H$14:$H$23,0)),-2)),SUMIFS(Dati!$B$2:$B$46,Dati!$A$2:$A$46,$H14,Dati!$H$2:$H$46,$Z14)+SUMIFS(Dati!$I$2:$I$46,Dati!$H$2:$H$46,$H14,Dati!$A$2:$A$46,$Z14),"-") -> - | AM14: =IF(AND($H14<>"",$AA14<>"",$H14<>$AA14,IFERROR(INDEX($J$14:$J$23,MATCH($H14,$H$14:$H$23,0)),-1)=IFERROR(INDEX($J$14:$J$23,MATCH($AA14,$H$14:$H$23,0)),-2)),SUMIFS(Dati!$B$2:$B$46,Dati!$A$2:$A$46,$H14,Dati!$H$2:$H$46,$AA14)+SUMIFS(Dati!$I$2:$I$46,Dati!$H$2:$H$46,$H14,Dati!$A$2:$A$46,$AA14),"-") -> - | AN14: =IF(AND($H14<>"",$AB14<>"",$H14<>$AB14,IFERROR(INDEX($J$14:$J$23,MATCH($H14,$H$14:$H$23,0)),-1)=IFERROR(INDEX($J$14:$J$23,MATCH($AB14,$H$14:$H$23,0)),-2)),SUMIFS(Dati!$B$2:$B$46,Dati!$A$2:$A$46,$H14,Dati!$H$2:$H$46,$AB14)+SUMIFS(Dati!$I$2:$I$46,Dati!$H$2:$H$46,$H14,Dati!$A$2:$A$46,$AB14),"-") -> - | AO14: =IF(AND($H14<>"",$AC14<>"",$H14<>$AC14,IFERROR(INDEX($J$14:$J$23,MATCH($H14,$H$14:$H$23,0)),-1)=IFERROR(INDEX($J$14:$J$23,MATCH($AC14,$H$14:$H$23,0)),-2)),SUMIFS(Dati!$B$2:$B$46,Dati!$A$2:$A$46,$H14,Dati!$H$2:$H$46,$AC14)+SUMIFS(Dati!$I$2:$I$46,Dati!$H$2:$H$46,$H14,Dati!$A$2:$A$46,$AC14),"-") -> - | AP14: =IF(AND($H14<>"",$AD14<>"",$H14<>$AD14,IFERROR(INDEX($J$14:$J$23,MATCH($H14,$H$14:$H$23,0)),-1)=IFERROR(INDEX($J$14:$J$23,MATCH($AD14,$H$14:$H$23,0)),-2)),SUMIFS(Dati!$B$2:$B$46,Dati!$A$2:$A$46,$H14,Dati!$H$2:$H$46,$AD14)+SUMIFS(Dati!$I$2:$I$46,Dati!$H$2:$H$46,$H14,Dati!$A$2:$A$46,$AD14),"-") -> 1 | AQ14: =IF(AND($H14<>"",$AE14<>"",$H14<>$AE14,IFERROR(INDEX($J$14:$J$23,MATCH($H14,$H$14:$H$23,0)),-1)=IFERROR(INDEX($J$14:$J$23,MATCH($AE14,$H$14:$H$23,0)),-2)),SUMIFS(Dati!$B$2:$B$46,Dati!$A$2:$A$46,$H14,Dati!$H$2:$H$46,$AE14)+SUMIFS(Dati!$I$2:$I$46,Dati!$H$2:$H$46,$H14,Dati!$A$2:$A$46,$AE14),"-") -> - | AR14: =IF(AND($H14<>"",$AF14<>"",$H14<>$AF14,IFERROR(INDEX($J$14:$J$23,MATCH($H14,$H$14:$H$23,0)),-1)=IFERROR(INDEX($J$14:$J$23,MATCH($AF14,$H$14:$H$23,0)),-2)),SUMIFS(Dati!$B$2:$B$46,Dati!$A$2:$A$46,$H14,Dati!$H$2:$H$46,$AF14)+SUMIFS(Dati!$I$2:$I$46,Dati!$H$2:$H$46,$H14,Dati!$A$2:$A$46,$AF14),"-") -> - | AS14: =IF(AND($H14<>"",$AG14<>"",$H14<>$AG14,IFERROR(INDEX($J$14:$J$23,MATCH($H14,$H$14:$H$23,0)),-1)=IFERROR(INDEX($J$14:$J$23,MATCH($AG14,$H$14:$H$23,0)),-2)),SUMIFS(Dati!$B$2:$B$46,Dati!$A$2:$A$46,$H14,Dati!$H$2:$H$46,$AG14)+SUMIFS(Dati!$I$2:$I$46,Dati!$H$2:$H$46,$H14,Dati!$A$2:$A$46,$AG14),"-") -> 0 | AT14: =IF(AND($H14<>"",$AH14<>"",$H14<>$AH14,IFERROR(INDEX($J$14:$J$23,MATCH($H14,$H$14:$H$23,0)),-1)=IFERROR(INDEX($J$14:$J$23,MATCH($AH14,$H$14:$H$23,0)),-2)),SUMIFS(Dati!$B$2:$B$46,Dati!$A$2:$A$46,$H14,Dati!$H$2:$H$46,$AH14)+SUMIFS(Dati!$I$2:$I$46,Dati!$H$2:$H$46,$H14,Dati!$A$2:$A$46,$AH14),"-") -> - | AV14: =$C14 -> Anaconde Audaci-Anacondeopoli AA | AW14: =IF(AND($H14<>"",$Y14<>"",$H14<>$Y14,IFERROR(INDEX($J$14:$J$23,MATCH($H14,$H$14:$H$23,0)),-1)=IFERROR(INDEX($J$14:$J$23,MATCH($Y14,$H$14:$H$23,0)),-2)),SUMIFS(Dati!$D$2:$D$46,Dati!$A$2:$A$46,$H14,Dati!$H$2:$H$46,$Y14)+SUMIFS(Dati!$K$2:$K$46,Dati!$H$2:$H$46,$H14,Dati!$A$2:$A$46,$Y14)+SUMIFS(Dati!$C$2:$C$46,Dati!$A$2:$A$46,$H14,Dati!$H$2:$H$46,$Y14)+SUMIFS(Dati!$J$2:$J$46,Dati!$H$2:$H$46,$H14,Dati!$A$2:$A$46,$Y14),"-") -> - | AX14: =IF(AND($H14<>"",$Z14<>"",$H14<>$Z14,IFERROR(INDEX($J$14:$J$23,MATCH($H14,$H$14:$H$23,0)),-1)=IFERROR(INDEX($J$14:$J$23,MATCH($Z14,$H$14:$H$23,0)),-2)),SUMIFS(Dati!$D$2:$D$46,Dati!$A$2:$A$46,$H14,Dati!$H$2:$H$46,$Z14)+SUMIFS(Dati!$K$2:$K$46,Dati!$H$2:$H$46,$H14,Dati!$A$2:$A$46,$Z14)+SUMIFS(Dati!$C$2:$C$46,Dati!$A$2:$A$46,$H14,Dati!$H$2:$H$46,$Z14)+SUMIFS(Dati!$J$2:$J$46,Dati!$H$2:$H$46,$H14,Dati!$A$2:$A$46,$Z14),"-") -> - | AY14: =IF(AND($H14<>"",$AA14<>"",$H14<>$AA14,IFERROR(INDEX($J$14:$J$23,MATCH($H14,$H$14:$H$23,0)),-1)=IFERROR(INDEX($J$14:$J$23,MATCH($AA14,$H$14:$H$23,0)),-2)),SUMIFS(Dati!$D$2:$D$46,Dati!$A$2:$A$46,$H14,Dati!$H$2:$H$46,$AA14)+SUMIFS(Dati!$K$2:$K$46,Dati!$H$2:$H$46,$H14,Dati!$A$2:$A$46,$AA14)+SUMIFS(Dati!$C$2:$C$46,Dati!$A$2:$A$46,$H14,Dati!$H$2:$H$46,$AA14)+SUMIFS(Dati!$J$2:$J$46,Dati!$H$2:$H$46,$H14,Dati!$A$2:$A$46,$AA14),"-") -> - | AZ14: =IF(AND($H14<>"",$AB14<>"",$H14<>$AB14,IFERROR(INDEX($J$14:$J$23,MATCH($H14,$H$14:$H$23,0)),-1)=IFERROR(INDEX($J$14:$J$23,MATCH($AB14,$H$14:$H$23,0)),-2)),SUMIFS(Dati!$D$2:$D$46,Dati!$A$2:$A$46,$H14,Dati!$H$2:$H$46,$AB14)+SUMIFS(Dati!$K$2:$K$46,Dati!$H$2:$H$46,$H14,Dati!$A$2:$A$46,$AB14)+SUMIFS(Dati!$C$2:$C$46,Dati!$A$2:$A$46,$H14,Dati!$H$2:$H$46,$AB14)+SUMIFS(Dati!$J$2:$J$46,Dati!$H$2:$H$46,$H14,Dati!$A$2:$A$46,$AB14),"-") -> - | BA14: =IF(AND($H14<>"",$AC14<>"",$H14<>$AC14,IFERROR(INDEX($J$14:$J$23,MATCH($H14,$H$14:$H$23,0)),-1)=IFERROR(INDEX($J$14:$J$23,MATCH($AC14,$H$14:$H$23,0)),-2)),SUMIFS(Dati!$D$2:$D$46,Dati!$A$2:$A$46,$H14,Dati!$H$2:$H$46,$AC14)+SUMIFS(Dati!$K$2:$K$46,Dati!$H$2:$H$46,$H14,Dati!$A$2:$A$46,$AC14)+SUMIFS(Dati!$C$2:$C$46,Dati!$A$2:$A$46,$H14,Dati!$H$2:$H$46,$AC14)+SUMIFS(Dati!$J$2:$J$46,Dati!$H$2:$H$46,$H14,Dati!$A$2:$A$46,$AC14),"-") -> - | BB14: =IF(AND($H14<>"",$AD14<>"",$H14<>$AD14,IFERROR(INDEX($J$14:$J$23,MATCH($H14,$H$14:$H$23,0)),-1)=IFERROR(INDEX($J$14:$J$23,MATCH($AD14,$H$14:$H$23,0)),-2)),SUMIFS(Dati!$D$2:$D$46,Dati!$A$2:$A$46,$H14,Dati!$H$2:$H$46,$AD14)+SUMIFS(Dati!$K$2:$K$46,Dati!$H$2:$H$46,$H14,Dati!$A$2:$A$46,$AD14)+SUMIFS(Dati!$C$2:$C$46,Dati!$A$2:$A$46,$H14,Dati!$H$2:$H$46,$AD14)+SUMIFS(Dati!$J$2:$J$46,Dati!$H$2:$H$46,$H14,Dati!$A$2:$A$46,$AD14),"-") -> 0 | BC14: =IF(AND($H14<>"",$AE14<>"",$H14<>$AE14,IFERROR(INDEX($J$14:$J$23,MATCH($H14,$H$14:$H$23,0)),-1)=IFERROR(INDEX($J$14:$J$23,MATCH($AE14,$H$14:$H$23,0)),-2)),SUMIFS(Dati!$D$2:$D$46,Dati!$A$2:$A$46,$H14,Dati!$H$2:$H$46,$AE14)+SUMIFS(Dati!$K$2:$K$46,Dati!$H$2:$H$46,$H14,Dati!$A$2:$A$46,$AE14)+SUMIFS(Dati!$C$2:$C$46,Dati!$A$2:$A$46,$H14,Dati!$H$2:$H$46,$AE14)+SUMIFS(Dati!$J$2:$J$46,Dati!$H$2:$H$46,$H14,Dati!$A$2:$A$46,$AE14),"-") -> - | BD14: =IF(AND($H14<>"",$AF14<>"",$H14<>$AF14,IFERROR(INDEX($J$14:$J$23,MATCH($H14,$H$14:$H$23,0)),-1)=IFERROR(INDEX($J$14:$J$23,MATCH($AF14,$H$14:$H$23,0)),-2)),SUMIFS(Dati!$D$2:$D$46,Dati!$A$2:$A$46,$H14,Dati!$H$2:$H$46,$AF14)+SUMIFS(Dati!$K$2:$K$46,Dati!$H$2:$H$46,$H14,Dati!$A$2:$A$46,$AF14)+SUMIFS(Dati!$C$2:$C$46,Dati!$A$2:$A$46,$H14,Dati!$H$2:$H$46,$AF14)+SUMIFS(Dati!$J$2:$J$46,Dati!$H$2:$H$46,$H14,Dati!$A$2:$A$46,$AF14),"-") -> - | BE14: =IF(AND($H14<>"",$AG14<>"",$H14<>$AG14,IFERROR(INDEX($J$14:$J$23,MATCH($H14,$H$14:$H$23,0)),-1)=IFERROR(INDEX($J$14:$J$23,MATCH($AG14,$H$14:$H$23,0)),-2)),SUMIFS(Dati!$D$2:$D$46,Dati!$A$2:$A$46,$H14,Dati!$H$2:$H$46,$AG14)+SUMIFS(Dati!$K$2:$K$46,Dati!$H$2:$H$46,$H14,Dati!$A$2:$A$46,$AG14)+SUMIFS(Dati!$C$2:$C$46,Dati!$A$2:$A$46,$H14,Dati!$H$2:$H$46,$AG14)+SUMIFS(Dati!$J$2:$J$46,Dati!$H$2:$H$46,$H14,Dati!$A$2:$A$46,$AG14),"-") -> 1 | BF14: =IF(AND($H14<>"",$AH14<>"",$H14<>$AH14,IFERROR(INDEX($J$14:$J$23,MATCH($H14,$H$14:$H$23,0)),-1)=IFERROR(INDEX($J$14:$J$23,MATCH($AH14,$H$14:$H$23,0)),-2)),SUMIFS(Dati!$D$2:$D$46,Dati!$A$2:$A$46,$H14,Dati!$H$2:$H$46,$AH14)+SUMIFS(Dati!$K$2:$K$46,Dati!$H$2:$H$46,$H14,Dati!$A$2:$A$46,$AH14)+SUMIFS(Dati!$C$2:$C$46,Dati!$A$2:$A$46,$H14,Dati!$H$2:$H$46,$AH14)+SUMIFS(Dati!$J$2:$J$46,Dati!$H$2:$H$46,$H14,Dati!$A$2:$A$46,$AH14),"-") -> - | BH14: =$C14 -> Anaconde Audaci-Anacondeopoli AA | BI14: =IF(AND($H14<>"",$Y14<>"",$H14<>$Y14,IFERROR(INDEX($J$14:$J$23,MATCH($H14,$H$14:$H$23,0)),-1)=IFERROR(INDEX($J$14:$J$23,MATCH($Y14,$H$14:$H$23,0)),-2)),SUMIFS(Dati!$E$2:$E$46,Dati!$A$2:$A$46,$H14,Dati!$H$2:$H$46,$Y14)+SUMIFS(Dati!$L$2:$L$46,Dati!$H$2:$H$46,$H14,Dati!$A$2:$A$46,$Y14),"-") -> - | BJ14: =IF(AND($H14<>"",$Z14<>"",$H14<>$Z14,IFERROR(INDEX($J$14:$J$23,MATCH($H14,$H$14:$H$23,0)),-1)=IFERROR(INDEX($J$14:$J$23,MATCH($Z14,$H$14:$H$23,0)),-2)),SUMIFS(Dati!$E$2:$E$46,Dati!$A$2:$A$46,$H14,Dati!$H$2:$H$46,$Z14)+SUMIFS(Dati!$L$2:$L$46,Dati!$H$2:$H$46,$H14,Dati!$A$2:$A$46,$Z14),"-") -> - | BK14: =IF(AND($H14<>"",$AA14<>"",$H14<>$AA14,IFERROR(INDEX($J$14:$J$23,MATCH($H14,$H$14:$H$23,0)),-1)=IFERROR(INDEX($J$14:$J$23,MATCH($AA14,$H$14:$H$23,0)),-2)),SUMIFS(Dati!$E$2:$E$46,Dati!$A$2:$A$46,$H14,Dati!$H$2:$H$46,$AA14)+SUMIFS(Dati!$L$2:$L$46,Dati!$H$2:$H$46,$H14,Dati!$A$2:$A$46,$AA14),"-") -> - | BL14: =IF(AND($H14<>"",$AB14<>"",$H14<>$AB14,IFERROR(INDEX($J$14:$J$23,MATCH($H14,$H$14:$H$23,0)),-1)=IFERROR(INDEX($J$14:$J$23,MATCH($AB14,$H$14:$H$23,0)),-2)),SUMIFS(Dati!$E$2:$E$46,Dati!$A$2:$A$46,$H14,Dati!$H$2:$H$46,$AB14)+SUMIFS(Dati!$L$2:$L$46,Dati!$H$2:$H$46,$H14,Dati!$A$2:$A$46,$AB14),"-") -> - | BM14: =IF(AND($H14<>"",$AC14<>"",$H14<>$AC14,IFERROR(INDEX($J$14:$J$23,MATCH($H14,$H$14:$H$23,0)),-1)=IFERROR(INDEX($J$14:$J$23,MATCH($AC14,$H$14:$H$23,0)),-2)),SUMIFS(Dati!$E$2:$E$46,Dati!$A$2:$A$46,$H14,Dati!$H$2:$H$46,$AC14)+SUMIFS(Dati!$L$2:$L$46,Dati!$H$2:$H$46,$H14,Dati!$A$2:$A$46,$AC14),"-") -> - | BN14: =IF(AND($H14<>"",$AD14<>"",$H14<>$AD14,IFERROR(INDEX($J$14:$J$23,MATCH($H14,$H$14:$H$23,0)),-1)=IFERROR(INDEX($J$14:$J$23,MATCH($AD14,$H$14:$H$23,0)),-2)),SUMIFS(Dati!$E$2:$E$46,Dati!$A$2:$A$46,$H14,Dati!$H$2:$H$46,$AD14)+SUMIFS(Dati!$L$2:$L$46,Dati!$H$2:$H$46,$H14,Dati!$A$2:$A$46,$AD14),"-") -> 60 | BO14: =IF(AND($H14<>"",$AE14<>"",$H14<>$AE14,IFERROR(INDEX($J$14:$J$23,MATCH($H14,$H$14:$H$23,0)),-1)=IFERROR(INDEX($J$14:$J$23,MATCH($AE14,$H$14:$H$23,0)),-2)),SUMIFS(Dati!$E$2:$E$46,Dati!$A$2:$A$46,$H14,Dati!$H$2:$H$46,$AE14)+SUMIFS(Dati!$L$2:$L$46,Dati!$H$2:$H$46,$H14,Dati!$A$2:$A$46,$AE14),"-") -> - | BP14: =IF(AND($H14<>"",$AF14<>"",$H14<>$AF14,IFERROR(INDEX($J$14:$J$23,MATCH($H14,$H$14:$H$23,0)),-1)=IFERROR(INDEX($J$14:$J$23,MATCH($AF14,$H$14:$H$23,0)),-2)),SUMIFS(Dati!$E$2:$E$46,Dati!$A$2:$A$46,$H14,Dati!$H$2:$H$46,$AF14)+SUMIFS(Dati!$L$2:$L$46,Dati!$H$2:$H$46,$H14,Dati!$A$2:$A$46,$AF14),"-") -> - | BQ14: =IF(AND($H14<>"",$AG14<>"",$H14<>$AG14,IFERROR(INDEX($J$14:$J$23,MATCH($H14,$H$14:$H$23,0)),-1)=IFERROR(INDEX($J$14:$J$23,MATCH($AG14,$H$14:$H$23,0)),-2)),SUMIFS(Dati!$E$2:$E$46,Dati!$A$2:$A$46,$H14,Dati!$H$2:$H$46,$AG14)+SUMIFS(Dati!$L$2:$L$46,Dati!$H$2:$H$46,$H14,Dati!$A$2:$A$46,$AG14),"-") -> 50 | BR14: =IF(AND($H14<>"",$AH14<>"",$H14<>$AH14,IFERROR(INDEX($J$14:$J$23,MATCH($H14,$H$14:$H$23,0)),-1)=IFERROR(INDEX($J$14:$J$23,MATCH($AH14,$H$14:$H$23,0)),-2)),SUMIFS(Dati!$E$2:$E$46,Dati!$A$2:$A$46,$H14,Dati!$H$2:$H$46,$AH14)+SUMIFS(Dati!$L$2:$L$46,Dati!$H$2:$H$46,$H14,Dati!$A$2:$A$46,$AH14),"-") -> - | BT14: =$C14 -> Anaconde Audaci-Anacondeopoli AA | BU14: =IF(AND($H14<>"",$Y14<>"",$H14<>$Y14,IFERROR(INDEX($J$14:$J$23,MATCH($H14,$H$14:$H$23,0)),-1)=IFERROR(INDEX($J$14:$J$23,MATCH($Y14,$H$14:$H$23,0)),-2)),SUMIFS(Dati!$F$2:$F$46,Dati!$A$2:$A$46,$H14,Dati!$H$2:$H$46,$Y14)+SUMIFS(Dati!$M$2:$M$46,Dati!$H$2:$H$46,$H14,Dati!$A$2:$A$46,$Y14),"-") -> - | BV14: =IF(AND($H14<>"",$Z14<>"",$H14<>$Z14,IFERROR(INDEX($J$14:$J$23,MATCH($H14,$H$14:$H$23,0)),-1)=IFERROR(INDEX($J$14:$J$23,MATCH($Z14,$H$14:$H$23,0)),-2)),SUMIFS(Dati!$F$2:$F$46,Dati!$A$2:$A$46,$H14,Dati!$H$2:$H$46,$Z14)+SUMIFS(Dati!$M$2:$M$46,Dati!$H$2:$H$46,$H14,Dati!$A$2:$A$46,$Z14),"-") -> - | BW14: =IF(AND($H14<>"",$AA14<>"",$H14<>$AA14,IFERROR(INDEX($J$14:$J$23,MATCH($H14,$H$14:$H$23,0)),-1)=IFERROR(INDEX($J$14:$J$23,MATCH($AA14,$H$14:$H$23,0)),-2)),SUMIFS(Dati!$F$2:$F$46,Dati!$A$2:$A$46,$H14,Dati!$H$2:$H$46,$AA14)+SUMIFS(Dati!$M$2:$M$46,Dati!$H$2:$H$46,$H14,Dati!$A$2:$A$46,$AA14),"-") -> - | BX14: =IF(AND($H14<>"",$AB14<>"",$H14<>$AB14,IFERROR(INDEX($J$14:$J$23,MATCH($H14,$H$14:$H$23,0)),-1)=IFERROR(INDEX($J$14:$J$23,MATCH($AB14,$H$14:$H$23,0)),-2)),SUMIFS(Dati!$F$2:$F$46,Dati!$A$2:$A$46,$H14,Dati!$H$2:$H$46,$AB14)+SUMIFS(Dati!$M$2:$M$46,Dati!$H$2:$H$46,$H14,Dati!$A$2:$A$46,$AB14),"-") -> - | BY14: =IF(AND($H14<>"",$AC14<>"",$H14<>$AC14,IFERROR(INDEX($J$14:$J$23,MATCH($H14,$H$14:$H$23,0)),-1)=IFERROR(INDEX($J$14:$J$23,MATCH($AC14,$H$14:$H$23,0)),-2)),SUMIFS(Dati!$F$2:$F$46,Dati!$A$2:$A$46,$H14,Dati!$H$2:$H$46,$AC14)+SUMIFS(Dati!$M$2:$M$46,Dati!$H$2:$H$46,$H14,Dati!$A$2:$A$46,$AC14),"-") -> - | BZ14: =IF(AND($H14<>"",$AD14<>"",$H14<>$AD14,IFERROR(INDEX($J$14:$J$23,MATCH($H14,$H$14:$H$23,0)),-1)=IFERROR(INDEX($J$14:$J$23,MATCH($AD14,$H$14:$H$23,0)),-2)),SUMIFS(Dati!$F$2:$F$46,Dati!$A$2:$A$46,$H14,Dati!$H$2:$H$46,$AD14)+SUMIFS(Dati!$M$2:$M$46,Dati!$H$2:$H$46,$H14,Dati!$A$2:$A$46,$AD14),"-") -> 40 | CA14: =IF(AND($H14<>"",$AE14<>"",$H14<>$AE14,IFERROR(INDEX($J$14:$J$23,MATCH($H14,$H$14:$H$23,0)),-1)=IFERROR(INDEX($J$14:$J$23,MATCH($AE14,$H$14:$H$23,0)),-2)),SUMIFS(Dati!$F$2:$F$46,Dati!$A$2:$A$46,$H14,Dati!$H$2:$H$46,$AE14)+SUMIFS(Dati!$M$2:$M$46,Dati!$H$2:$H$46,$H14,Dati!$A$2:$A$46,$AE14),"-") -> - | CB14: =IF(AND($H14<>"",$AF14<>"",$H14<>$AF14,IFERROR(INDEX($J$14:$J$23,MATCH($H14,$H$14:$H$23,0)),-1)=IFERROR(INDEX($J$14:$J$23,MATCH($AF14,$H$14:$H$23,0)),-2)),SUMIFS(Dati!$F$2:$F$46,Dati!$A$2:$A$46,$H14,Dati!$H$2:$H$46,$AF14)+SUMIFS(Dati!$M$2:$M$46,Dati!$H$2:$H$46,$H14,Dati!$A$2:$A$46,$AF14),"-") -> - | CC14: =IF(AND($H14<>"",$AG14<>"",$H14<>$AG14,IFERROR(INDEX($J$14:$J$23,MATCH($H14,$H$14:$H$23,0)),-1)=IFERROR(INDEX($J$14:$J$23,MATCH($AG14,$H$14:$H$23,0)),-2)),SUMIFS(Dati!$F$2:$F$46,Dati!$A$2:$A$46,$H14,Dati!$H$2:$H$46,$AG14)+SUMIFS(Dati!$M$2:$M$46,Dati!$H$2:$H$46,$H14,Dati!$A$2:$A$46,$AG14),"-") -> 52 | CD14: =IF(AND($H14<>"",$AH14<>"",$H14<>$AH14,IFERROR(INDEX($J$14:$J$23,MATCH($H14,$H$14:$H$23,0)),-1)=IFERROR(INDEX($J$14:$J$23,MATCH($AH14,$H$14:$H$23,0)),-2)),SUMIFS(Dati!$F$2:$F$46,Dati!$A$2:$A$46,$H14,Dati!$H$2:$H$46,$AH14)+SUMIFS(Dati!$M$2:$M$46,Dati!$H$2:$H$46,$H14,Dati!$A$2:$A$46,$AH14),"-") -> - | CF14: =IF($C14="","",SUM(AK14:AT14)) -> 1
B15: A02 | C15: Bufali Belligeranti-Bufaliopoli BE | E15: A | G15: =IF($C15="","",$E15&(COUNTIFS(I$14:I$23,">"&I15,E$14:E$23,"="&E15,C$14:C$23,"<>")+COUNTIFS(I$14:I$23,"="&I15,H$14:H$23,"<="&H15,E$14:E$23,"="&E15,C$14:C$23,"<>"))) -> A7 | H15: =IF($C15="","",IFERROR(LEFT($C15,FIND("-",$C15)-1),$C15)) -> Bufali Belligeranti | I15: =TEXT(1000000000+J15,"|0000000000|")&TEXT(SUM(AK15:AT15),"0000000000|")&IF(SUM(BU15:CD15)=0,"0000000000|",TEXT(ROUND(SUM(BI15:BR15)/SUM(BU15:CD15),4)*100000,"0000000000|"))&IF(P15=0,"0000000000|",TEXT(ROUND(O15/P15,4)*100000,"0000000000|")) -> |1000000015|0000000001|0000100000|0000088120| | J15: =L15*Campionato!$D$7+M15*Campionato!$D$8+N15*Campionato!$D$9+IF(D15="",0,D15) -> 15 | K15: =SUM(L15:N15) -> 9 | L15: =IF($H15="",0,SUMIF(Dati!$A$2:$A$46,$H15,Dati!$B$2:$B$46)+SUMIF(Dati!$H$2:$H$46,$H15,Dati!$I$2:$I$46)) -> 3 | M15: =IF($H15="",0,SUMIF(Dati!$A$2:$A$46,$H15,Dati!$D$2:$D$46)+SUMIF(Dati!$H$2:$H$46,$H15,Dati!$K$2:$K$46)) -> 6 | N15: =IF($H15="",0,SUMIF(Dati!$A$2:$A$46,$H15,Dati!$C$2:$C$46)+SUMIF(Dati!$H$2:$H$46,$H15,Dati!$J$2:$J$46)) -> 0 | O15: =IF($H15="",0,SUMIF(Dati!$A$2:$A$46,$H15,Dati!$E$2:$E$46)+SUMIF(Dati!$H$2:$H$46,$H15,Dati!$L$2:$L$46)) -> 408 | P15: =IF($H15="",0,SUMIF(Dati!$A$2:$A$46,$H15,Dati!$F$2:$F$46)+SUMIF(Dati!$H$2:$H$46,$H15,Dati!$M$2:$M$46)) -> 463 | Q15: =IF($H15="",0,SUMIF(Dati!$A$2:$A$46,$H15,Dati!$G$2:$G$46)+SUMIF(Dati!$H$2:$H$46,$H15,Dati!$N$2:$N$46)) -> -55 | R15: =IF(K15=0,0,ROUND(O15/K15,2)) -> 45.33 | S15: =IF(K15=0,0,ROUND(P15/K15,2)) -> 51.44 | T15: =IF(K15=0,0,ROUND(Q15/K15,2)) -> -6.11 | U15: =IF(COUNTIFS($E$14:$E$23,$E15,$J$14:$J$23,$J15,$C$14:$C$23,"<>")<=1,"-",SUM(AK15:AT15)&"-"&SUM(AW15:BF15)) -> 1-1 | V15: =IF(COUNTIFS($E$14:$E$23,$E15,$J$14:$J$23,$J15,$C$14:$C$23,"<>",$CF$14:$CF$23,$CF15)<=1,"-",IF(SUM(BU15:CD15)=0,0,ROUND(SUM(BI15:BR15)/SUM(BU15:CD15),3))) -> 1 | W15: =IF(COUNTIFS($E$14:$E$23,$E15,$J$14:$J$23,$J15,$C$14:$C$23,"<>",$CF$14:$CF$23,$CF15,$V$14:$V$23,$V15)<=1,"-",IF(P15=0,0,ROUND(O15/P15,3))) -> 0.881 | X15: =IF($C15="","",$E15&"#"&COUNTIFS($E$14:$E15,$E15,$C$14:$C15,"<>")) -> A#2 | Y15: =IFERROR(INDEX($H$14:$H$23,MATCH($E15&"#1",$X$14:$X$23,0)),"") -> Anaconde Audaci | Z15: =IFERROR(INDEX($H$14:$H$23,MATCH($E15&"#2",$X$14:$X$23,0)),"") -> Bufali Belligeranti | AA15: =IFERROR(INDEX($H$14:$H$23,MATCH($E15&"#3",$X$14:$X$23,0)),"") -> Cobra Celeri | AB15: =IFERROR(INDEX($H$14:$H$23,MATCH($E15&"#4",$X$14:$X$23,0)),"") -> Dingo Docili | AC15: =IFERROR(INDEX($H$14:$H$23,MATCH($E15&"#5",$X$14:$X$23,0)),"") -> Ermellini Eleganti | AD15: =IFERROR(INDEX($H$14:$H$23,MATCH($E15&"#6",$X$14:$X$23,0)),"") -> Falchi Feroci | AE15: =IFERROR(INDEX($H$14:$H$23,MATCH($E15&"#7",$X$14:$X$23,0)),"") -> Gazzelle Gentili | AF15: =IFERROR(INDEX($H$14:$H$23,MATCH($E15&"#8",$X$14:$X$23,0)),"") -> Ibis Instancabili | AG15: =IFERROR(INDEX($H$14:$H$23,MATCH($E15&"#9",$X$14:$X$23,0)),"") -> Lupi Leali | AH15: =IFERROR(INDEX($H$14:$H$23,MATCH($E15&"#10",$X$14:$X$23,0)),"") -> Marmotte Mobili | AJ15: =$C15 -> Bufali Belligeranti-Bufaliopoli BE | AK15: =IF(AND($H15<>"",$Y15<>"",$H15<>$Y15,IFERROR(INDEX($J$14:$J$23,MATCH($H15,$H$14:$H$23,0)),-1)=IFERROR(INDEX($J$14:$J$23,MATCH($Y15,$H$14:$H$23,0)),-2)),SUMIFS(Dati!$B$2:$B$46,Dati!$A$2:$A$46,$H15,Dati!$H$2:$H$46,$Y15)+SUMIFS(Dati!$I$2:$I$46,Dati!$H$2:$H$46,$H15,Dati!$A$2:$A$46,$Y15),"-") -> - | AL15: =IF(AND($H15<>"",$Z15<>"",$H15<>$Z15,IFERROR(INDEX($J$14:$J$23,MATCH($H15,$H$14:$H$23,0)),-1)=IFERROR(INDEX($J$14:$J$23,MATCH($Z15,$H$14:$H$23,0)),-2)),SUMIFS(Dati!$B$2:$B$46,Dati!$A$2:$A$46,$H15,Dati!$H$2:$H$46,$Z15)+SUMIFS(Dati!$I$2:$I$46,Dati!$H$2:$H$46,$H15,Dati!$A$2:$A$46,$Z15),"-") -> - | AM15: =IF(AND($H15<>"",$AA15<>"",$H15<>$AA15,IFERROR(INDEX($J$14:$J$23,MATCH($H15,$H$14:$H$23,0)),-1)=IFERROR(INDEX($J$14:$J$23,MATCH($AA15,$H$14:$H$23,0)),-2)),SUMIFS(Dati!$B$2:$B$46,Dati!$A$2:$A$46,$H15,Dati!$H$2:$H$46,$AA15)+SUMIFS(Dati!$I$2:$I$46,Dati!$H$2:$H$46,$H15,Dati!$A$2:$A$46,$AA15),"-") -> - | AN15: =IF(AND($H15<>"",$AB15<>"",$H15<>$AB15,IFERROR(INDEX($J$14:$J$23,MATCH($H15,$H$14:$H$23,0)),-1)=IFERROR(INDEX($J$14:$J$23,MATCH($AB15,$H$14:$H$23,0)),-2)),SUMIFS(Dati!$B$2:$B$46,Dati!$A$2:$A$46,$H15,Dati!$H$2:$H$46,$AB15)+SUMIFS(Dati!$I$2:$I$46,Dati!$H$2:$H$46,$H15,Dati!$A$2:$A$46,$AB15),"-") -> - | AO15: =IF(AND($H15<>"",$AC15<>"",$H15<>$AC15,IFERROR(INDEX($J$14:$J$23,MATCH($H15,$H$14:$H$23,0)),-1)=IFERROR(INDEX($J$14:$J$23,MATCH($AC15,$H$14:$H$23,0)),-2)),SUMIFS(Dati!$B$2:$B$46,Dati!$A$2:$A$46,$H15,Dati!$H$2:$H$46,$AC15)+SUMIFS(Dati!$I$2:$I$46,Dati!$H$2:$H$46,$H15,Dati!$A$2:$A$46,$AC15),"-") -> 1 | AP15: =IF(AND($H15<>"",$AD15<>"",$H15<>$AD15,IFERROR(INDEX($J$14:$J$23,MATCH($H15,$H$14:$H$23,0)),-1)=IFERROR(INDEX($J$14:$J$23,MATCH($AD15,$H$14:$H$23,0)),-2)),SUMIFS(Dati!$B$2:$B$46,Dati!$A$2:$A$46,$H15,Dati!$H$2:$H$46,$AD15)+SUMIFS(Dati!$I$2:$I$46,Dati!$H$2:$H$46,$H15,Dati!$A$2:$A$46,$AD15),"-") -> - | AQ15: =IF(AND($H15<>"",$AE15<>"",$H15<>$AE15,IFERROR(INDEX($J$14:$J$23,MATCH($H15,$H$14:$H$23,0)),-1)=IFERROR(INDEX($J$14:$J$23,MATCH($AE15,$H$14:$H$23,0)),-2)),SUMIFS(Dati!$B$2:$B$46,Dati!$A$2:$A$46,$H15,Dati!$H$2:$H$46,$AE15)+SUMIFS(Dati!$I$2:$I$46,Dati!$H$2:$H$46,$H15,Dati!$A$2:$A$46,$AE15),"-") -> - | AR15: =IF(AND($H15<>"",$AF15<>"",$H15<>$AF15,IFERROR(INDEX($J$14:$J$23,MATCH($H15,$H$14:$H$23,0)),-1)=IFERROR(INDEX($J$14:$J$23,MATCH($AF15,$H$14:$H$23,0)),-2)),SUMIFS(Dati!$B$2:$B$46,Dati!$A$2:$A$46,$H15,Dati!$H$2:$H$46,$AF15)+SUMIFS(Dati!$I$2:$I$46,Dati!$H$2:$H$46,$H15,Dati!$A$2:$A$46,$AF15),"-") -> - | AS15: =IF(AND($H15<>"",$AG15<>"",$H15<>$AG15,IFERROR(INDEX($J$14:$J$23,MATCH($H15,$H$14:$H$23,0)),-1)=IFERROR(INDEX($J$14:$J$23,MATCH($AG15,$H$14:$H$23,0)),-2)),SUMIFS(Dati!$B$2:$B$46,Dati!$A$2:$A$46,$H15,Dati!$H$2:$H$46,$AG15)+SUMIFS(Dati!$I$2:$I$46,Dati!$H$2:$H$46,$H15,Dati!$A$2:$A$46,$AG15),"-") -> - | AT15: =IF(AND($H15<>"",$AH15<>"",$H15<>$AH15,IFERROR(INDEX($J$14:$J$23,MATCH($H15,$H$14:$H$23,0)),-1)=IFERROR(INDEX($J$14:$J$23,MATCH($AH15,$H$14:$H$23,0)),-2)),SUMIFS(Dati!$B$2:$B$46,Dati!$A$2:$A$46,$H15,Dati!$H$2:$H$46,$AH15)+SUMIFS(Dati!$I$2:$I$46,Dati!$H$2:$H$46,$H15,Dati!$A$2:$A$46,$AH15),"-") -> 0 | AV15: =$C15 -> Bufali Belligeranti-Bufaliopoli BE | AW15: =IF(AND($H15<>"",$Y15<>"",$H15<>$Y15,IFERROR(INDEX($J$14:$J$23,MATCH($H15,$H$14:$H$23,0)),-1)=IFERROR(INDEX($J$14:$J$23,MATCH($Y15,$H$14:$H$23,0)),-2)),SUMIFS(Dati!$D$2:$D$46,Dati!$A$2:$A$46,$H15,Dati!$H$2:$H$46,$Y15)+SUMIFS(Dati!$K$2:$K$46,Dati!$H$2:$H$46,$H15,Dati!$A$2:$A$46,$Y15)+SUMIFS(Dati!$C$2:$C$46,Dati!$A$2:$A$46,$H15,Dati!$H$2:$H$46,$Y15)+SUMIFS(Dati!$J$2:$J$46,Dati!$H$2:$H$46,$H15,Dati!$A$2:$A$46,$Y15),"-") -> - | AX15: =IF(AND($H15<>"",$Z15<>"",$H15<>$Z15,IFERROR(INDEX($J$14:$J$23,MATCH($H15,$H$14:$H$23,0)),-1)=IFERROR(INDEX($J$14:$J$23,MATCH($Z15,$H$14:$H$23,0)),-2)),SUMIFS(Dati!$D$2:$D$46,Dati!$A$2:$A$46,$H15,Dati!$H$2:$H$46,$Z15)+SUMIFS(Dati!$K$2:$K$46,Dati!$H$2:$H$46,$H15,Dati!$A$2:$A$46,$Z15)+SUMIFS(Dati!$C$2:$C$46,Dati!$A$2:$A$46,$H15,Dati!$H$2:$H$46,$Z15)+SUMIFS(Dati!$J$2:$J$46,Dati!$H$2:$H$46,$H15,Dati!$A$2:$A$46,$Z15),"-") -> - | AY15: =IF(AND($H15<>"",$AA15<>"",$H15<>$AA15,IFERROR(INDEX($J$14:$J$23,MATCH($H15,$H$14:$H$23,0)),-1)=IFERROR(INDEX($J$14:$J$23,MATCH($AA15,$H$14:$H$23,0)),-2)),SUMIFS(Dati!$D$2:$D$46,Dati!$A$2:$A$46,$H15,Dati!$H$2:$H$46,$AA15)+SUMIFS(Dati!$K$2:$K$46,Dati!$H$2:$H$46,$H15,Dati!$A$2:$A$46,$AA15)+SUMIFS(Dati!$C$2:$C$46,Dati!$A$2:$A$46,$H15,Dati!$H$2:$H$46,$AA15)+SUMIFS(Dati!$J$2:$J$46,Dati!$H$2:$H$46,$H15,Dati!$A$2:$A$46,$AA15),"-") -> - | AZ15: =IF(AND($H15<>"",$AB15<>"",$H15<>$AB15,IFERROR(INDEX($J$14:$J$23,MATCH($H15,$H$14:$H$23,0)),-1)=IFERROR(INDEX($J$14:$J$23,MATCH($AB15,$H$14:$H$23,0)),-2)),SUMIFS(Dati!$D$2:$D$46,Dati!$A$2:$A$46,$H15,Dati!$H$2:$H$46,$AB15)+SUMIFS(Dati!$K$2:$K$46,Dati!$H$2:$H$46,$H15,Dati!$A$2:$A$46,$AB15)+SUMIFS(Dati!$C$2:$C$46,Dati!$A$2:$A$46,$H15,Dati!$H$2:$H$46,$AB15)+SUMIFS(Dati!$J$2:$J$46,Dati!$H$2:$H$46,$H15,Dati!$A$2:$A$46,$AB15),"-") -> - | BA15: =IF(AND($H15<>"",$AC15<>"",$H15<>$AC15,IFERROR(INDEX($J$14:$J$23,MATCH($H15,$H$14:$H$23,0)),-1)=IFERROR(INDEX($J$14:$J$23,MATCH($AC15,$H$14:$H$23,0)),-2)),SUMIFS(Dati!$D$2:$D$46,Dati!$A$2:$A$46,$H15,Dati!$H$2:$H$46,$AC15)+SUMIFS(Dati!$K$2:$K$46,Dati!$H$2:$H$46,$H15,Dati!$A$2:$A$46,$AC15)+SUMIFS(Dati!$C$2:$C$46,Dati!$A$2:$A$46,$H15,Dati!$H$2:$H$46,$AC15)+SUMIFS(Dati!$J$2:$J$46,Dati!$H$2:$H$46,$H15,Dati!$A$2:$A$46,$AC15),"-") -> 0 | BB15: =IF(AND($H15<>"",$AD15<>"",$H15<>$AD15,IFERROR(INDEX($J$14:$J$23,MATCH($H15,$H$14:$H$23,0)),-1)=IFERROR(INDEX($J$14:$J$23,MATCH($AD15,$H$14:$H$23,0)),-2)),SUMIFS(Dati!$D$2:$D$46,Dati!$A$2:$A$46,$H15,Dati!$H$2:$H$46,$AD15)+SUMIFS(Dati!$K$2:$K$46,Dati!$H$2:$H$46,$H15,Dati!$A$2:$A$46,$AD15)+SUMIFS(Dati!$C$2:$C$46,Dati!$A$2:$A$46,$H15,Dati!$H$2:$H$46,$AD15)+SUMIFS(Dati!$J$2:$J$46,Dati!$H$2:$H$46,$H15,Dati!$A$2:$A$46,$AD15),"-") -> - | BC15: =IF(AND($H15<>"",$AE15<>"",$H15<>$AE15,IFERROR(INDEX($J$14:$J$23,MATCH($H15,$H$14:$H$23,0)),-1)=IFERROR(INDEX($J$14:$J$23,MATCH($AE15,$H$14:$H$23,0)),-2)),SUMIFS(Dati!$D$2:$D$46,Dati!$A$2:$A$46,$H15,Dati!$H$2:$H$46,$AE15)+SUMIFS(Dati!$K$2:$K$46,Dati!$H$2:$H$46,$H15,Dati!$A$2:$A$46,$AE15)+SUMIFS(Dati!$C$2:$C$46,Dati!$A$2:$A$46,$H15,Dati!$H$2:$H$46,$AE15)+SUMIFS(Dati!$J$2:$J$46,Dati!$H$2:$H$46,$H15,Dati!$A$2:$A$46,$AE15),"-") -> - | BD15: =IF(AND($H15<>"",$AF15<>"",$H15<>$AF15,IFERROR(INDEX($J$14:$J$23,MATCH($H15,$H$14:$H$23,0)),-1)=IFERROR(INDEX($J$14:$J$23,MATCH($AF15,$H$14:$H$23,0)),-2)),SUMIFS(Dati!$D$2:$D$46,Dati!$A$2:$A$46,$H15,Dati!$H$2:$H$46,$AF15)+SUMIFS(Dati!$K$2:$K$46,Dati!$H$2:$H$46,$H15,Dati!$A$2:$A$46,$AF15)+SUMIFS(Dati!$C$2:$C$46,Dati!$A$2:$A$46,$H15,Dati!$H$2:$H$46,$AF15)+SUMIFS(Dati!$J$2:$J$46,Dati!$H$2:$H$46,$H15,Dati!$A$2:$A$46,$AF15),"-") -> - | BE15: =IF(AND($H15<>"",$AG15<>"",$H15<>$AG15,IFERROR(INDEX($J$14:$J$23,MATCH($H15,$H$14:$H$23,0)),-1)=IFERROR(INDEX($J$14:$J$23,MATCH($AG15,$H$14:$H$23,0)),-2)),SUMIFS(Dati!$D$2:$D$46,Dati!$A$2:$A$46,$H15,Dati!$H$2:$H$46,$AG15)+SUMIFS(Dati!$K$2:$K$46,Dati!$H$2:$H$46,$H15,Dati!$A$2:$A$46,$AG15)+SUMIFS(Dati!$C$2:$C$46,Dati!$A$2:$A$46,$H15,Dati!$H$2:$H$46,$AG15)+SUMIFS(Dati!$J$2:$J$46,Dati!$H$2:$H$46,$H15,Dati!$A$2:$A$46,$AG15),"-") -> - | BF15: =IF(AND($H15<>"",$AH15<>"",$H15<>$AH15,IFERROR(INDEX($J$14:$J$23,MATCH($H15,$H$14:$H$23,0)),-1)=IFERROR(INDEX($J$14:$J$23,MATCH($AH15,$H$14:$H$23,0)),-2)),SUMIFS(Dati!$D$2:$D$46,Dati!$A$2:$A$46,$H15,Dati!$H$2:$H$46,$AH15)+SUMIFS(Dati!$K$2:$K$46,Dati!$H$2:$H$46,$H15,Dati!$A$2:$A$46,$AH15)+SUMIFS(Dati!$C$2:$C$46,Dati!$A$2:$A$46,$H15,Dati!$H$2:$H$46,$AH15)+SUMIFS(Dati!$J$2:$J$46,Dati!$H$2:$H$46,$H15,Dati!$A$2:$A$46,$AH15),"-") -> 1 | BH15: =$C15 -> Bufali Belligeranti-Bufaliopoli BE | BI15: =IF(AND($H15<>"",$Y15<>"",$H15<>$Y15,IFERROR(INDEX($J$14:$J$23,MATCH($H15,$H$14:$H$23,0)),-1)=IFERROR(INDEX($J$14:$J$23,MATCH($Y15,$H$14:$H$23,0)),-2)),SUMIFS(Dati!$E$2:$E$46,Dati!$A$2:$A$46,$H15,Dati!$H$2:$H$46,$Y15)+SUMIFS(Dati!$L$2:$L$46,Dati!$H$2:$H$46,$H15,Dati!$A$2:$A$46,$Y15),"-") -> - | BJ15: =IF(AND($H15<>"",$Z15<>"",$H15<>$Z15,IFERROR(INDEX($J$14:$J$23,MATCH($H15,$H$14:$H$23,0)),-1)=IFERROR(INDEX($J$14:$J$23,MATCH($Z15,$H$14:$H$23,0)),-2)),SUMIFS(Dati!$E$2:$E$46,Dati!$A$2:$A$46,$H15,Dati!$H$2:$H$46,$Z15)+SUMIFS(Dati!$L$2:$L$46,Dati!$H$2:$H$46,$H15,Dati!$A$2:$A$46,$Z15),"-") -> - | BK15: =IF(AND($H15<>"",$AA15<>"",$H15<>$AA15,IFERROR(INDEX($J$14:$J$23,MATCH($H15,$H$14:$H$23,0)),-1)=IFERROR(INDEX($J$14:$J$23,MATCH($AA15,$H$14:$H$23,0)),-2)),SUMIFS(Dati!$E$2:$E$46,Dati!$A$2:$A$46,$H15,Dati!$H$2:$H$46,$AA15)+SUMIFS(Dati!$L$2:$L$46,Dati!$H$2:$H$46,$H15,Dati!$A$2:$A$46,$AA15),"-") -> - | BL15: =IF(AND($H15<>"",$AB15<>"",$H15<>$AB15,IFERROR(INDEX($J$14:$J$23,MATCH($H15,$H$14:$H$23,0)),-1)=IFERROR(INDEX($J$14:$J$23,MATCH($AB15,$H$14:$H$23,0)),-2)),SUMIFS(Dati!$E$2:$E$46,Dati!$A$2:$A$46,$H15,Dati!$H$2:$H$46,$AB15)+SUMIFS(Dati!$L$2:$L$46,Dati!$H$2:$H$46,$H15,Dati!$A$2:$A$46,$AB15),"-") -> - | BM15: =IF(AND($H15<>"",$AC15<>"",$H15<>$AC15,IFERROR(INDEX($J$14:$J$23,MATCH($H15,$H$14:$H$23,0)),-1)=IFERROR(INDEX($J$14:$J$23,MATCH($AC15,$H$14:$H$23,0)),-2)),SUMIFS(Dati!$E$2:$E$46,Dati!$A$2:$A$46,$H15,Dati!$H$2:$H$46,$AC15)+SUMIFS(Dati!$L$2:$L$46,Dati!$H$2:$H$46,$H15,Dati!$A$2:$A$46,$AC15),"-") -> 50 | BN15: =IF(AND($H15<>"",$AD15<>"",$H15<>$AD15,IFERROR(INDEX($J$14:$J$23,MATCH($H15,$H$14:$H$23,0)),-1)=IFERROR(INDEX($J$14:$J$23,MATCH($AD15,$H$14:$H$23,0)),-2)),SUMIFS(Dati!$E$2:$E$46,Dati!$A$2:$A$46,$H15,Dati!$H$2:$H$46,$AD15)+SUMIFS(Dati!$L$2:$L$46,Dati!$H$2:$H$46,$H15,Dati!$A$2:$A$46,$AD15),"-") -> - | BO15: =IF(AND($H15<>"",$AE15<>"",$H15<>$AE15,IFERROR(INDEX($J$14:$J$23,MATCH($H15,$H$14:$H$23,0)),-1)=IFERROR(INDEX($J$14:$J$23,MATCH($AE15,$H$14:$H$23,0)),-2)),SUMIFS(Dati!$E$2:$E$46,Dati!$A$2:$A$46,$H15,Dati!$H$2:$H$46,$AE15)+SUMIFS(Dati!$L$2:$L$46,Dati!$H$2:$H$46,$H15,Dati!$A$2:$A$46,$AE15),"-") -> - | BP15: =IF(AND($H15<>"",$AF15<>"",$H15<>$AF15,IFERROR(INDEX($J$14:$J$23,MATCH($H15,$H$14:$H$23,0)),-1)=IFERROR(INDEX($J$14:$J$23,MATCH($AF15,$H$14:$H$23,0)),-2)),SUMIFS(Dati!$E$2:$E$46,Dati!$A$2:$A$46,$H15,Dati!$H$2:$H$46,$AF15)+SUMIFS(Dati!$L$2:$L$46,Dati!$H$2:$H$46,$H15,Dati!$A$2:$A$46,$AF15),"-") -> - | BQ15: =IF(AND($H15<>"",$AG15<>"",$H15<>$AG15,IFERROR(INDEX($J$14:$J$23,MATCH($H15,$H$14:$H$23,0)),-1)=IFERROR(INDEX($J$14:$J$23,MATCH($AG15,$H$14:$H$23,0)),-2)),SUMIFS(Dati!$E$2:$E$46,Dati!$A$2:$A$46,$H15,Dati!$H$2:$H$46,$AG15)+SUMIFS(Dati!$L$2:$L$46,Dati!$H$2:$H$46,$H15,Dati!$A$2:$A$46,$AG15),"-") -> - | BR15: =IF(AND($H15<>"",$AH15<>"",$H15<>$AH15,IFERROR(INDEX($J$14:$J$23,MATCH($H15,$H$14:$H$23,0)),-1)=IFERROR(INDEX($J$14:$J$23,MATCH($AH15,$H$14:$H$23,0)),-2)),SUMIFS(Dati!$E$2:$E$46,Dati!$A$2:$A$46,$H15,Dati!$H$2:$H$46,$AH15)+SUMIFS(Dati!$L$2:$L$46,Dati!$H$2:$H$46,$H15,Dati!$A$2:$A$46,$AH15),"-") -> 40 | BT15: =$C15 -> Bufali Belligeranti-Bufaliopoli BE | BU15: =IF(AND($H15<>"",$Y15<>"",$H15<>$Y15,IFERROR(INDEX($J$14:$J$23,MATCH($H15,$H$14:$H$23,0)),-1)=IFERROR(INDEX($J$14:$J$23,MATCH($Y15,$H$14:$H$23,0)),-2)),SUMIFS(Dati!$F$2:$F$46,Dati!$A$2:$A$46,$H15,Dati!$H$2:$H$46,$Y15)+SUMIFS(Dati!$M$2:$M$46,Dati!$H$2:$H$46,$H15,Dati!$A$2:$A$46,$Y15),"-") -> - | BV15: =IF(AND($H15<>"",$Z15<>"",$H15<>$Z15,IFERROR(INDEX($J$14:$J$23,MATCH($H15,$H$14:$H$23,0)),-1)=IFERROR(INDEX($J$14:$J$23,MATCH($Z15,$H$14:$H$23,0)),-2)),SUMIFS(Dati!$F$2:$F$46,Dati!$A$2:$A$46,$H15,Dati!$H$2:$H$46,$Z15)+SUMIFS(Dati!$M$2:$M$46,Dati!$H$2:$H$46,$H15,Dati!$A$2:$A$46,$Z15),"-") -> - | BW15: =IF(AND($H15<>"",$AA15<>"",$H15<>$AA15,IFERROR(INDEX($J$14:$J$23,MATCH($H15,$H$14:$H$23,0)),-1)=IFERROR(INDEX($J$14:$J$23,MATCH($AA15,$H$14:$H$23,0)),-2)),SUMIFS(Dati!$F$2:$F$46,Dati!$A$2:$A$46,$H15,Dati!$H$2:$H$46,$AA15)+SUMIFS(Dati!$M$2:$M$46,Dati!$H$2:$H$46,$H15,Dati!$A$2:$A$46,$AA15),"-") -> - | BX15: =IF(AND($H15<>"",$AB15<>"",$H15<>$AB15,IFERROR(INDEX($J$14:$J$23,MATCH($H15,$H$14:$H$23,0)),-1)=IFERROR(INDEX($J$14:$J$23,MATCH($AB15,$H$14:$H$23,0)),-2)),SUMIFS(Dati!$F$2:$F$46,Dati!$A$2:$A$46,$H15,Dati!$H$2:$H$46,$AB15)+SUMIFS(Dati!$M$2:$M$46,Dati!$H$2:$H$46,$H15,Dati!$A$2:$A$46,$AB15),"-") -> - | BY15: =IF(AND($H15<>"",$AC15<>"",$H15<>$AC15,IFERROR(INDEX($J$14:$J$23,MATCH($H15,$H$14:$H$23,0)),-1)=IFERROR(INDEX($J$14:$J$23,MATCH($AC15,$H$14:$H$23,0)),-2)),SUMIFS(Dati!$F$2:$F$46,Dati!$A$2:$A$46,$H15,Dati!$H$2:$H$46,$AC15)+SUMIFS(Dati!$M$2:$M$46,Dati!$H$2:$H$46,$H15,Dati!$A$2:$A$46,$AC15),"-") -> 40 | BZ15: =IF(AND($H15<>"",$AD15<>"",$H15<>$AD15,IFERROR(INDEX($J$14:$J$23,MATCH($H15,$H$14:$H$23,0)),-1)=IFERROR(INDEX($J$14:$J$23,MATCH($AD15,$H$14:$H$23,0)),-2)),SUMIFS(Dati!$F$2:$F$46,Dati!$A$2:$A$46,$H15,Dati!$H$2:$H$46,$AD15)+SUMIFS(Dati!$M$2:$M$46,Dati!$H$2:$H$46,$H15,Dati!$A$2:$A$46,$AD15),"-") -> - | CA15: =IF(AND($H15<>"",$AE15<>"",$H15<>$AE15,IFERROR(INDEX($J$14:$J$23,MATCH($H15,$H$14:$H$23,0)),-1)=IFERROR(INDEX($J$14:$J$23,MATCH($AE15,$H$14:$H$23,0)),-2)),SUMIFS(Dati!$F$2:$F$46,Dati!$A$2:$A$46,$H15,Dati!$H$2:$H$46,$AE15)+SUMIFS(Dati!$M$2:$M$46,Dati!$H$2:$H$46,$H15,Dati!$A$2:$A$46,$AE15),"-") -> - | CB15: =IF(AND($H15<>"",$AF15<>"",$H15<>$AF15,IFERROR(INDEX($J$14:$J$23,MATCH($H15,$H$14:$H$23,0)),-1)=IFERROR(INDEX($J$14:$J$23,MATCH($AF15,$H$14:$H$23,0)),-2)),SUMIFS(Dati!$F$2:$F$46,Dati!$A$2:$A$46,$H15,Dati!$H$2:$H$46,$AF15)+SUMIFS(Dati!$M$2:$M$46,Dati!$H$2:$H$46,$H15,Dati!$A$2:$A$46,$AF15),"-") -> - | CC15: =IF(AND($H15<>"",$AG15<>"",$H15<>$AG15,IFERROR(INDEX($J$14:$J$23,MATCH($H15,$H$14:$H$23,0)),-1)=IFERROR(INDEX($J$14:$J$23,MATCH($AG15,$H$14:$H$23,0)),-2)),SUMIFS(Dati!$F$2:$F$46,Dati!$A$2:$A$46,$H15,Dati!$H$2:$H$46,$AG15)+SUMIFS(Dati!$M$2:$M$46,Dati!$H$2:$H$46,$H15,Dati!$A$2:$A$46,$AG15),"-") -> - | CD15: =IF(AND($H15<>"",$AH15<>"",$H15<>$AH15,IFERROR(INDEX($J$14:$J$23,MATCH($H15,$H$14:$H$23,0)),-1)=IFERROR(INDEX($J$14:$J$23,MATCH($AH15,$H$14:$H$23,0)),-2)),SUMIFS(Dati!$F$2:$F$46,Dati!$A$2:$A$46,$H15,Dati!$H$2:$H$46,$AH15)+SUMIFS(Dati!$M$2:$M$46,Dati!$H$2:$H$46,$H15,Dati!$A$2:$A$46,$AH15),"-") -> 50 | CF15: =IF($C15="","",SUM(AK15:AT15)) -> 1
B16: A03 | C16: Cobra Celeri-Cobraopoli CI | E16: A | G16: =IF($C16="","",$E16&(COUNTIFS(I$14:I$23,">"&I16,E$14:E$23,"="&E16,C$14:C$23,"<>")+COUNTIFS(I$14:I$23,"="&I16,H$14:H$23,"<="&H16,E$14:E$23,"="&E16,C$14:C$23,"<>"))) -> A5 | H16: =IF($C16="","",IFERROR(LEFT($C16,FIND("-",$C16)-1),$C16)) -> Cobra Celeri | I16: =TEXT(1000000000+J16,"|0000000000|")&TEXT(SUM(AK16:AT16),"0000000000|")&IF(SUM(BU16:CD16)=0,"0000000000|",TEXT(ROUND(SUM(BI16:BR16)/SUM(BU16:CD16),4)*100000,"0000000000|"))&IF(P16=0,"0000000000|",TEXT(ROUND(O16/P16,4)*100000,"0000000000|")) -> |1000000019|0000000001|0000113730|0000107070| | J16: =L16*Campionato!$D$7+M16*Campionato!$D$8+N16*Campionato!$D$9+IF(D16="",0,D16) -> 19 | K16: =SUM(L16:N16) -> 9 | L16: =IF($H16="",0,SUMIF(Dati!$A$2:$A$46,$H16,Dati!$B$2:$B$46)+SUMIF(Dati!$H$2:$H$46,$H16,Dati!$I$2:$I$46)) -> 5 | M16: =IF($H16="",0,SUMIF(Dati!$A$2:$A$46,$H16,Dati!$D$2:$D$46)+SUMIF(Dati!$H$2:$H$46,$H16,Dati!$K$2:$K$46)) -> 4 | N16: =IF($H16="",0,SUMIF(Dati!$A$2:$A$46,$H16,Dati!$C$2:$C$46)+SUMIF(Dati!$H$2:$H$46,$H16,Dati!$J$2:$J$46)) -> 0 | O16: =IF($H16="",0,SUMIF(Dati!$A$2:$A$46,$H16,Dati!$E$2:$E$46)+SUMIF(Dati!$H$2:$H$46,$H16,Dati!$L$2:$L$46)) -> 545 | P16: =IF($H16="",0,SUMIF(Dati!$A$2:$A$46,$H16,Dati!$F$2:$F$46)+SUMIF(Dati!$H$2:$H$46,$H16,Dati!$M$2:$M$46)) -> 509 | Q16: =IF($H16="",0,SUMIF(Dati!$A$2:$A$46,$H16,Dati!$G$2:$G$46)+SUMIF(Dati!$H$2:$H$46,$H16,Dati!$N$2:$N$46)) -> 36 | R16: =IF(K16=0,0,ROUND(O16/K16,2)) -> 60.56 | S16: =IF(K16=0,0,ROUND(P16/K16,2)) -> 56.56 | T16: =IF(K16=0,0,ROUND(Q16/K16,2)) -> 4 | U16: =IF(COUNTIFS($E$14:$E$23,$E16,$J$14:$J$23,$J16,$C$14:$C$23,"<>")<=1,"-",SUM(AK16:AT16)&"-"&SUM(AW16:BF16)) -> 1-0 | V16: =IF(COUNTIFS($E$14:$E$23,$E16,$J$14:$J$23,$J16,$C$14:$C$23,"<>",$CF$14:$CF$23,$CF16)<=1,"-",IF(SUM(BU16:CD16)=0,0,ROUND(SUM(BI16:BR16)/SUM(BU16:CD16),3))) -> - | W16: =IF(COUNTIFS($E$14:$E$23,$E16,$J$14:$J$23,$J16,$C$14:$C$23,"<>",$CF$14:$CF$23,$CF16,$V$14:$V$23,$V16)<=1,"-",IF(P16=0,0,ROUND(O16/P16,3))) -> - | X16: =IF($C16="","",$E16&"#"&COUNTIFS($E$14:$E16,$E16,$C$14:$C16,"<>")) -> A#3 | Y16: =IFERROR(INDEX($H$14:$H$23,MATCH($E16&"#1",$X$14:$X$23,0)),"") -> Anaconde Audaci | Z16: =IFERROR(INDEX($H$14:$H$23,MATCH($E16&"#2",$X$14:$X$23,0)),"") -> Bufali Belligeranti | AA16: =IFERROR(INDEX($H$14:$H$23,MATCH($E16&"#3",$X$14:$X$23,0)),"") -> Cobra Celeri | AB16: =IFERROR(INDEX($H$14:$H$23,MATCH($E16&"#4",$X$14:$X$23,0)),"") -> Dingo Docili | AC16: =IFERROR(INDEX($H$14:$H$23,MATCH($E16&"#5",$X$14:$X$23,0)),"") -> Ermellini Eleganti | AD16: =IFERROR(INDEX($H$14:$H$23,MATCH($E16&"#6",$X$14:$X$23,0)),"") -> Falchi Feroci | AE16: =IFERROR(INDEX($H$14:$H$23,MATCH($E16&"#7",$X$14:$X$23,0)),"") -> Gazzelle Gentili | AF16: =IFERROR(INDEX($H$14:$H$23,MATCH($E16&"#8",$X$14:$X$23,0)),"") -> Ibis Instancabili | AG16: =IFERROR(INDEX($H$14:$H$23,MATCH($E16&"#9",$X$14:$X$23,0)),"") -> Lupi Leali | AH16: =IFERROR(INDEX($H$14:$H$23,MATCH($E16&"#10",$X$14:$X$23,0)),"") -> Marmotte Mobili | AJ16: =$C16 -> Cobra Celeri-Cobraopoli CI | AK16: =IF(AND($H16<>"",$Y16<>"",$H16<>$Y16,IFERROR(INDEX($J$14:$J$23,MATCH($H16,$H$14:$H$23,0)),-1)=IFERROR(INDEX($J$14:$J$23,MATCH($Y16,$H$14:$H$23,0)),-2)),SUMIFS(Dati!$B$2:$B$46,Dati!$A$2:$A$46,$H16,Dati!$H$2:$H$46,$Y16)+SUMIFS(Dati!$I$2:$I$46,Dati!$H$2:$H$46,$H16,Dati!$A$2:$A$46,$Y16),"-") -> - | AL16: =IF(AND($H16<>"",$Z16<>"",$H16<>$Z16,IFERROR(INDEX($J$14:$J$23,MATCH($H16,$H$14:$H$23,0)),-1)=IFERROR(INDEX($J$14:$J$23,MATCH($Z16,$H$14:$H$23,0)),-2)),SUMIFS(Dati!$B$2:$B$46,Dati!$A$2:$A$46,$H16,Dati!$H$2:$H$46,$Z16)+SUMIFS(Dati!$I$2:$I$46,Dati!$H$2:$H$46,$H16,Dati!$A$2:$A$46,$Z16),"-") -> - | AM16: =IF(AND($H16<>"",$AA16<>"",$H16<>$AA16,IFERROR(INDEX($J$14:$J$23,MATCH($H16,$H$14:$H$23,0)),-1)=IFERROR(INDEX($J$14:$J$23,MATCH($AA16,$H$14:$H$23,0)),-2)),SUMIFS(Dati!$B$2:$B$46,Dati!$A$2:$A$46,$H16,Dati!$H$2:$H$46,$AA16)+SUMIFS(Dati!$I$2:$I$46,Dati!$H$2:$H$46,$H16,Dati!$A$2:$A$46,$AA16),"-") -> - | AN16: =IF(AND($H16<>"",$AB16<>"",$H16<>$AB16,IFERROR(INDEX($J$14:$J$23,MATCH($H16,$H$14:$H$23,0)),-1)=IFERROR(INDEX($J$14:$J$23,MATCH($AB16,$H$14:$H$23,0)),-2)),SUMIFS(Dati!$B$2:$B$46,Dati!$A$2:$A$46,$H16,Dati!$H$2:$H$46,$AB16)+SUMIFS(Dati!$I$2:$I$46,Dati!$H$2:$H$46,$H16,Dati!$A$2:$A$46,$AB16),"-") -> - | AO16: =IF(AND($H16<>"",$AC16<>"",$H16<>$AC16,IFERROR(INDEX($J$14:$J$23,MATCH($H16,$H$14:$H$23,0)),-1)=IFERROR(INDEX($J$14:$J$23,MATCH($AC16,$H$14:$H$23,0)),-2)),SUMIFS(Dati!$B$2:$B$46,Dati!$A$2:$A$46,$H16,Dati!$H$2:$H$46,$AC16)+SUMIFS(Dati!$I$2:$I$46,Dati!$H$2:$H$46,$H16,Dati!$A$2:$A$46,$AC16),"-") -> - | AP16: =IF(AND($H16<>"",$AD16<>"",$H16<>$AD16,IFERROR(INDEX($J$14:$J$23,MATCH($H16,$H$14:$H$23,0)),-1)=IFERROR(INDEX($J$14:$J$23,MATCH($AD16,$H$14:$H$23,0)),-2)),SUMIFS(Dati!$B$2:$B$46,Dati!$A$2:$A$46,$H16,Dati!$H$2:$H$46,$AD16)+SUMIFS(Dati!$I$2:$I$46,Dati!$H$2:$H$46,$H16,Dati!$A$2:$A$46,$AD16),"-") -> - | AQ16: =IF(AND($H16<>"",$AE16<>"",$H16<>$AE16,IFERROR(INDEX($J$14:$J$23,MATCH($H16,$H$14:$H$23,0)),-1)=IFERROR(INDEX($J$14:$J$23,MATCH($AE16,$H$14:$H$23,0)),-2)),SUMIFS(Dati!$B$2:$B$46,Dati!$A$2:$A$46,$H16,Dati!$H$2:$H$46,$AE16)+SUMIFS(Dati!$I$2:$I$46,Dati!$H$2:$H$46,$H16,Dati!$A$2:$A$46,$AE16),"-") -> - | AR16: =IF(AND($H16<>"",$AF16<>"",$H16<>$AF16,IFERROR(INDEX($J$14:$J$23,MATCH($H16,$H$14:$H$23,0)),-1)=IFERROR(INDEX($J$14:$J$23,MATCH($AF16,$H$14:$H$23,0)),-2)),SUMIFS(Dati!$B$2:$B$46,Dati!$A$2:$A$46,$H16,Dati!$H$2:$H$46,$AF16)+SUMIFS(Dati!$I$2:$I$46,Dati!$H$2:$H$46,$H16,Dati!$A$2:$A$46,$AF16),"-") -> 1 | AS16: =IF(AND($H16<>"",$AG16<>"",$H16<>$AG16,IFERROR(INDEX($J$14:$J$23,MATCH($H16,$H$14:$H$23,0)),-1)=IFERROR(INDEX($J$14:$J$23,MATCH($AG16,$H$14:$H$23,0)),-2)),SUMIFS(Dati!$B$2:$B$46,Dati!$A$2:$A$46,$H16,Dati!$H$2:$H$46,$AG16)+SUMIFS(Dati!$I$2:$I$46,Dati!$H$2:$H$46,$H16,Dati!$A$2:$A$46,$AG16),"-") -> - | AT16: =IF(AND($H16<>"",$AH16<>"",$H16<>$AH16,IFERROR(INDEX($J$14:$J$23,MATCH($H16,$H$14:$H$23,0)),-1)=IFERROR(INDEX($J$14:$J$23,MATCH($AH16,$H$14:$H$23,0)),-2)),SUMIFS(Dati!$B$2:$B$46,Dati!$A$2:$A$46,$H16,Dati!$H$2:$H$46,$AH16)+SUMIFS(Dati!$I$2:$I$46,Dati!$H$2:$H$46,$H16,Dati!$A$2:$A$46,$AH16),"-") -> - | AV16: =$C16 -> Cobra Celeri-Cobraopoli CI | AW16: =IF(AND($H16<>"",$Y16<>"",$H16<>$Y16,IFERROR(INDEX($J$14:$J$23,MATCH($H16,$H$14:$H$23,0)),-1)=IFERROR(INDEX($J$14:$J$23,MATCH($Y16,$H$14:$H$23,0)),-2)),SUMIFS(Dati!$D$2:$D$46,Dati!$A$2:$A$46,$H16,Dati!$H$2:$H$46,$Y16)+SUMIFS(Dati!$K$2:$K$46,Dati!$H$2:$H$46,$H16,Dati!$A$2:$A$46,$Y16)+SUMIFS(Dati!$C$2:$C$46,Dati!$A$2:$A$46,$H16,Dati!$H$2:$H$46,$Y16)+SUMIFS(Dati!$J$2:$J$46,Dati!$H$2:$H$46,$H16,Dati!$A$2:$A$46,$Y16),"-") -> - | AX16: =IF(AND($H16<>"",$Z16<>"",$H16<>$Z16,IFERROR(INDEX($J$14:$J$23,MATCH($H16,$H$14:$H$23,0)),-1)=IFERROR(INDEX($J$14:$J$23,MATCH($Z16,$H$14:$H$23,0)),-2)),SUMIFS(Dati!$D$2:$D$46,Dati!$A$2:$A$46,$H16,Dati!$H$2:$H$46,$Z16)+SUMIFS(Dati!$K$2:$K$46,Dati!$H$2:$H$46,$H16,Dati!$A$2:$A$46,$Z16)+SUMIFS(Dati!$C$2:$C$46,Dati!$A$2:$A$46,$H16,Dati!$H$2:$H$46,$Z16)+SUMIFS(Dati!$J$2:$J$46,Dati!$H$2:$H$46,$H16,Dati!$A$2:$A$46,$Z16),"-") -> - | AY16: =IF(AND($H16<>"",$AA16<>"",$H16<>$AA16,IFERROR(INDEX($J$14:$J$23,MATCH($H16,$H$14:$H$23,0)),-1)=IFERROR(INDEX($J$14:$J$23,MATCH($AA16,$H$14:$H$23,0)),-2)),SUMIFS(Dati!$D$2:$D$46,Dati!$A$2:$A$46,$H16,Dati!$H$2:$H$46,$AA16)+SUMIFS(Dati!$K$2:$K$46,Dati!$H$2:$H$46,$H16,Dati!$A$2:$A$46,$AA16)+SUMIFS(Dati!$C$2:$C$46,Dati!$A$2:$A$46,$H16,Dati!$H$2:$H$46,$AA16)+SUMIFS(Dati!$J$2:$J$46,Dati!$H$2:$H$46,$H16,Dati!$A$2:$A$46,$AA16),"-") -> - | AZ16: =IF(AND($H16<>"",$AB16<>"",$H16<>$AB16,IFERROR(INDEX($J$14:$J$23,MATCH($H16,$H$14:$H$23,0)),-1)=IFERROR(INDEX($J$14:$J$23,MATCH($AB16,$H$14:$H$23,0)),-2)),SUMIFS(Dati!$D$2:$D$46,Dati!$A$2:$A$46,$H16,Dati!$H$2:$H$46,$AB16)+SUMIFS(Dati!$K$2:$K$46,Dati!$H$2:$H$46,$H16,Dati!$A$2:$A$46,$AB16)+SUMIFS(Dati!$C$2:$C$46,Dati!$A$2:$A$46,$H16,Dati!$H$2:$H$46,$AB16)+SUMIFS(Dati!$J$2:$J$46,Dati!$H$2:$H$46,$H16,Dati!$A$2:$A$46,$AB16),"-") -> - | BA16: =IF(AND($H16<>"",$AC16<>"",$H16<>$AC16,IFERROR(INDEX($J$14:$J$23,MATCH($H16,$H$14:$H$23,0)),-1)=IFERROR(INDEX($J$14:$J$23,MATCH($AC16,$H$14:$H$23,0)),-2)),SUMIFS(Dati!$D$2:$D$46,Dati!$A$2:$A$46,$H16,Dati!$H$2:$H$46,$AC16)+SUMIFS(Dati!$K$2:$K$46,Dati!$H$2:$H$46,$H16,Dati!$A$2:$A$46,$AC16)+SUMIFS(Dati!$C$2:$C$46,Dati!$A$2:$A$46,$H16,Dati!$H$2:$H$46,$AC16)+SUMIFS(Dati!$J$2:$J$46,Dati!$H$2:$H$46,$H16,Dati!$A$2:$A$46,$AC16),"-") -> - | BB16: =IF(AND($H16<>"",$AD16<>"",$H16<>$AD16,IFERROR(INDEX($J$14:$J$23,MATCH($H16,$H$14:$H$23,0)),-1)=IFERROR(INDEX($J$14:$J$23,MATCH($AD16,$H$14:$H$23,0)),-2)),SUMIFS(Dati!$D$2:$D$46,Dati!$A$2:$A$46,$H16,Dati!$H$2:$H$46,$AD16)+SUMIFS(Dati!$K$2:$K$46,Dati!$H$2:$H$46,$H16,Dati!$A$2:$A$46,$AD16)+SUMIFS(Dati!$C$2:$C$46,Dati!$A$2:$A$46,$H16,Dati!$H$2:$H$46,$AD16)+SUMIFS(Dati!$J$2:$J$46,Dati!$H$2:$H$46,$H16,Dati!$A$2:$A$46,$AD16),"-") -> - | BC16: =IF(AND($H16<>"",$AE16<>"",$H16<>$AE16,IFERROR(INDEX($J$14:$J$23,MATCH($H16,$H$14:$H$23,0)),-1)=IFERROR(INDEX($J$14:$J$23,MATCH($AE16,$H$14:$H$23,0)),-2)),SUMIFS(Dati!$D$2:$D$46,Dati!$A$2:$A$46,$H16,Dati!$H$2:$H$46,$AE16)+SUMIFS(Dati!$K$2:$K$46,Dati!$H$2:$H$46,$H16,Dati!$A$2:$A$46,$AE16)+SUMIFS(Dati!$C$2:$C$46,Dati!$A$2:$A$46,$H16,Dati!$H$2:$H$46,$AE16)+SUMIFS(Dati!$J$2:$J$46,Dati!$H$2:$H$46,$H16,Dati!$A$2:$A$46,$AE16),"-") -> - | BD16: =IF(AND($H16<>"",$AF16<>"",$H16<>$AF16,IFERROR(INDEX($J$14:$J$23,MATCH($H16,$H$14:$H$23,0)),-1)=IFERROR(INDEX($J$14:$J$23,MATCH($AF16,$H$14:$H$23,0)),-2)),SUMIFS(Dati!$D$2:$D$46,Dati!$A$2:$A$46,$H16,Dati!$H$2:$H$46,$AF16)+SUMIFS(Dati!$K$2:$K$46,Dati!$H$2:$H$46,$H16,Dati!$A$2:$A$46,$AF16)+SUMIFS(Dati!$C$2:$C$46,Dati!$A$2:$A$46,$H16,Dati!$H$2:$H$46,$AF16)+SUMIFS(Dati!$J$2:$J$46,Dati!$H$2:$H$46,$H16,Dati!$A$2:$A$46,$AF16),"-") -> 0 | BE16: =IF(AND($H16<>"",$AG16<>"",$H16<>$AG16,IFERROR(INDEX($J$14:$J$23,MATCH($H16,$H$14:$H$23,0)),-1)=IFERROR(INDEX($J$14:$J$23,MATCH($AG16,$H$14:$H$23,0)),-2)),SUMIFS(Dati!$D$2:$D$46,Dati!$A$2:$A$46,$H16,Dati!$H$2:$H$46,$AG16)+SUMIFS(Dati!$K$2:$K$46,Dati!$H$2:$H$46,$H16,Dati!$A$2:$A$46,$AG16)+SUMIFS(Dati!$C$2:$C$46,Dati!$A$2:$A$46,$H16,Dati!$H$2:$H$46,$AG16)+SUMIFS(Dati!$J$2:$J$46,Dati!$H$2:$H$46,$H16,Dati!$A$2:$A$46,$AG16),"-") -> - | BF16: =IF(AND($H16<>"",$AH16<>"",$H16<>$AH16,IFERROR(INDEX($J$14:$J$23,MATCH($H16,$H$14:$H$23,0)),-1)=IFERROR(INDEX($J$14:$J$23,MATCH($AH16,$H$14:$H$23,0)),-2)),SUMIFS(Dati!$D$2:$D$46,Dati!$A$2:$A$46,$H16,Dati!$H$2:$H$46,$AH16)+SUMIFS(Dati!$K$2:$K$46,Dati!$H$2:$H$46,$H16,Dati!$A$2:$A$46,$AH16)+SUMIFS(Dati!$C$2:$C$46,Dati!$A$2:$A$46,$H16,Dati!$H$2:$H$46,$AH16)+SUMIFS(Dati!$J$2:$J$46,Dati!$H$2:$H$46,$H16,Dati!$A$2:$A$46,$AH16),"-") -> - | BH16: =$C16 -> Cobra Celeri-Cobraopoli CI | BI16: =IF(AND($H16<>"",$Y16<>"",$H16<>$Y16,IFERROR(INDEX($J$14:$J$23,MATCH($H16,$H$14:$H$23,0)),-1)=IFERROR(INDEX($J$14:$J$23,MATCH($Y16,$H$14:$H$23,0)),-2)),SUMIFS(Dati!$E$2:$E$46,Dati!$A$2:$A$46,$H16,Dati!$H$2:$H$46,$Y16)+SUMIFS(Dati!$L$2:$L$46,Dati!$H$2:$H$46,$H16,Dati!$A$2:$A$46,$Y16),"-") -> - | BJ16: =IF(AND($H16<>"",$Z16<>"",$H16<>$Z16,IFERROR(INDEX($J$14:$J$23,MATCH($H16,$H$14:$H$23,0)),-1)=IFERROR(INDEX($J$14:$J$23,MATCH($Z16,$H$14:$H$23,0)),-2)),SUMIFS(Dati!$E$2:$E$46,Dati!$A$2:$A$46,$H16,Dati!$H$2:$H$46,$Z16)+SUMIFS(Dati!$L$2:$L$46,Dati!$H$2:$H$46,$H16,Dati!$A$2:$A$46,$Z16),"-") -> - | BK16: =IF(AND($H16<>"",$AA16<>"",$H16<>$AA16,IFERROR(INDEX($J$14:$J$23,MATCH($H16,$H$14:$H$23,0)),-1)=IFERROR(INDEX($J$14:$J$23,MATCH($AA16,$H$14:$H$23,0)),-2)),SUMIFS(Dati!$E$2:$E$46,Dati!$A$2:$A$46,$H16,Dati!$H$2:$H$46,$AA16)+SUMIFS(Dati!$L$2:$L$46,Dati!$H$2:$H$46,$H16,Dati!$A$2:$A$46,$AA16),"-") -> - | BL16: =IF(AND($H16<>"",$AB16<>"",$H16<>$AB16,IFERROR(INDEX($J$14:$J$23,MATCH($H16,$H$14:$H$23,0)),-1)=IFERROR(INDEX($J$14:$J$23,MATCH($AB16,$H$14:$H$23,0)),-2)),SUMIFS(Dati!$E$2:$E$46,Dati!$A$2:$A$46,$H16,Dati!$H$2:$H$46,$AB16)+SUMIFS(Dati!$L$2:$L$46,Dati!$H$2:$H$46,$H16,Dati!$A$2:$A$46,$AB16),"-") -> - | BM16: =IF(AND($H16<>"",$AC16<>"",$H16<>$AC16,IFERROR(INDEX($J$14:$J$23,MATCH($H16,$H$14:$H$23,0)),-1)=IFERROR(INDEX($J$14:$J$23,MATCH($AC16,$H$14:$H$23,0)),-2)),SUMIFS(Dati!$E$2:$E$46,Dati!$A$2:$A$46,$H16,Dati!$H$2:$H$46,$AC16)+SUMIFS(Dati!$L$2:$L$46,Dati!$H$2:$H$46,$H16,Dati!$A$2:$A$46,$AC16),"-") -> - | BN16: =IF(AND($H16<>"",$AD16<>"",$H16<>$AD16,IFERROR(INDEX($J$14:$J$23,MATCH($H16,$H$14:$H$23,0)),-1)=IFERROR(INDEX($J$14:$J$23,MATCH($AD16,$H$14:$H$23,0)),-2)),SUMIFS(Dati!$E$2:$E$46,Dati!$A$2:$A$46,$H16,Dati!$H$2:$H$46,$AD16)+SUMIFS(Dati!$L$2:$L$46,Dati!$H$2:$H$46,$H16,Dati!$A$2:$A$46,$AD16),"-") -> - | BO16: =IF(AND($H16<>"",$AE16<>"",$H16<>$AE16,IFERROR(INDEX($J$14:$J$23,MATCH($H16,$H$14:$H$23,0)),-1)=IFERROR(INDEX($J$14:$J$23,MATCH($AE16,$H$14:$H$23,0)),-2)),SUMIFS(Dati!$E$2:$E$46,Dati!$A$2:$A$46,$H16,Dati!$H$2:$H$46,$AE16)+SUMIFS(Dati!$L$2:$L$46,Dati!$H$2:$H$46,$H16,Dati!$A$2:$A$46,$AE16),"-") -> - | BP16: =IF(AND($H16<>"",$AF16<>"",$H16<>$AF16,IFERROR(INDEX($J$14:$J$23,MATCH($H16,$H$14:$H$23,0)),-1)=IFERROR(INDEX($J$14:$J$23,MATCH($AF16,$H$14:$H$23,0)),-2)),SUMIFS(Dati!$E$2:$E$46,Dati!$A$2:$A$46,$H16,Dati!$H$2:$H$46,$AF16)+SUMIFS(Dati!$L$2:$L$46,Dati!$H$2:$H$46,$H16,Dati!$A$2:$A$46,$AF16),"-") -> 58 | BQ16: =IF(AND($H16<>"",$AG16<>"",$H16<>$AG16,IFERROR(INDEX($J$14:$J$23,MATCH($H16,$H$14:$H$23,0)),-1)=IFERROR(INDEX($J$14:$J$23,MATCH($AG16,$H$14:$H$23,0)),-2)),SUMIFS(Dati!$E$2:$E$46,Dati!$A$2:$A$46,$H16,Dati!$H$2:$H$46,$AG16)+SUMIFS(Dati!$L$2:$L$46,Dati!$H$2:$H$46,$H16,Dati!$A$2:$A$46,$AG16),"-") -> - | BR16: =IF(AND($H16<>"",$AH16<>"",$H16<>$AH16,IFERROR(INDEX($J$14:$J$23,MATCH($H16,$H$14:$H$23,0)),-1)=IFERROR(INDEX($J$14:$J$23,MATCH($AH16,$H$14:$H$23,0)),-2)),SUMIFS(Dati!$E$2:$E$46,Dati!$A$2:$A$46,$H16,Dati!$H$2:$H$46,$AH16)+SUMIFS(Dati!$L$2:$L$46,Dati!$H$2:$H$46,$H16,Dati!$A$2:$A$46,$AH16),"-") -> - | BT16: =$C16 -> Cobra Celeri-Cobraopoli CI | BU16: =IF(AND($H16<>"",$Y16<>"",$H16<>$Y16,IFERROR(INDEX($J$14:$J$23,MATCH($H16,$H$14:$H$23,0)),-1)=IFERROR(INDEX($J$14:$J$23,MATCH($Y16,$H$14:$H$23,0)),-2)),SUMIFS(Dati!$F$2:$F$46,Dati!$A$2:$A$46,$H16,Dati!$H$2:$H$46,$Y16)+SUMIFS(Dati!$M$2:$M$46,Dati!$H$2:$H$46,$H16,Dati!$A$2:$A$46,$Y16),"-") -> - | BV16: =IF(AND($H16<>"",$Z16<>"",$H16<>$Z16,IFERROR(INDEX($J$14:$J$23,MATCH($H16,$H$14:$H$23,0)),-1)=IFERROR(INDEX($J$14:$J$23,MATCH($Z16,$H$14:$H$23,0)),-2)),SUMIFS(Dati!$F$2:$F$46,Dati!$A$2:$A$46,$H16,Dati!$H$2:$H$46,$Z16)+SUMIFS(Dati!$M$2:$M$46,Dati!$H$2:$H$46,$H16,Dati!$A$2:$A$46,$Z16),"-") -> - | BW16: =IF(AND($H16<>"",$AA16<>"",$H16<>$AA16,IFERROR(INDEX($J$14:$J$23,MATCH($H16,$H$14:$H$23,0)),-1)=IFERROR(INDEX($J$14:$J$23,MATCH($AA16,$H$14:$H$23,0)),-2)),SUMIFS(Dati!$F$2:$F$46,Dati!$A$2:$A$46,$H16,Dati!$H$2:$H$46,$AA16)+SUMIFS(Dati!$M$2:$M$46,Dati!$H$2:$H$46,$H16,Dati!$A$2:$A$46,$AA16),"-") -> - | BX16: =IF(AND($H16<>"",$AB16<>"",$H16<>$AB16,IFERROR(INDEX($J$14:$J$23,MATCH($H16,$H$14:$H$23,0)),-1)=IFERROR(INDEX($J$14:$J$23,MATCH($AB16,$H$14:$H$23,0)),-2)),SUMIFS(Dati!$F$2:$F$46,Dati!$A$2:$A$46,$H16,Dati!$H$2:$H$46,$AB16)+SUMIFS(Dati!$M$2:$M$46,Dati!$H$2:$H$46,$H16,Dati!$A$2:$A$46,$AB16),"-") -> - | BY16: =IF(AND($H16<>"",$AC16<>"",$H16<>$AC16,IFERROR(INDEX($J$14:$J$23,MATCH($H16,$H$14:$H$23,0)),-1)=IFERROR(INDEX($J$14:$J$23,MATCH($AC16,$H$14:$H$23,0)),-2)),SUMIFS(Dati!$F$2:$F$46,Dati!$A$2:$A$46,$H16,Dati!$H$2:$H$46,$AC16)+SUMIFS(Dati!$M$2:$M$46,Dati!$H$2:$H$46,$H16,Dati!$A$2:$A$46,$AC16),"-") -> - | BZ16: =IF(AND($H16<>"",$AD16<>"",$H16<>$AD16,IFERROR(INDEX($J$14:$J$23,MATCH($H16,$H$14:$H$23,0)),-1)=IFERROR(INDEX($J$14:$J$23,MATCH($AD16,$H$14:$H$23,0)),-2)),SUMIFS(Dati!$F$2:$F$46,Dati!$A$2:$A$46,$H16,Dati!$H$2:$H$46,$AD16)+SUMIFS(Dati!$M$2:$M$46,Dati!$H$2:$H$46,$H16,Dati!$A$2:$A$46,$AD16),"-") -> - | CA16: =IF(AND($H16<>"",$AE16<>"",$H16<>$AE16,IFERROR(INDEX($J$14:$J$23,MATCH($H16,$H$14:$H$23,0)),-1)=IFERROR(INDEX($J$14:$J$23,MATCH($AE16,$H$14:$H$23,0)),-2)),SUMIFS(Dati!$F$2:$F$46,Dati!$A$2:$A$46,$H16,Dati!$H$2:$H$46,$AE16)+SUMIFS(Dati!$M$2:$M$46,Dati!$H$2:$H$46,$H16,Dati!$A$2:$A$46,$AE16),"-") -> - | CB16: =IF(AND($H16<>"",$AF16<>"",$H16<>$AF16,IFERROR(INDEX($J$14:$J$23,MATCH($H16,$H$14:$H$23,0)),-1)=IFERROR(INDEX($J$14:$J$23,MATCH($AF16,$H$14:$H$23,0)),-2)),SUMIFS(Dati!$F$2:$F$46,Dati!$A$2:$A$46,$H16,Dati!$H$2:$H$46,$AF16)+SUMIFS(Dati!$M$2:$M$46,Dati!$H$2:$H$46,$H16,Dati!$A$2:$A$46,$AF16),"-") -> 51 | CC16: =IF(AND($H16<>"",$AG16<>"",$H16<>$AG16,IFERROR(INDEX($J$14:$J$23,MATCH($H16,$H$14:$H$23,0)),-1)=IFERROR(INDEX($J$14:$J$23,MATCH($AG16,$H$14:$H$23,0)),-2)),SUMIFS(Dati!$F$2:$F$46,Dati!$A$2:$A$46,$H16,Dati!$H$2:$H$46,$AG16)+SUMIFS(Dati!$M$2:$M$46,Dati!$H$2:$H$46,$H16,Dati!$A$2:$A$46,$AG16),"-") -> - | CD16: =IF(AND($H16<>"",$AH16<>"",$H16<>$AH16,IFERROR(INDEX($J$14:$J$23,MATCH($H16,$H$14:$H$23,0)),-1)=IFERROR(INDEX($J$14:$J$23,MATCH($AH16,$H$14:$H$23,0)),-2)),SUMIFS(Dati!$F$2:$F$46,Dati!$A$2:$A$46,$H16,Dati!$H$2:$H$46,$AH16)+SUMIFS(Dati!$M$2:$M$46,Dati!$H$2:$H$46,$H16,Dati!$A$2:$A$46,$AH16),"-") -> - | CF16: =IF($C16="","",SUM(AK16:AT16)) -> 1
