Workbook
Name constNomeCampionato: Campionato!$D$2
Name constGironi: Campionato!$D$5
Name constNomiGironi: Campionato!$D$11
Name constLogo1: Campionato!$D$3
Name constLogo2: Campionato!$D$4
Name constSezioneCampionato: Campionato!$D$5
Name constStagionaCampionato: Campionato!$D$6
Name constPuntiVittoria: Campionato!$D$7
Name constPuntiSconfitta: Campionato!$D$8
Name constPuntiForfait: Campionato!$D$9
Name constPunteggioForfait: Campionato!$D$10
Name areaNomiSquadre: Campionato!$B$14:$C$53
Name areaNomiBreviSquadre: Campionato!$B$14:$H$53
Name areaCoefficienteSquadre: Campionato!$I$14:$I$53
Name areaCercaPuntiClassificaSquadra: Campionato!$H$14:$J$53
Name areaCercaDatiPerPosizioneSquadre: Campionato!$G$14:$W$53
Name areaCampiSquadre: Campionato!$B$57:$D$105
Name ARBITRI: Arbitri!$D$5:$D$304
Name UDC: UdC!$D$5:$D$304
Name areaSquadraACalendario: 'Calendario A'!$M$8:$M$615
Name areaVintaACalendario: 'Calendario A'!$N$8:$N$615
Name areaForfaitACalendario: 'Calendario A'!$O$8:$O$615
Name areaPersaACalendario: 'Calendario A'!$P$8:$P$615
Name areaPuntiFattiACalendario: 'Calendario A'!$Q$8:$Q$615
Name areaPuntiSubitiACalendario: 'Calendario A'!$R$8:$R$615
Name areaDifferenzaPuntiACalendario: 'Calendario A'!$S$8:$S$615
Name areaSquadraBCalendario: 'Calendario A'!$T$8:$T$615
Name areaVintaBCalendario: 'Calendario A'!$U$8:$U$615
Name areaForfaitBCalendario: 'Calendario A'!$V$8:$V$615
Name areaPersaBCalendario: 'Calendario A'!$W$8:$W$615
Name areaPuntiFattiBCalendario: 'Calendario A'!$X$8:$X$615
Name areaPuntiSubitiBCalendario: 'Calendario A'!$Y$8:$Y$615
Name areaDifferenzaPuntiBCalendario: 'Calendario A'!$Z$8:$Z$615
Name areaSquadraACalendario: 'Calendario B'!$M$8:$M$615
Name areaVintaACalendario: 'Calendario B'!$N$8:$N$615
Name areaForfaitACalendario: 'Calendario B'!$O$8:$O$615
Name areaPersaACalendario: 'Calendario B'!$P$8:$P$615
Name areaPuntiFattiACalendario: 'Calendario B'!$Q$8:$Q$615
Name areaPuntiSubitiACalendario: 'Calendario B'!$R$8:$R$615
Name areaDifferenzaPuntiACalendario: 'Calendario B'!$S$8:$S$615
Name areaSquadraBCalendario: 'Calendario B'!$T$8:$T$615
Name areaVintaBCalendario: 'Calendario B'!$U$8:$U$615
Name areaForfaitBCalendario: 'Calendario B'!$V$8:$V$615
Name areaPersaBCalendario: 'Calendario B'!$W$8:$W$615
Name areaPuntiFattiBCalendario: 'Calendario B'!$X$8:$X$615
Name areaPuntiSubitiBCalendario: 'Calendario B'!$Y$8:$Y$615
Name areaDifferenzaPuntiBCalendario: 'Calendario B'!$Z$8:$Z$615
Name areaSquadraACalendario: Playoff!$M$8:$M$63
Name areaVintaACalendario: Playoff!$N$8:$N$63
Name areaForfaitACalendario: Playoff!$O$8:$O$63
Name areaPersaACalendario: Playoff!$P$8:$P$63
Name areaPuntiFattiACalendario: Playoff!$Q$8:$Q$63
Name areaPuntiSubitiACalendario: Playoff!$R$8:$R$63
Name areaDifferenzaPuntiACalendario: Playoff!$S$8:$S$63
Name areaSquadraBCalendario: Playoff!$T$8:$T$63
Name areaVintaBCalendario: Playoff!$U$8:$U$63
Name areaForfaitBCalendario: Playoff!$V$8:$V$63
Name areaPersaBCalendario: Playoff!$W$8:$W$63
Name areaPuntiFattiBCalendario: Playoff!$X$8:$X$63
Name areaPuntiSubitiBCalendario: Playoff!$Y$8:$Y$63

Sheet Campionato
B1: PARAMETRI
B2: Campionato | D2: Campionato Baskin Demo - ESEMPIO 40 Squadre
B3: Link Logo 1
B4: Link Logo 2
B5: Gironi (separati da virgola) | D5: A,B
B6: Stagione | D6: 2026/2027
B7: Punti vittoria | D7: 3
B8: Punti sconfitta | D8: 1
B9: Punti forfait | D9: 0
B10: Punteggio forfait (vincente-perdente, separati da "-") | D10: 40-0
B11: Nomi gironi per la stampa (stesso ordine, separati da virgola) | D11: Gold,Silver
B12: SQUADRE | Y12: Squadre del girone (in ordine di inserimento) | AT12: Squadra | AU12: Vittorie Scontri Diretti | BP12: Squadra | BQ12: Sconfitte & Forfait Scontri Diretti | CL12: Squadra | CM12: Punti Fatti Scontri Diretti | DH12: Squadra | DI12: Punti Subiti Scontri Diretti
B13: # | C13: Squadra | D13: Eventuali Punti di Penalizzazione | E13: Girone | G13: Posizione | H13: Squadra | I13: Coefficiente | J13: Punti Classifica | K13: Partite Giocate | L13: Partite Vinte | M13: Partite Perse | N13: Partite Forfait | O13: Punti Fatti | P13: Punti Subiti | Q13: Differenza Punti | R13: Media Punti Fatti | S13: Media Punti Subiti | T13: Media Differenza Punti | U13: Record Scontri Diretti | V13: Quoziente Canestri Scontri Diretti | W13: Quoziente Canestri Totale | X13: Chiave girone | Y13: 1^ | Z13: 2^ | AA13: 3^ | AB13: 4^ | AC13: 5^ | AD13: 6^ | AE13: 7^ | AF13: 8^ | AG13: 9^ | AH13: 10^ | AI13: 11^ | AJ13: 12^ | AK13: 13^ | AL13: 14^ | AM13: 15^ | AN13: 16^ | AO13: 17^ | AP13: 18^ | AQ13: 19^ | AR13: 20^ | AT13: Squadra | AU13: 1^ | AV13: 2^ | AW13: 3^ | AX13: 4^ | AY13: 5^ | AZ13: 6^ | BA13: 7^ | BB13: 8^ | BC13: 9^ | BD13: 10^ | BE13: 11^ | BF13: 12^ | BG13: 13^ | BH13: 14^ | BI13: 15^ | BJ13: 16^ | BK13: 17^ | BL13: 18^ | BM13: 19^ | BN13: 20^ | BP13: Squadra | BQ13: 1^ | BR13: 2^ | BS13: 3^ | BT13: 4^ | BU13: 5^ | BV13: 6^ | BW13: 7^ | BX13: 8^ | BY13: 9^ | BZ13: 10^ | CA13: 11^ | CB13: 12^ | CC13: 13^ | CD13: 14^ | CE13: 15^ | CF13: 16^ | CG13: 17^ | CH13: 18^ | CI13: 19^ | CJ13: 20^ | CL13: Squadra | CM13: 1^ | CN13: 2^ | CO13: 3^ | CP13: 4^ | CQ13: 5^ | CR13: 6^ | CS13: 7^ | CT13: 8^ | CU13: 9^ | CV13: 10^ | CW13: 11^ | CX13: 12^ | CY13: 13^ | CZ13: 14^ | DA13: 15^ | DB13: 16^ | DC13: 17^ | DD13: 18^ | DE13: 19^ | DF13: 20^ | DH13: Squadra | DI13: 1^ | DJ13: 2^ | DK13: 3^ | DL13: 4^ | DM13: 5^ | DN13: 6^ | DO13: 7^ | DP13: 8^ | DQ13: 9^ | DR13: 10^ | DS13: 11^ | DT13: 12^ | DU13: 13^ | DV13: 14^ | DW13: 15^ | DX13: 16^ | DY13: 17^ | DZ13: 18^ | EA13: 19^ | EB13: 20^ | ED13: Vittorie SD
B14: A01 | C14: Anaconde Audaci-Anacondeopoli AA | E14: A | G14: =IF($C14="","",$E14&(COUNTIFS(I$14:I$53,">"&I14,E$14:E$53,"="&E14,C$14:C$53,"<>")+COUNTIFS(I$14:I$53,"="&I14,H$14:H$53,"<="&H14,E$14:E$53,"="&E14,C$14:C$53,"<>"))) | H14: =IF($C14="","",IFERROR(LEFT($C14,FIND("-",$C14)-1),$C14)) | I14: =TEXT(1000000000+J14,"|0000000000|")&TEXT(SUM(AU14:BN14),"0000000000|")&IF(SUM(DI14:EB14)=0,"0000000000|",TEXT(ROUND(SUM(CM14:DF14)/SUM(DI14:EB14),4)*100000,"0000000000|"))&IF(P14=0,"0000000000|",TEXT(ROUND(O14/P14,4)*100000,"0000000000|")) | J14: =L14*constPuntiVittoria+M14*constPuntiSconfitta+N14*constPuntiForfait+IF(D14="",0,D14) | K14: =SUM(L14:N14) | L14: =IF($H14="",0,SUMIF(Dati!$A$2:$A$381,$H14,Dati!$B$2:$B$381)+SUMIF(Dati!$H$2:$H$381,$H14,Dati!$I$2:$I$381)) | M14: =IF($H14="",0,SUMIF(Dati!$A$2:$A$381,$H14,Dati!$D$2:$D$381)+SUMIF(Dati!$H$2:$H$381,$H14,Dati!$K$2:$K$381)) | N14: =IF($H14="",0,SUMIF(Dati!$A$2:$A$381,$H14,Dati!$C$2:$C$381)+SUMIF(Dati!$H$2:$H$381,$H14,Dati!$J$2:$J$381)) | O14: =IF($H14="",0,SUMIF(Dati!$A$2:$A$381,$H14,Dati!$E$2:$E$381)+SUMIF(Dati!$H$2:$H$381,$H14,Dati!$L$2:$L$381)) | P14: =IF($H14="",0,SUMIF(Dati!$A$2:$A$381,$H14,Dati!$F$2:$F$381)+SUMIF(Dati!$H$2:$H$381,$H14,Dati!$M$2:$M$381)) | Q14: =IF($H14="",0,SUMIF(Dati!$A$2:$A$381,$H14,Dati!$G$2:$G$381)+SUMIF(Dati!$H$2:$H$381,$H14,Dati!$N$2:$N$381)) | R14: =IF(K14=0,0,ROUND(O14/K14,2)) | S14: =IF(K14=0,0,ROUND(P14/K14,2)) | T14: =IF(K14=0,0,ROUND(Q14/K14,2)) | U14: =IF(COUNTIFS($E$14:$E$53,$E14,$J$14:$J$53,$J14,$C$14:$C$53,"<>")<=1,"-",SUM(AU14:BN14)&"-"&SUM(BQ14:CJ14)) | V14: =IF(COUNTIFS($E$14:$E$53,$E14,$J$14:$J$53,$J14,$C$14:$C$53,"<>",$ED$14:$ED$53,$ED14)<=1,"-",IF(SUM(DI14:EB14)=0,0,ROUND(SUM(CM14:DF14)/SUM(DI14:EB14),3))) | W14: =IF(COUNTIFS($E$14:$E$53,$E14,$J$14:$J$53,$J14,$C$14:$C$53,"<>",$ED$14:$ED$53,$ED14,$V$14:$V$53,$V14)<=1,"-",IF(P14=0,0,ROUND(O14/P14,3))) | X14: =IF($C14="","",$E14&"#"&COUNTIFS($E$14:$E14,$E14,$C$14:$C14,"<>")) | Y14: =IFERROR(INDEX($H$14:$H$53,MATCH($E14&"#1",$X$14:$X$53,0)),"") | Z14: =IFERROR(INDEX($H$14:$H$53,MATCH($E14&"#2",$X$14:$X$53,0)),"") | AA14: =IFERROR(INDEX($H$14:$H$53,MATCH($E14&"#3",$X$14:$X$53,0)),"") | AB14: =IFERROR(INDEX($H$14:$H$53,MATCH($E14&"#4",$X$14:$X$53,0)),"") | AC14: =IFERROR(INDEX($H$14:$H$53,MATCH($E14&"#5",$X$14:$X$53,0)),"") | AD14: =IFERROR(INDEX($H$14:$H$53,MATCH($E14&"#6",$X$14:$X$53,0)),"") | AE14: =IFERROR(INDEX($H$14:$H$53,MATCH($E14&"#7",$X$14:$X$53,0)),"") | AF14: =IFERROR(INDEX($H$14:$H$53,MATCH($E14&"#8",$X$14:$X$53,0)),"") | AG14: =IFERROR(INDEX($H$14:$H$53,MATCH($E14&"#9",$X$14:$X$53,0)),"") | AH14: =IFERROR(INDEX($H$14:$H$53,MATCH($E14&"#10",$X$14:$X$53,0)),"") | AI14: =IFERROR(INDEX($H$14:$H$53,MATCH($E14&"#11",$X$14:$X$53,0)),"") | AJ14: =IFERROR(INDEX($H$14:$H$53,MATCH($E14&"#12",$X$14:$X$53,0)),"") | AK14: =IFERROR(INDEX($H$14:$H$53,MATCH($E14&"#13",$X$14:$X$53,0)),"") | AL14: =IFERROR(INDEX($H$14:$H$53,MATCH($E14&"#14",$X$14:$X$53,0)),"") | AM14: =IFERROR(INDEX($H$14:$H$53,MATCH($E14&"#15",$X$14:$X$53,0)),"") | AN14: =IFERROR(INDEX($H$14:$H$53,MATCH($E14&"#16",$X$14:$X$53,0)),"") | AO14: =IFERROR(INDEX($H$14:$H$53,MATCH($E14&"#17",$X$14:$X$53,0)),"") | AP14: =IFERROR(INDEX($H$14:$H$53,MATCH($E14&"#18",$X$14:$X$53,0)),"") | AQ14: =IFERROR(INDEX($H$14:$H$53,MATCH($E14&"#19",$X$14:$X$53,0)),"") | AR14: =IFERROR(INDEX($H$14:$H$53,MATCH($E14&"#20",$X$14:$X$53,0)),"") | AT14: =$C14 | AU14: =IF(AND($H14<>"",$Y14<>"",$H14<>$Y14,IFERROR(VLOOKUP($H14,areaCercaPuntiClassificaSquadra,3,FALSE),-1)=IFERROR(VLOOKUP($Y14,areaCercaPuntiClassificaSquadra,3,FALSE),-2)),SUMIFS(Dati!$B$2:$B$381,Dati!$A$2:$A$381,$H14,Dati!$H$2:$H$381,$Y14)+SUMIFS(Dati!$I$2:$I$381,Dati!$H$2:$H$381,$H14,Dati!$A$2:$A$381,$Y14),"-") | AV14: =IF(AND($H14<>"",$Z14<>"",$H14<>$Z14,IFERROR(VLOOKUP($H14,areaCercaPuntiClassificaSquadra,3,FALSE),-1)=IFERROR(VLOOKUP($Z14,areaCercaPuntiClassificaSquadra,3,FALSE),-2)),SUMIFS(Dati!$B$2:$B$381,Dati!$A$2:$A$381,$H14,Dati!$H$2:$H$381,$Z14)+SUMIFS(Dati!$I$2:$I$381,Dati!$H$2:$H$381,$H14,Dati!$A$2:$A$381,$Z14),"-") | AW14: =IF(AND($H14<>"",$AA14<>"",$H14<>$AA14,IFERROR(VLOOKUP($H14,areaCercaPuntiClassificaSquadra,3,FALSE),-1)=IFERROR(VLOOKUP($AA14,areaCercaPuntiClassificaSquadra,3,FALSE),-2)),SUMIFS(Dati!$B$2:$B$381,Dati!$A$2:$A$381,$H14,Dati!$H$2:$H$381,$AA14)+SUMIFS(Dati!$I$2:$I$381,Dati!$H$2:$H$381,$H14,Dati!$A$2:$A$381,$AA14),"-") | AX14: =IF(AND($H14<>"",$AB14<>"",$H14<>$AB14,IFERROR(VLOOKUP($H14,areaCercaPuntiClassificaSquadra,3,FALSE),-1)=IFERROR(VLOOKUP($AB14,areaCercaPuntiClassificaSquadra,3,FALSE),-2)),SUMIFS(Dati!$B$2:$B$381,Dati!$A$2:$A$381,$H14,Dati!$H$2:$H$381,$AB14)+SUMIFS(Dati!$I$2:$I$381,Dati!$H$2:$H$381,$H14,Dati!$A$2:$A$381,$AB14),"-") | AY14: =IF(AND($H14<>"",$AC14<>"",$H14<>$AC14,IFERROR(VLOOKUP($H14,areaCercaPuntiClassificaSquadra,3,FALSE),-1)=IFERROR(VLOOKUP($AC14,areaCercaPuntiClassificaSquadra,3,FALSE),-2)),SUMIFS(Dati!$B$2:$B$381,Dati!$A$2:$A$381,$H14,Dati!$H$2:$H$381,$AC14)+SUMIFS(Dati!$I$2:$I$381,Dati!$H$2:$H$381,$H14,Dati!$A$2:$A$381,$AC14),"-") | AZ14: =IF(AND($H14<>"",$AD14<>"",$H14<>$AD14,IFERROR(VLOOKUP($H14,areaCercaPuntiClassificaSquadra,3,FALSE),-1)=IFERROR(VLOOKUP($AD14,areaCercaPuntiClassificaSquadra,3,FALSE),-2)),SUMIFS(Dati!$B$2:$B$381,Dati!$A$2:$A$381,$H14,Dati!$H$2:$H$381,$AD14)+SUMIFS(Dati!$I$2:$I$381,Dati!$H$2:$H$381,$H14,Dati!$A$2:$A$381,$AD14),"-") | BA14: =IF(AND($H14<>"",$AE14<>"",$H14<>$AE14,IFERROR(VLOOKUP($H14,areaCercaPuntiClassificaSquadra,3,FALSE),-1)=IFERROR(VLOOKUP($AE14,areaCercaPuntiClassificaSquadra,3,FALSE),-2)),SUMIFS(Dati!$B$2:$B$381,Dati!$A$2:$A$381,$H14,Dati!$H$2:$H$381,$AE14)+SUMIFS(Dati!$I$2:$I$381,Dati!$H$2:$H$381,$H14,Dati!$A$2:$A$381,$AE14),"-") | BB14: =IF(AND($H14<>"",$AF14<>"",$H14<>$AF14,IFERROR(VLOOKUP($H14,areaCercaPuntiClassificaSquadra,3,FALSE),-1)=IFERROR(VLOOKUP($AF14,areaCercaPuntiClassificaSquadra,3,FALSE),-2)),SUMIFS(Dati!$B$2:$B$381,Dati!$A$2:$A$381,$H14,Dati!$H$2:$H$381,$AF14)+SUMIFS(Dati!$I$2:$I$381,Dati!$H$2:$H$381,$H14,Dati!$A$2:$A$381,$AF14),"-") | BC14: =IF(AND($H14<>"",$AG14<>"",$H14<>$AG14,IFERROR(VLOOKUP($H14,areaCercaPuntiClassificaSquadra,3,FALSE),-1)=IFERROR(VLOOKUP($AG14,areaCercaPuntiClassificaSquadra,3,FALSE),-2)),SUMIFS(Dati!$B$2:$B$381,Dati!$A$2:$A$381,$H14,Dati!$H$2:$H$381,$AG14)+SUMIFS(Dati!$I$2:$I$381,Dati!$H$2:$H$381,$H14,Dati!$A$2:$A$381,$AG14),"-") | BD14: =IF(AND($H14<>"",$AH14<>"",$H14<>$AH14,IFERROR(VLOOKUP($H14,areaCercaPuntiClassificaSquadra,3,FALSE),-1)=IFERROR(VLOOKUP($AH14,areaCercaPuntiClassificaSquadra,3,FALSE),-2)),SUMIFS(Dati!$B$2:$B$381,Dati!$A$2:$A$381,$H14,Dati!$H$2:$H$381,$AH14)+SUMIFS(Dati!$I$2:$I$381,Dati!$H$2:$H$381,$H14,Dati!$A$2:$A$381,$AH14),"-") | BE14: =IF(AND($H14<>"",$AI14<>"",$H14<>$AI14,IFERROR(VLOOKUP($H14,areaCercaPuntiClassificaSquadra,3,FALSE),-1)=IFERROR(VLOOKUP($AI14,areaCercaPuntiClassificaSquadra,3,FALSE),-2)),SUMIFS(Dati!$B$2:$B$381,Dati!$A$2:$A$381,$H14,Dati!$H$2:$H$381,$AI14)+SUMIFS(Dati!$I$2:$I$381,Dati!$H$2:$H$381,$H14,Dati!$A$2:$A$381,$AI14),"-") | BF14: =IF(AND($H14<>"",$AJ14<>"",$H14<>$AJ14,IFERROR(VLOOKUP($H14,areaCercaPuntiClassificaSquadra,3,FALSE),-1)=IFERROR(VLOOKUP($AJ14,areaCercaPuntiClassificaSquadra,3,FALSE),-2)),SUMIFS(Dati!$B$2:$B$381,Dati!$A$2:$A$381,$H14,Dati!$H$2:$H$381,$AJ14)+SUMIFS(Dati!$I$2:$I$381,Dati!$H$2:$H$381,$H14,Dati!$A$2:$A$381,$AJ14),"-") | BG14: =IF(AND($H14<>"",$AK14<>"",$H14<>$AK14,IFERROR(VLOOKUP($H14,areaCercaPuntiClassificaSquadra,3,FALSE),-1)=IFERROR(VLOOKUP($AK14,areaCercaPuntiClassificaSquadra,3,FALSE),-2)),SUMIFS(Dati!$B$2:$B$381,Dati!$A$2:$A$381,$H14,Dati!$H$2:$H$381,$AK14)+SUMIFS(Dati!$I$2:$I$381,Dati!$H$2:$H$381,$H14,Dati!$A$2:$A$381,$AK14),"-") | BH14: =IF(AND($H14<>"",$AL14<>"",$H14<>$AL14,IFERROR(VLOOKUP($H14,areaCercaPuntiClassificaSquadra,3,FALSE),-1)=IFERROR(VLOOKUP($AL14,areaCercaPuntiClassificaSquadra,3,FALSE),-2)),SUMIFS(Dati!$B$2:$B$381,Dati!$A$2:$A$381,$H14,Dati!$H$2:$H$381,$AL14)+SUMIFS(Dati!$I$2:$I$381,Dati!$H$2:$H$381,$H14,Dati!$A$2:$A$381,$AL14),"-") | BI14: =IF(AND($H14<>"",$AM14<>"",$H14<>$AM14,IFERROR(VLOOKUP($H14,areaCercaPuntiClassificaSquadra,3,FALSE),-1)=IFERROR(VLOOKUP($AM14,areaCercaPuntiClassificaSquadra,3,FALSE),-2)),SUMIFS(Dati!$B$2:$B$381,Dati!$A$2:$A$381,$H14,Dati!$H$2:$H$381,$AM14)+SUMIFS(Dati!$I$2:$I$381,Dati!$H$2:$H$381,$H14,Dati!$A$2:$A$381,$AM14),"-") | BJ14: =IF(AND($H14<>"",$AN14<>"",$H14<>$AN14,IFERROR(VLOOKUP($H14,areaCercaPuntiClassificaSquadra,3,FALSE),-1)=IFERROR(VLOOKUP($AN14,areaCercaPuntiClassificaSquadra,3,FALSE),-2)),SUMIFS(Dati!$B$2:$B$381,Dati!$A$2:$A$381,$H14,Dati!$H$2:$H$381,$AN14)+SUMIFS(Dati!$I$2:$I$381,Dati!$H$2:$H$381,$H14,Dati!$A$2:$A$381,$AN14),"-") | BK14: =IF(AND($H14<>"",$AO14<>"",$H14<>$AO14,IFERROR(VLOOKUP($H14,areaCercaPuntiClassificaSquadra,3,FALSE),-1)=IFERROR(VLOOKUP($AO14,areaCercaPuntiClassificaSquadra,3,FALSE),-2)),SUMIFS(Dati!$B$2:$B$381,Dati!$A$2:$A$381,$H14,Dati!$H$2:$H$381,$AO14)+SUMIFS(Dati!$I$2:$I$381,Dati!$H$2:$H$381,$H14,Dati!$A$2:$A$381,$AO14),"-") | BL14: =IF(AND($H14<>"",$AP14<>"",$H14<>$AP14,IFERROR(VLOOKUP($H14,areaCercaPuntiClassificaSquadra,3,FALSE),-1)=IFERROR(VLOOKUP($AP14,areaCercaPuntiClassificaSquadra,3,FALSE),-2)),SUMIFS(Dati!$B$2:$B$381,Dati!$A$2:$A$381,$H14,Dati!$H$2:$H$381,$AP14)+SUMIFS(Dati!$I$2:$I$381,Dati!$H$2:$H$381,$H14,Dati!$A$2:$A$381,$AP14),"-") | BM14: =IF(AND($H14<>"",$AQ14<>"",$H14<>$AQ14,IFERROR(VLOOKUP($H14,areaCercaPuntiClassificaSquadra,3,FALSE),-1)=IFERROR(VLOOKUP($AQ14,areaCercaPuntiClassificaSquadra,3,FALSE),-2)),SUMIFS(Dati!$B$2:$B$381,Dati!$A$2:$A$381,$H14,Dati!$H$2:$H$381,$AQ14)+SUMIFS(Dati!$I$2:$I$381,Dati!$H$2:$H$381,$H14,Dati!$A$2:$A$381,$AQ14),"-") | BN14: =IF(AND($H14<>"",$AR14<>"",$H14<>$AR14,IFERROR(VLOOKUP($H14,areaCercaPuntiClassificaSquadra,3,FALSE),-1)=IFERROR(VLOOKUP($AR14,areaCercaPuntiClassificaSquadra,3,FALSE),-2)),SUMIFS(Dati!$B$2:$B$381,Dati!$A$2:$A$381,$H14,Dati!$H$2:$H$381,$AR14)+SUMIFS(Dati!$I$2:$I$381,Dati!$H$2:$H$381,$H14,Dati!$A$2:$A$381,$AR14),"-") | BP14: =$C14 | BQ14: =IF(AND($H14<>"",$Y14<>"",$H14<>$Y14,IFERROR(VLOOKUP($H14,areaCercaPuntiClassificaSquadra,3,FALSE),-1)=IFERROR(VLOOKUP($Y14,areaCercaPuntiClassificaSquadra,3,FALSE),-2)),SUMIFS(Dati!$D$2:$D$381,Dati!$A$2:$A$381,$H14,Dati!$H$2:$H$381,$Y14)+SUMIFS(Dati!$K$2:$K$381,Dati!$H$2:$H$381,$H14,Dati!$A$2:$A$381,$Y14)+SUMIFS(Dati!$C$2:$C$381,Dati!$A$2:$A$381,$H14,Dati!$H$2:$H$381,$Y14)+SUMIFS(Dati!$J$2:$J$381,Dati!$H$2:$H$381,$H14,Dati!$A$2:$A$381,$Y14),"-") | BR14: =IF(AND($H14<>"",$Z14<>"",$H14<>$Z14,IFERROR(VLOOKUP($H14,areaCercaPuntiClassificaSquadra,3,FALSE),-1)=IFERROR(VLOOKUP($Z14,areaCercaPuntiClassificaSquadra,3,FALSE),-2)),SUMIFS(Dati!$D$2:$D$381,Dati!$A$2:$A$381,$H14,Dati!$H$2:$H$381,$Z14)+SUMIFS(Dati!$K$2:$K$381,Dati!$H$2:$H$381,$H14,Dati!$A$2:$A$381,$Z14)+SUMIFS(Dati!$C$2:$C$381,Dati!$A$2:$A$381,$H14,Dati!$H$2:$H$381,$Z14)+SUMIFS(Dati!$J$2:$J$381,Dati!$H$2:$H$381,$H14,Dati!$A$2:$A$381,$Z14),"-") | BS14: =IF(AND($H14<>"",$AA14<>"",$H14<>$AA14,IFERROR(VLOOKUP($H14,areaCercaPuntiClassificaSquadra,3,FALSE),-1)=IFERROR(VLOOKUP($AA14,areaCercaPuntiClassificaSquadra,3,FALSE),-2)),SUMIFS(Dati!$D$2:$D$381,Dati!$A$2:$A$381,$H14,Dati!$H$2:$H$381,$AA14)+SUMIFS(Dati!$K$2:$K$381,Dati!$H$2:$H$381,$H14,Dati!$A$2:$A$381,$AA14)+SUMIFS(Dati!$C$2:$C$381,Dati!$A$2:$A$381,$H14,Dati!$H$2:$H$381,$AA14)+SUMIFS(Dati!$J$2:$J$381,Dati!$H$2:$H$381,$H14,Dati!$A$2:$A$381,$AA14),"-") | BT14: =IF(AND($H14<>"",$AB14<>"",$H14<>$AB14,IFERROR(VLOOKUP($H14,areaCercaPuntiClassificaSquadra,3,FALSE),-1)=IFERROR(VLOOKUP($AB14,areaCercaPuntiClassificaSquadra,3,FALSE),-2)),SUMIFS(Dati!$D$2:$D$381,Dati!$A$2:$A$381,$H14,Dati!$H$2:$H$381,$AB14)+SUMIFS(Dati!$K$2:$K$381,Dati!$H$2:$H$381,$H14,Dati!$A$2:$A$381,$AB14)+SUMIFS(Dati!$C$2:$C$381,Dati!$A$2:$A$381,$H14,Dati!$H$2:$H$381,$AB14)+SUMIFS(Dati!$J$2:$J$381,Dati!$H$2:$H$381,$H14,Dati!$A$2:$A$381,$AB14),"-") | BU14: =IF(AND($H14<>"",$AC14<>"",$H14<>$AC14,IFERROR(VLOOKUP($H14,areaCercaPuntiClassificaSquadra,3,FALSE),-1)=IFERROR(VLOOKUP($AC14,areaCercaPuntiClassificaSquadra,3,FALSE),-2)),SUMIFS(Dati!$D$2:$D$381,Dati!$A$2:$A$381,$H14,Dati!$H$2:$H$381,$AC14)+SUMIFS(Dati!$K$2:$K$381,Dati!$H$2:$H$381,$H14,Dati!$A$2:$A$381,$AC14)+SUMIFS(Dati!$C$2:$C$381,Dati!$A$2:$A$381,$H14,Dati!$H$2:$H$381,$AC14)+SUMIFS(Dati!$J$2:$J$381,Dati!$H$2:$H$381,$H14,Dati!$A$2:$A$381,$AC14),"-") | BV14: =IF(AND($H14<>"",$AD14<>"",$H14<>$AD14,IFERROR(VLOOKUP($H14,areaCercaPuntiClassificaSquadra,3,FALSE),-1)=IFERROR(VLOOKUP($AD14,areaCercaPuntiClassificaSquadra,3,FALSE),-2)),SUMIFS(Dati!$D$2:$D$381,Dati!$A$2:$A$381,$H14,Dati!$H$2:$H$381,$AD14)+SUMIFS(Dati!$K$2:$K$381,Dati!$H$2:$H$381,$H14,Dati!$A$2:$A$381,$AD14)+SUMIFS(Dati!$C$2:$C$381,Dati!$A$2:$A$381,$H14,Dati!$H$2:$H$381,$AD14)+SUMIFS(Dati!$J$2:$J$381,Dati!$H$2:$H$381,$H14,Dati!$A$2:$A$381,$AD14),"-") | BW14: =IF(AND($H14<>"",$AE14<>"",$H14<>$AE14,IFERROR(VLOOKUP($H14,areaCercaPuntiClassificaSquadra,3,FALSE),-1)=IFERROR(VLOOKUP($AE14,areaCercaPuntiClassificaSquadra,3,FALSE),-2)),SUMIFS(Dati!$D$2:$D$381,Dati!$A$2:$A$381,$H14,Dati!$H$2:$H$381,$AE14)+SUMIFS(Dati!$K$2:$K$381,Dati!$H$2:$H$381,$H14,Dati!$A$2:$A$381,$AE14)+SUMIFS(Dati!$C$2:$C$381,Dati!$A$2:$A$381,$H14,Dati!$H$2:$H$381,$AE14)+SUMIFS(Dati!$J$2:$J$381,Dati!$H$2:$H$381,$H14,Dati!$A$2:$A$381,$AE14),"-") | BX14: =IF(AND($H14<>"",$AF14<>"",$H14<>$AF14,IFERROR(VLOOKUP($H14,areaCercaPuntiClassificaSquadra,3,FALSE),-1)=IFERROR(VLOOKUP($AF14,areaCercaPuntiClassificaSquadra,3,FALSE),-2)),SUMIFS(Dati!$D$2:$D$381,Dati!$A$2:$A$381,$H14,Dati!$H$2:$H$381,$AF14)+SUMIFS(Dati!$K$2:$K$381,Dati!$H$2:$H$381,$H14,Dati!$A$2:$A$381,$AF14)+SUMIFS(Dati!$C$2:$C$381,Dati!$A$2:$A$381,$H14,Dati!$H$2:$H$381,$AF14)+SUMIFS(Dati!$J$2:$J$381,Dati!$H$2:$H$381,$H14,Dati!$A$2:$A$381,$AF14),"-") | BY14: =IF(AND($H14<>"",$AG14<>"",$H14<>$AG14,IFERROR(VLOOKUP($H14,areaCercaPuntiClassificaSquadra,3,FALSE),-1)=IFERROR(VLOOKUP($AG14,areaCercaPuntiClassificaSquadra,3,FALSE),-2)),SUMIFS(Dati!$D$2:$D$381,Dati!$A$2:$A$381,$H14,Dati!$H$2:$H$381,$AG14)+SUMIFS(Dati!$K$2:$K$381,Dati!$H$2:$H$381,$H14,Dati!$A$2:$A$381,$AG14)+SUMIFS(Dati!$C$2:$C$381,Dati!$A$2:$A$381,$H14,Dati!$H$2:$H$381,$AG14)+SUMIFS(Dati!$J$2:$J$381,Dati!$H$2:$H$381,$H14,Dati!$A$2:$A$381,$AG14),"-") | BZ14: =IF(AND($H14<>"",$AH14<>"",$H14<>$AH14,IFERROR(VLOOKUP($H14,areaCercaPuntiClassificaSquadra,3,FALSE),-1)=IFERROR(VLOOKUP($AH14,areaCercaPuntiClassificaSquadra,3,FALSE),-2)),SUMIFS(Dati!$D$2:$D$381,Dati!$A$2:$A$381,$H14,Dati!$H$2:$H$381,$AH14)+SUMIFS(Dati!$K$2:$K$381,Dati!$H$2:$H$381,$H14,Dati!$A$2:$A$381,$AH14)+SUMIFS(Dati!$C$2:$C$381,Dati!$A$2:$A$381,$H14,Dati!$H$2:$H$381,$AH14)+SUMIFS(Dati!$J$2:$J$381,Dati!$H$2:$H$381,$H14,Dati!$A$2:$A$381,$AH14),"-") | CA14: =IF(AND($H14<>"",$AI14<>"",$H14<>$AI14,IFERROR(VLOOKUP($H14,areaCercaPuntiClassificaSquadra,3,FALSE),-1)=IFERROR(VLOOKUP($AI14,areaCercaPuntiClassificaSquadra,3,FALSE),-2)),SUMIFS(Dati!$D$2:$D$381,Dati!$A$2:$A$381,$H14,Dati!$H$2:$H$381,$AI14)+SUMIFS(Dati!$K$2:$K$381,Dati!$H$2:$H$381,$H14,Dati!$A$2:$A$381,$AI14)+SUMIFS(Dati!$C$2:$C$381,Dati!$A$2:$A$381,$H14,Dati!$H$2:$H$381,$AI14)+SUMIFS(Dati!$J$2:$J$381,Dati!$H$2:$H$381,$H14,Dati!$A$2:$A$381,$AI14),"-") | CB14: =IF(AND($H14<>"",$AJ14<>"",$H14<>$AJ14,IFERROR(VLOOKUP($H14,areaCercaPuntiClassificaSquadra,3,FALSE),-1)=IFERROR(VLOOKUP($AJ14,areaCercaPuntiClassificaSquadra,3,FALSE),-2)),SUMIFS(Dati!$D$2:$D$381,Dati!$A$2:$A$381,$H14,Dati!$H$2:$H$381,$AJ14)+SUMIFS(Dati!$K$2:$K$381,Dati!$H$2:$H$381,$H14,Dati!$A$2:$A$381,$AJ14)+SUMIFS(Dati!$C$2:$C$381,Dati!$A$2:$A$381,$H14,Dati!$H$2:$H$381,$AJ14)+SUMIFS(Dati!$J$2:$J$381,Dati!$H$2:$H$381,$H14,Dati!$A$2:$A$381,$AJ14),"-") | CC14: =IF(AND($H14<>"",$AK14<>"",$H14<>$AK14,IFERROR(VLOOKUP($H14,areaCercaPuntiClassificaSquadra,3,FALSE),-1)=IFERROR(VLOOKUP($AK14,areaCercaPuntiClassificaSquadra,3,FALSE),-2)),SUMIFS(Dati!$D$2:$D$381,Dati!$A$2:$A$381,$H14,Dati!$H$2:$H$381,$AK14)+SUMIFS(Dati!$K$2:$K$381,Dati!$H$2:$H$381,$H14,Dati!$A$2:$A$381,$AK14)+SUMIFS(Dati!$C$2:$C$381,Dati!$A$2:$A$381,$H14,Dati!$H$2:$H$381,$AK14)+SUMIFS(Dati!$J$2:$J$381,Dati!$H$2:$H$381,$H14,Dati!$A$2:$A$381,$AK14),"-") | CD14: =IF(AND($H14<>"",$AL14<>"",$H14<>$AL14,IFERROR(VLOOKUP($H14,areaCercaPuntiClassificaSquadra,3,FALSE),-1)=IFERROR(VLOOKUP($AL14,areaCercaPuntiClassificaSquadra,3,FALSE),-2)),SUMIFS(Dati!$D$2:$D$381,Dati!$A$2:$A$381,$H14,Dati!$H$2:$H$381,$AL14)+SUMIFS(Dati!$K$2:$K$381,Dati!$H$2:$H$381,$H14,Dati!$A$2:$A$381,$AL14)+SUMIFS(Dati!$C$2:$C$381,Dati!$A$2:$A$381,$H14,Dati!$H$2:$H$381,$AL14)+SUMIFS(Dati!$J$2:$J$381,Dati!$H$2:$H$381,$H14,Dati!$A$2:$A$381,$AL14),"-") | CE14: =IF(AND($H14<>"",$AM14<>"",$H14<>$AM14,IFERROR(VLOOKUP($H14,areaCercaPuntiClassificaSquadra,3,FALSE),-1)=IFERROR(VLOOKUP($AM14,areaCercaPuntiClassificaSquadra,3,FALSE),-2)),SUMIFS(Dati!$D$2:$D$381,Dati!$A$2:$A$381,$H14,Dati!$H$2:$H$381,$AM14)+SUMIFS(Dati!$K$2:$K$381,Dati!$H$2:$H$381,$H14,Dati!$A$2:$A$381,$AM14)+SUMIFS(Dati!$C$2:$C$381,Dati!$A$2:$A$381,$H14,Dati!$H$2:$H$381,$AM14)+SUMIFS(Dati!$J$2:$J$381,Dati!$H$2:$H$381,$H14,Dati!$A$2:$A$381,$AM14),"-") | CF14: =IF(AND($H14<>"",$AN14<>"",$H14<>$AN14,IFERROR(VLOOKUP($H14,areaCercaPuntiClassificaSquadra,3,FALSE),-1)=IFERROR(VLOOKUP($AN14,areaCercaPuntiClassificaSquadra,3,FALSE),-2)),SUMIFS(Dati!$D$2:$D$381,Dati!$A$2:$A$381,$H14,Dati!$H$2:$H$381,$AN14)+SUMIFS(Dati!$K$2:$K$381,Dati!$H$2:$H$381,$H14,Dati!$A$2:$A$381,$AN14)+SUMIFS(Dati!$C$2:$C$381,Dati!$A$2:$A$381,$H14,Dati!$H$2:$H$381,$AN14)+SUMIFS(Dati!$J$2:$J$381,Dati!$H$2:$H$381,$H14,Dati!$A$2:$A$381,$AN14),"-") | CG14: =IF(AND($H14<>"",$AO14<>"",$H14<>$AO14,IFERROR(VLOOKUP($H14,areaCercaPuntiClassificaSquadra,3,FALSE),-1)=IFERROR(VLOOKUP($AO14,areaCercaPuntiClassificaSquadra,3,FALSE),-2)),SUMIFS(Dati!$D$2:$D$381,Dati!$A$2:$A$381,$H14,Dati!$H$2:$H$381,$AO14)+SUMIFS(Dati!$K$2:$K$381,Dati!$H$2:$H$381,$H14,Dati!$A$2:$A$381,$AO14)+SUMIFS(Dati!$C$2:$C$381,Dati!$A$2:$A$381,$H14,Dati!$H$2:$H$381,$AO14)+SUMIFS(Dati!$J$2:$J$381,Dati!$H$2:$H$381,$H14,Dati!$A$2:$A$381,$AO14),"-") | CH14: =IF(AND($H14<>"",$AP14<>"",$H14<>$AP14,IFERROR(VLOOKUP($H14,areaCercaPuntiClassificaSquadra,3,FALSE),-1)=IFERROR(VLOOKUP($AP14,areaCercaPuntiClassificaSquadra,3,FALSE),-2)),SUMIFS(Dati!$D$2:$D$381,Dati!$A$2:$A$381,$H14,Dati!$H$2:$H$381,$AP14)+SUMIFS(Dati!$K$2:$K$381,Dati!$H$2:$H$381,$H14,Dati!$A$2:$A$381,$AP14)+SUMIFS(Dati!$C$2:$C$381,Dati!$A$2:$A$381,$H14,Dati!$H$2:$H$381,$AP14)+SUMIFS(Dati!$J$2:$J$381,Dati!$H$2:$H$381,$H14,Dati!$A$2:$A$381,$AP14),"-") | CI14: =IF(AND($H14<>"",$AQ14<>"",$H14<>$AQ14,IFERROR(VLOOKUP($H14,areaCercaPuntiClassificaSquadra,3,FALSE),-1)=IFERROR(VLOOKUP($AQ14,areaCercaPuntiClassificaSquadra,3,FALSE),-2)),SUMIFS(Dati!$D$2:$D$381,Dati!$A$2:$A$381,$H14,Dati!$H$2:$H$381,$AQ14)+SUMIFS(Dati!$K$2:$K$381,Dati!$H$2:$H$381,$H14,Dati!$A$2:$A$381,$AQ14)+SUMIFS(Dati!$C$2:$C$381,Dati!$A$2:$A$381,$H14,Dati!$H$2:$H$381,$AQ14)+SUMIFS(Dati!$J$2:$J$381,Dati!$H$2:$H$381,$H14,Dati!$A$2:$A$381,$AQ14),"-") | CJ14: =IF(AND($H14<>"",$AR14<>"",$H14<>$AR14,IFERROR(VLOOKUP($H14,areaCercaPuntiClassificaSquadra,3,FALSE),-1)=IFERROR(VLOOKUP($AR14,areaCercaPuntiClassificaSquadra,3,FALSE),-2)),SUMIFS(Dati!$D$2:$D$381,Dati!$A$2:$A$381,$H14,Dati!$H$2:$H$381,$AR14)+SUMIFS(Dati!$K$2:$K$381,Dati!$H$2:$H$381,$H14,Dati!$A$2:$A$381,$AR14)+SUMIFS(Dati!$C$2:$C$381,Dati!$A$2:$A$381,$H14,Dati!$H$2:$H$381,$AR14)+SUMIFS(Dati!$J$2:$J$381,Dati!$H$2:$H$381,$H14,Dati!$A$2:$A$381,$AR14),"-") | CL14: =$C14 | CM14: =IF(AND($H14<>"",$Y14<>"",$H14<>$Y14,IFERROR(VLOOKUP($H14,areaCercaPuntiClassificaSquadra,3,FALSE),-1)=IFERROR(VLOOKUP($Y14,areaCercaPuntiClassificaSquadra,3,FALSE),-2)),SUMIFS(Dati!$E$2:$E$381,Dati!$A$2:$A$381,$H14,Dati!$H$2:$H$381,$Y14)+SUMIFS(Dati!$L$2:$L$381,Dati!$H$2:$H$381,$H14,Dati!$A$2:$A$381,$Y14),"-") | CN14: =IF(AND($H14<>"",$Z14<>"",$H14<>$Z14,IFERROR(VLOOKUP($H14,areaCercaPuntiClassificaSquadra,3,FALSE),-1)=IFERROR(VLOOKUP($Z14,areaCercaPuntiClassificaSquadra,3,FALSE),-2)),SUMIFS(Dati!$E$2:$E$381,Dati!$A$2:$A$381,$H14,Dati!$H$2:$H$381,$Z14)+SUMIFS(Dati!$L$2:$L$381,Dati!$H$2:$H$381,$H14,Dati!$A$2:$A$381,$Z14),"-") | CO14: =IF(AND($H14<>"",$AA14<>"",$H14<>$AA14,IFERROR(VLOOKUP($H14,areaCercaPuntiClassificaSquadra,3,FALSE),-1)=IFERROR(VLOOKUP($AA14,areaCercaPuntiClassificaSquadra,3,FALSE),-2)),SUMIFS(Dati!$E$2:$E$381,Dati!$A$2:$A$381,$H14,Dati!$H$2:$H$381,$AA14)+SUMIFS(Dati!$L$2:$L$381,Dati!$H$2:$H$381,$H14,Dati!$A$2:$A$381,$AA14),"-") | CP14: =IF(AND($H14<>"",$AB14<>"",$H14<>$AB14,IFERROR(VLOOKUP($H14,areaCercaPuntiClassificaSquadra,3,FALSE),-1)=IFERROR(VLOOKUP($AB14,areaCercaPuntiClassificaSquadra,3,FALSE),-2)),SUMIFS(Dati!$E$2:$E$381,Dati!$A$2:$A$381,$H14,Dati!$H$2:$H$381,$AB14)+SUMIFS(Dati!$L$2:$L$381,Dati!$H$2:$H$381,$H14,Dati!$A$2:$A$381,$AB14),"-") | CQ14: =IF(AND($H14<>"",$AC14<>"",$H14<>$AC14,IFERROR(VLOOKUP($H14,areaCercaPuntiClassificaSquadra,3,FALSE),-1)=IFERROR(VLOOKUP($AC14,areaCercaPuntiClassificaSquadra,3,FALSE),-2)),SUMIFS(Dati!$E$2:$E$381,Dati!$A$2:$A$381,$H14,Dati!$H$2:$H$381,$AC14)+SUMIFS(Dati!$L$2:$L$381,Dati!$H$2:$H$381,$H14,Dati!$A$2:$A$381,$AC14),"-") | CR14: =IF(AND($H14<>"",$AD14<>"",$H14<>$AD14,IFERROR(VLOOKUP($H14,areaCercaPuntiClassificaSquadra,3,FALSE),-1)=IFERROR(VLOOKUP($AD14,areaCercaPuntiClassificaSquadra,3,FALSE),-2)),SUMIFS(Dati!$E$2:$E$381,Dati!$A$2:$A$381,$H14,Dati!$H$2:$H$381,$AD14)+SUMIFS(Dati!$L$2:$L$381,Dati!$H$2:$H$381,$H14,Dati!$A$2:$A$381,$AD14),"-") | CS14: =IF(AND($H14<>"",$AE14<>"",$H14<>$AE14,IFERROR(VLOOKUP($H14,areaCercaPuntiClassificaSquadra,3,FALSE),-1)=IFERROR(VLOOKUP($AE14,areaCercaPuntiClassificaSquadra,3,FALSE),-2)),SUMIFS(Dati!$E$2:$E$381,Dati!$A$2:$A$381,$H14,Dati!$H$2:$H$381,$AE14)+SUMIFS(Dati!$L$2:$L$381,Dati!$H$2:$H$381,$H14,Dati!$A$2:$A$381,$AE14),"-") | CT14: =IF(AND($H14<>"",$AF14<>"",$H14<>$AF14,IFERROR(VLOOKUP($H14,areaCercaPuntiClassificaSquadra,3,FALSE),-1)=IFERROR(VLOOKUP($AF14,areaCercaPuntiClassificaSquadra,3,FALSE),-2)),SUMIFS(Dati!$E$2:$E$381,Dati!$A$2:$A$381,$H14,Dati!$H$2:$H$381,$AF14)+SUMIFS(Dati!$L$2:$L$381,Dati!$H$2:$H$381,$H14,Dati!$A$2:$A$381,$AF14),"-") | CU14: =IF(AND($H14<>"",$AG14<>"",$H14<>$AG14,IFERROR(VLOOKUP($H14,areaCercaPuntiClassificaSquadra,3,FALSE),-1)=IFERROR(VLOOKUP($AG14,areaCercaPuntiClassificaSquadra,3,FALSE),-2)),SUMIFS(Dati!$E$2:$E$381,Dati!$A$2:$A$381,$H14,Dati!$H$2:$H$381,$AG14)+SUMIFS(Dati!$L$2:$L$381,Dati!$H$2:$H$381,$H14,Dati!$A$2:$A$381,$AG14),"-") | CV14: =IF(AND($H14<>"",$AH14<>"",$H14<>$AH14,IFERROR(VLOOKUP($H14,areaCercaPuntiClassificaSquadra,3,FALSE),-1)=IFERROR(VLOOKUP($AH14,areaCercaPuntiClassificaSquadra,3,FALSE),-2)),SUMIFS(Dati!$E$2:$E$381,Dati!$A$2:$A$381,$H14,Dati!$H$2:$H$381,$AH14)+SUMIFS(Dati!$L$2:$L$381,Dati!$H$2:$H$381,$H14,Dati!$A$2:$A$381,$AH14),"-") | CW14: =IF(AND($H14<>"",$AI14<>"",$H14<>$AI14,IFERROR(VLOOKUP($H14,areaCercaPuntiClassificaSquadra,3,FALSE),-1)=IFERROR(VLOOKUP($AI14,areaCercaPuntiClassificaSquadra,3,FALSE),-2)),SUMIFS(Dati!$E$2:$E$381,Dati!$A$2:$A$381,$H14,Dati!$H$2:$H$381,$AI14)+SUMIFS(Dati!$L$2:$L$381,Dati!$H$2:$H$381,$H14,Dati!$A$2:$A$381,$AI14),"-") | CX14: =IF(AND($H14<>"",$AJ14<>"",$H14<>$AJ14,IFERROR(VLOOKUP($H14,areaCercaPuntiClassificaSquadra,3,FALSE),-1)=IFERROR(VLOOKUP($AJ14,areaCercaPuntiClassificaSquadra,3,FALSE),-2)),SUMIFS(Dati!$E$2:$E$381,Dati!$A$2:$A$381,$H14,Dati!$H$2:$H$381,$AJ14)+SUMIFS(Dati!$L$2:$L$381,Dati!$H$2:$H$381,$H14,Dati!$A$2:$A$381,$AJ14),"-") | CY14: =IF(AND($H14<>"",$AK14<>"",$H14<>$AK14,IFERROR(VLOOKUP($H14,areaCercaPuntiClassificaSquadra,3,FALSE),-1)=IFERROR(VLOOKUP($AK14,areaCercaPuntiClassificaSquadra,3,FALSE),-2)),SUMIFS(Dati!$E$2:$E$381,Dati!$A$2:$A$381,$H14,Dati!$H$2:$H$381,$AK14)+SUMIFS(Dati!$L$2:$L$381,Dati!$H$2:$H$381,$H14,Dati!$A$2:$A$381,$AK14),"-") | CZ14: =IF(AND($H14<>"",$AL14<>"",$H14<>$AL14,IFERROR(VLOOKUP($H14,areaCercaPuntiClassificaSquadra,3,FALSE),-1)=IFERROR(VLOOKUP($AL14,areaCercaPuntiClassificaSquadra,3,FALSE),-2)),SUMIFS(Dati!$E$2:$E$381,Dati!$A$2:$A$381,$H14,Dati!$H$2:$H$381,$AL14)+SUMIFS(Dati!$L$2:$L$381,Dati!$H$2:$H$381,$H14,Dati!$A$2:$A$381,$AL14),"-") | DA14: =IF(AND($H14<>"",$AM14<>"",$H14<>$AM14,IFERROR(VLOOKUP($H14,areaCercaPuntiClassificaSquadra,3,FALSE),-1)=IFERROR(VLOOKUP($AM14,areaCercaPuntiClassificaSquadra,3,FALSE),-2)),SUMIFS(Dati!$E$2:$E$381,Dati!$A$2:$A$381,$H14,Dati!$H$2:$H$381,$AM14)+SUMIFS(Dati!$L$2:$L$381,Dati!$H$2:$H$381,$H14,Dati!$A$2:$A$381,$AM14),"-") | DB14: =IF(AND($H14<>"",$AN14<>"",$H14<>$AN14,IFERROR(VLOOKUP($H14,areaCercaPuntiClassificaSquadra,3,FALSE),-1)=IFERROR(VLOOKUP($AN14,areaCercaPuntiClassificaSquadra,3,FALSE),-2)),SUMIFS(Dati!$E$2:$E$381,Dati!$A$2:$A$381,$H14,Dati!$H$2:$H$381,$AN14)+SUMIFS(Dati!$L$2:$L$381,Dati!$H$2:$H$381,$H14,Dati!$A$2:$A$381,$AN14),"-") | DC14: =IF(AND($H14<>"",$AO14<>"",$H14<>$AO14,IFERROR(VLOOKUP($H14,areaCercaPuntiClassificaSquadra,3,FALSE),-1)=IFERROR(VLOOKUP($AO14,areaCercaPuntiClassificaSquadra,3,FALSE),-2)),SUMIFS(Dati!$E$2:$E$381,Dati!$A$2:$A$381,$H14,Dati!$H$2:$H$381,$AO14)+SUMIFS(Dati!$L$2:$L$381,Dati!$H$2:$H$381,$H14,Dati!$A$2:$A$381,$AO14),"-") | DD14: =IF(AND($H14<>"",$AP14<>"",$H14<>$AP14,IFERROR(VLOOKUP($H14,areaCercaPuntiClassificaSquadra,3,FALSE),-1)=IFERROR(VLOOKUP($AP14,areaCercaPuntiClassificaSquadra,3,FALSE),-2)),SUMIFS(Dati!$E$2:$E$381,Dati!$A$2:$A$381,$H14,Dati!$H$2:$H$381,$AP14)+SUMIFS(Dati!$L$2:$L$381,Dati!$H$2:$H$381,$H14,Dati!$A$2:$A$381,$AP14),"-") | DE14: =IF(AND($H14<>"",$AQ14<>"",$H14<>$AQ14,IFERROR(VLOOKUP($H14,areaCercaPuntiClassificaSquadra,3,FALSE),-1)=IFERROR(VLOOKUP($AQ14,areaCercaPuntiClassificaSquadra,3,FALSE),-2)),SUMIFS(Dati!$E$2:$E$381,Dati!$A$2:$A$381,$H14,Dati!$H$2:$H$381,$AQ14)+SUMIFS(Dati!$L$2:$L$381,Dati!$H$2:$H$381,$H14,Dati!$A$2:$A$381,$AQ14),"-") | DF14: =IF(AND($H14<>"",$AR14<>"",$H14<>$AR14,IFERROR(VLOOKUP($H14,areaCercaPuntiClassificaSquadra,3,FALSE),-1)=IFERROR(VLOOKUP($AR14,areaCercaPuntiClassificaSquadra,3,FALSE),-2)),SUMIFS(Dati!$E$2:$E$381,Dati!$A$2:$A$381,$H14,Dati!$H$2:$H$381,$AR14)+SUMIFS(Dati!$L$2:$L$381,Dati!$H$2:$H$381,$H14,Dati!$A$2:$A$381,$AR14),"-") | DH14: =$C14 | DI14: =IF(AND($H14<>"",$Y14<>"",$H14<>$Y14,IFERROR(VLOOKUP($H14,areaCercaPuntiClassificaSquadra,3,FALSE),-1)=IFERROR(VLOOKUP($Y14,areaCercaPuntiClassificaSquadra,3,FALSE),-2)),SUMIFS(Dati!$F$2:$F$381,Dati!$A$2:$A$381,$H14,Dati!$H$2:$H$381,$Y14)+SUMIFS(Dati!$M$2:$M$381,Dati!$H$2:$H$381,$H14,Dati!$A$2:$A$381,$Y14),"-") | DJ14: =IF(AND($H14<>"",$Z14<>"",$H14<>$Z14,IFERROR(VLOOKUP($H14,areaCercaPuntiClassificaSquadra,3,FALSE),-1)=IFERROR(VLOOKUP($Z14,areaCercaPuntiClassificaSquadra,3,FALSE),-2)),SUMIFS(Dati!$F$2:$F$381,Dati!$A$2:$A$381,$H14,Dati!$H$2:$H$381,$Z14)+SUMIFS(Dati!$M$2:$M$381,Dati!$H$2:$H$381,$H14,Dati!$A$2:$A$381,$Z14),"-") | DK14: =IF(AND($H14<>"",$AA14<>"",$H14<>$AA14,IFERROR(VLOOKUP($H14,areaCercaPuntiClassificaSquadra,3,FALSE),-1)=IFERROR(VLOOKUP($AA14,areaCercaPuntiClassificaSquadra,3,FALSE),-2)),SUMIFS(Dati!$F$2:$F$381,Dati!$A$2:$A$381,$H14,Dati!$H$2:$H$381,$AA14)+SUMIFS(Dati!$M$2:$M$381,Dati!$H$2:$H$381,$H14,Dati!$A$2:$A$381,$AA14),"-") | DL14: =IF(AND($H14<>"",$AB14<>"",$H14<>$AB14,IFERROR(VLOOKUP($H14,areaCercaPuntiClassificaSquadra,3,FALSE),-1)=IFERROR(VLOOKUP($AB14,areaCercaPuntiClassificaSquadra,3,FALSE),-2)),SUMIFS(Dati!$F$2:$F$381,Dati!$A$2:$A$381,$H14,Dati!$H$2:$H$381,$AB14)+SUMIFS(Dati!$M$2:$M$381,Dati!$H$2:$H$381,$H14,Dati!$A$2:$A$381,$AB14),"-") | DM14: =IF(AND($H14<>"",$AC14<>"",$H14<>$AC14,IFERROR(VLOOKUP($H14,areaCercaPuntiClassificaSquadra,3,FALSE),-1)=IFERROR(VLOOKUP($AC14,areaCercaPuntiClassificaSquadra,3,FALSE),-2)),SUMIFS(Dati!$F$2:$F$381,Dati!$A$2:$A$381,$H14,Dati!$H$2:$H$381,$AC14)+SUMIFS(Dati!$M$2:$M$381,Dati!$H$2:$H$381,$H14,Dati!$A$2:$A$381,$AC14),"-") | DN14: =IF(AND($H14<>"",$AD14<>"",$H14<>$AD14,IFERROR(VLOOKUP($H14,areaCercaPuntiClassificaSquadra,3,FALSE),-1)=IFERROR(VLOOKUP($AD14,areaCercaPuntiClassificaSquadra,3,FALSE),-2)),SUMIFS(Dati!$F$2:$F$381,Dati!$A$2:$A$381,$H14,Dati!$H$2:$H$381,$AD14)+SUMIFS(Dati!$M$2:$M$381,Dati!$H$2:$H$381,$H14,Dati!$A$2:$A$381,$AD14),"-") | DO14: =IF(AND($H14<>"",$AE14<>"",$H14<>$AE14,IFERROR(VLOOKUP($H14,areaCercaPuntiClassificaSquadra,3,FALSE),-1)=IFERROR(VLOOKUP($AE14,areaCercaPuntiClassificaSquadra,3,FALSE),-2)),SUMIFS(Dati!$F$2:$F$381,Dati!$A$2:$A$381,$H14,Dati!$H$2:$H$381,$AE14)+SUMIFS(Dati!$M$2:$M$381,Dati!$H$2:$H$381,$H14,Dati!$A$2:$A$381,$AE14),"-") | DP14: =IF(AND($H14<>"",$AF14<>"",$H14<>$AF14,IFERROR(VLOOKUP($H14,areaCercaPuntiClassificaSquadra,3,FALSE),-1)=IFERROR(VLOOKUP($AF14,areaCercaPuntiClassificaSquadra,3,FALSE),-2)),SUMIFS(Dati!$F$2:$F$381,Dati!$A$2:$A$381,$H14,Dati!$H$2:$H$381,$AF14)+SUMIFS(Dati!$M$2:$M$381,Dati!$H$2:$H$381,$H14,Dati!$A$2:$A$381,$AF14),"-") | DQ14: =IF(AND($H14<>"",$AG14<>"",$H14<>$AG14,IFERROR(VLOOKUP($H14,areaCercaPuntiClassificaSquadra,3,FALSE),-1)=IFERROR(VLOOKUP($AG14,areaCercaPuntiClassificaSquadra,3,FALSE),-2)),SUMIFS(Dati!$F$2:$F$381,Dati!$A$2:$A$381,$H14,Dati!$H$2:$H$381,$AG14)+SUMIFS(Dati!$M$2:$M$381,Dati!$H$2:$H$381,$H14,Dati!$A$2:$A$381,$AG14),"-") | DR14: =IF(AND($H14<>"",$AH14<>"",$H14<>$AH14,IFERROR(VLOOKUP($H14,areaCercaPuntiClassificaSquadra,3,FALSE),-1)=IFERROR(VLOOKUP($AH14,areaCercaPuntiClassificaSquadra,3,FALSE),-2)),SUMIFS(Dati!$F$2:$F$381,Dati!$A$2:$A$381,$H14,Dati!$H$2:$H$381,$AH14)+SUMIFS(Dati!$M$2:$M$381,Dati!$H$2:$H$381,$H14,Dati!$A$2:$A$381,$AH14),"-") | DS14: =IF(AND($H14<>"",$AI14<>"",$H14<>$AI14,IFERROR(VLOOKUP($H14,areaCercaPuntiClassificaSquadra,3,FALSE),-1)=IFERROR(VLOOKUP($AI14,areaCercaPuntiClassificaSquadra,3,FALSE),-2)),SUMIFS(Dati!$F$2:$F$381,Dati!$A$2:$A$381,$H14,Dati!$H$2:$H$381,$AI14)+SUMIFS(Dati!$M$2:$M$381,Dati!$H$2:$H$381,$H14,Dati!$A$2:$A$381,$AI14),"-") | DT14: =IF(AND($H14<>"",$AJ14<>"",$H14<>$AJ14,IFERROR(VLOOKUP($H14,areaCercaPuntiClassificaSquadra,3,FALSE),-1)=IFERROR(VLOOKUP($AJ14,areaCercaPuntiClassificaSquadra,3,FALSE),-2)),SUMIFS(Dati!$F$2:$F$381,Dati!$A$2:$A$381,$H14,Dati!$H$2:$H$381,$AJ14)+SUMIFS(Dati!$M$2:$M$381,Dati!$H$2:$H$381,$H14,Dati!$A$2:$A$381,$AJ14),"-") | DU14: =IF(AND($H14<>"",$AK14<>"",$H14<>$AK14,IFERROR(VLOOKUP($H14,areaCercaPuntiClassificaSquadra,3,FALSE),-1)=IFERROR(VLOOKUP($AK14,areaCercaPuntiClassificaSquadra,3,FALSE),-2)),SUMIFS(Dati!$F$2:$F$381,Dati!$A$2:$A$381,$H14,Dati!$H$2:$H$381,$AK14)+SUMIFS(Dati!$M$2:$M$381,Dati!$H$2:$H$381,$H14,Dati!$A$2:$A$381,$AK14),"-") | DV14: =IF(AND($H14<>"",$AL14<>"",$H14<>$AL14,IFERROR(VLOOKUP($H14,areaCercaPuntiClassificaSquadra,3,FALSE),-1)=IFERROR(VLOOKUP($AL14,areaCercaPuntiClassificaSquadra,3,FALSE),-2)),SUMIFS(Dati!$F$2:$F$381,Dati!$A$2:$A$381,$H14,Dati!$H$2:$H$381,$AL14)+SUMIFS(Dati!$M$2:$M$381,Dati!$H$2:$H$381,$H14,Dati!$A$2:$A$381,$AL14),"-") | DW14: =IF(AND($H14<>"",$AM14<>"",$H14<>$AM14,IFERROR(VLOOKUP($H14,areaCercaPuntiClassificaSquadra,3,FALSE),-1)=IFERROR(VLOOKUP($AM14,areaCercaPuntiClassificaSquadra,3,FALSE),-2)),SUMIFS(Dati!$F$2:$F$381,Dati!$A$2:$A$381,$H14,Dati!$H$2:$H$381,$AM14)+SUMIFS(Dati!$M$2:$M$381,Dati!$H$2:$H$381,$H14,Dati!$A$2:$A$381,$AM14),"-") | DX14: =IF(AND($H14<>"",$AN14<>"",$H14<>$AN14,IFERROR(VLOOKUP($H14,areaCercaPuntiClassificaSquadra,3,FALSE),-1)=IFERROR(VLOOKUP($AN14,areaCercaPuntiClassificaSquadra,3,FALSE),-2)),SUMIFS(Dati!$F$2:$F$381,Dati!$A$2:$A$381,$H14,Dati!$H$2:$H$381,$AN14)+SUMIFS(Dati!$M$2:$M$381,Dati!$H$2:$H$381,$H14,Dati!$A$2:$A$381,$AN14),"-") | DY14: =IF(AND($H14<>"",$AO14<>"",$H14<>$AO14,IFERROR(VLOOKUP($H14,areaCercaPuntiClassificaSquadra,3,FALSE),-1)=IFERROR(VLOOKUP($AO14,areaCercaPuntiClassificaSquadra,3,FALSE),-2)),SUMIFS(Dati!$F$2:$F$381,Dati!$A$2:$A$381,$H14,Dati!$H$2:$H$381,$AO14)+SUMIFS(Dati!$M$2:$M$381,Dati!$H$2:$H$381,$H14,Dati!$A$2:$A$381,$AO14),"-") | DZ14: =IF(AND($H14<>"",$AP14<>"",$H14<>$AP14,IFERROR(VLOOKUP($H14,areaCercaPuntiClassificaSquadra,3,FALSE),-1)=IFERROR(VLOOKUP($AP14,areaCercaPuntiClassificaSquadra,3,FALSE),-2)),SUMIFS(Dati!$F$2:$F$381,Dati!$A$2:$A$381,$H14,Dati!$H$2:$H$381,$AP14)+SUMIFS(Dati!$M$2:$M$381,Dati!$H$2:$H$381,$H14,Dati!$A$2:$A$381,$AP14),"-") | EA14: =IF(AND($H14<>"",$AQ14<>"",$H14<>$AQ14,IFERROR(VLOOKUP($H14,areaCercaPuntiClassificaSquadra,3,FALSE),-1)=IFERROR(VLOOKUP($AQ14,areaCercaPuntiClassificaSquadra,3,FALSE),-2)),SUMIFS(Dati!$F$2:$F$381,Dati!$A$2:$A$381,$H14,Dati!$H$2:$H$381,$AQ14)+SUMIFS(Dati!$M$2:$M$381,Dati!$H$2:$H$381,$H14,Dati!$A$2:$A$381,$AQ14),"-") | EB14: =IF(AND($H14<>"",$AR14<>"",$H14<>$AR14,IFERROR(VLOOKUP($H14,areaCercaPuntiClassificaSquadra,3,FALSE),-1)=IFERROR(VLOOKUP($AR14,areaCercaPuntiClassificaSquadra,3,FALSE),-2)),SUMIFS(Dati!$F$2:$F$381,Dati!$A$2:$A$381,$H14,Dati!$H$2:$H$381,$AR14)+SUMIFS(Dati!$M$2:$M$381,Dati!$H$2:$H$381,$H14,Dati!$A$2:$A$381,$AR14),"-") | ED14: =IF($C14="","",SUM(AU14:BN14))
